Workbook
Name mono__tri?: '11'!#REF!
Name mono__tri?: '11'!#REF!
Name mono__tri?: '11'!#REF!
Name mono__tri?: '11'!#REF!
Name mono__tri?: '11'!#REF!

Sheet Índice RTIEBT (Portaria 949)
A1: Índice das RTIEBT (Portaria n.º 949-A/2006, de 11 de Setembro - Diário da República, 1.ª Série - n.º 175 )
A2: Partes (Capítulos) | B2: Subdivisão das Partes | C2: Secção/ Anexos | D2: Designação | E2: Página
A3: 1- Generalidades | B3: 11 - Campo de aplicação | E3: 2
B4: 12 - Objectivo | E4: 2
B5: 13 - Princípios fundamentais | C5: 131 | D5: Protecção para garantir a segurança | E5: 3
C6: 132 | D6: Concepção das instalações | E6: 3
C7: 133 | D7: Selecção dos equipamentos | E7: 4
C8: 134 | D8: Execução e verificação das instalações eléctricas antes da entrada em serviço | E8: 5
B9: 14 - Limites das instalações | C9: 141 | D9: Origem das instalações | E9: 5
C10: 142 | D10: Limites (a juzante) das instalações | E10: 5
A11: 2 - Definições | B11: 21 - Características das instalações | C11: 211 | D11: Características gerais | E11: 5
C12: 212 | D12: Grandezas | E12: 5
C13: 213 | D13: Instalações diversas | E13: 5
C14: 214 | D14: Disponível | E14: 5
C15: 215 | D15: Alimentações | E15: 5
C16: 216 | D16: Factores | E16: 6
C17: 217 | D17: Influências externas | E17: 6
B18: 22 - Tensões | C18: 221 | D18: Tensão nominal | E18: 6
C19: 222 | D19: Domínio das tensões em corrente alternada | E19: 6
C20: 223 | D20: Domínio das tensões em corrente contínua | E20: 6
B21: 23 - Protecção contra os choques eléctricos | C21: 231 | D21: Termos gerais | E21: 6
C22: 232 | D22: Condutores, partes activas e massas | E22: 6
C23: 233 | D23: Defeitos | E23: 7
C24: 234 | D24: Tensões | E24: 7
C25: 235 | D25: Diversos | E25: 7
C26: 236 | D26: Isolamentos | E26: 7
C27: 237 | D27: Classificação dos equipamentos relativamente à protecção contra choques eléctricos | E27: 7
B28: 24 - Ligações à terra | C28: 241 | D28: Temos gerais | E28: 8
C29: 242 | D29: Eléctrodos de terra | E29: 8
C30: 243 | D30: Diversos | E30: 8
C31: 244 | D31: Ligações equipotenciais | E31: 8
B32: 25 - Circuitos eléctricos | C32: 251 | D32: Termos gerais | E32: 8
C33: 252 | D33: Correntes | E33: 8
C34: 253 | D34: Dispositivo de seccionamento, de comando e de protecção | E34: 9
C35: 254 | D35: Características dos dispositivos de protecção | E35: 9
B36: 26 - Canalizações | C36: 261 | D36: Termos gerais | E36: 9
C37: 262 | D37: Modos de instalação | E37: 9
C38: 263 | D38: Diversos | E38: 10
B39: 27 - Equipamentos | C39: 270 | D39: Termos gerais | E39: 10
C40: 271 | D40: Possibilidades de deslocamento | E40: 10
...

Sheet 1.1_ligacao_bt
C4: S | D4: kVA | E4: 41.4
C5: Uc | D5: V | E5: 400
C6: I | D6: A | E6: =E4*1000/(SQRT(3)*E5) -> 59.755753
C8: In | D8: A | E8: 80
C9: Z | D9: W/km | E9: 1.082
C10: L | D10: km | E10: 0.21
C11: DU | D11: V | E11: =E8*E9*E10 -> 18.1776
C12: Du | D12: % | E12: =E11/(E5/SQRT(3)) -> 0.078711317

Sheet 11
A1: Balanço de potência industrial
C3: Us = | D3: =D4/SQRT(3) -> 230.94011 | E3: V | S3: Exame 03/Fev/2016
C4: Uc = | D4: 400 | E4: V
B6: Saída 3 - Escritório | S6: P (kW) | T6: Q (kvar) | U6: S (kVA)
C7: BALANÇO DE POTÊNCIA MONOFÁSICO | S7: 31.7 | T7: 18.8
C8: Designação | D8: Obs | E8: Pinst (kW) | F8: cos j | G8: Ku | H8: Ks | I8: P (kW) | J8: Q (kVAr) | S8: 7.3 | T8: 0
C9: Tomadas | D9: 3x(10x16) | E9: =$D$3*3*10*16/1000 -> 110.85125 | F9: 1 | G9: 1 | H9: 0.2 | I9: =E9*G9*H9 -> 22.17025 | J9: =I9*TAN(ACOS(F9)) -> 0 | S9: 33 | T9: 13.5
C10: Aquecimento | D10: 12x1kW | E10: =12*1 -> 12 | F10: 1 | G10: 1 | H10: 1 | I10: =E10*G10*H10 -> 12 | J10: =I10*TAN(ACOS(F10)) -> 0 | S10: 46.4 | T10: 7.2
C11: Iluminação | D11: 6x16lum (2x36W)+25% | E11: =6*16*2*36*1.25/1000 -> 8.64 | F11: 0.6 | G11: 1 | H11: 1 | I11: =E11*G11*H11 -> 8.64 | J11: =I11*TAN(ACOS(F11)) -> 11.52 | S11: 12.1 | T11: 5.4
C12: TOTAL | I12: =SUM(I9:I11) -> 42.81025 | J12: =SUM(J9:J11) -> 11.52 | M12: Ib (A) | N12: cos j | S12: 9.1 | T12: 4.3
M13: =N18*1000/(3*D3) -> 93.947477 | N13: =L18/N18 -> 0.96919675 | S13: 42 | T13: 54.7
C14: BALANÇO DE POTÊNCIA TRIFÁSICO | S14: =7*22/0.9*0.7 -> 119.77778 | T14: =S14*TAN(ACOS(0.83)) -> 80.491156
C15: Designação | D15: Obs | E15: Pinst (kW) | F15: cos j | G15: Ku | H15: Ks | I15: Pu (kW) | J15: Qu (kVAr)
C16: Aquecimento | D16: 6 kW | E16: 6 | F16: 1 | G16: 1 | H16: 1 | I16: =E16*G16*H16 -> 6 | J16: =I16*TAN(ACOS(F16)) -> 0 | L16: Ptotal (kW) | M16: Qtotal (kVAr) | N16: Stotal (kVA) | S16: =SUM(S7:S15) -> 301.37778 | T16: =SUM(T7:T15) -> 184.39116 | U16: =SQRT(S16^2+T16^2) -> 353.311
C17: UPS | D17: Iamont=18A | E17: =SQRT(3)*D4*18*0.95/1000 -> 11.847228 | F17: 0.95 | G17: 1 | H17: 1 | I17: =E17*G17*H17 -> 11.847228 | J17: =I17*TAN(ACOS(F17)) -> 3.8939954 | L17: =I12+I18 -> 60.657478 | M17: =J12+J18 -> 15.413995 | N17: =SQRT(L17^2+M17^2) -> 62.585309 | O17: Sem perdas | U17: 0.9
C18: TOTAL | I18: =SUM(I16:I17) -> 17.847228 | J18: =SUM(J16:J17) -> 3.8939954 | L18: =L17*1.04 -> 63.083777 | M18: =M17*1.04 -> 16.030555 | N18: =SQRT(L18^2+M18^2) -> 65.088721 | O18: Com perdas | U18: =U16*0.9 -> 317.9799
C20: Considerando as cargas das saídas monofásicas repartidas sobre as 3 fases de forma equilibrada na saída do transformador. | T20: Sn | U20: 1000
T21: FC | U21: =U18/U20 -> 0.3179799
B24: Saída 4 - Estação de bombagem
C25: Motor | D25: Pn (kW) | E25: h | F25: cos j | G25: Ku | H25: P (kW) | I25: Q (kVAr) | J25: S (kVAr) | K25: Ib(A)
C26: M1 | D26: 11 | E26: 0.87 | F26: 0.86 | G26: 1 | H26: =D26/E26*G26 -> 12.643678 | I26: =H26*TAN(ACOS(F26)) -> 7.502318 | J26: =SQRT(H26^2+I26^2) -> 14.701951 | K26: =J26*1000/(3*$D$3) -> 21.220439
C27: M2 | D27: 22 | E27: 0.89 | F27: 0.86 | G27: 1 | H27: =D27/E27*G27 -> 24.719101 | I27: =H27*TAN(ACOS(F27)) -> 14.667453 | J27: =SQRT(H27^2+I27^2) -> 28.743141 | K27: =J27*1000/(3*$D$3) -> 41.48715
C28: M3 | D28: 37 | E28: 0.9 | F28: 0.86 | G28: 1 | H28: =D28/E28*G28 -> 41.111111 | I28: =H28*TAN(ACOS(F28)) -> 24.393901 | J28: =SQRT(H28^2+I28^2) -> 47.803618 | K28: =J28*1000/(3*$D$3) -> 68.998579 | L28: Ib (A) | M28: cos j | N28: In
C29: TOTAL | H29: =SUM(H26:H28) -> 78.47389 | I29: =SUM(I26:I28) -> 46.563672 | J29: =SUM(J26:J28) -> 91.24871 | L29: =J29/(3*$D$3)*1000 -> 131.70617 | M29: =H29/J29 -> 0.86 | N29: 160
B32: Saída 5 - Ventilador - extrator
D33: Pn (kW) | E33: h | F33: cos j | G33: Ku | H33: P (kW) | I33: Q (kVAr) | J33: S (kVAr) | L33: Ib (A) | M33: cos j | N33: In
D34: 75 | E34: 0.92 | F34: 0.87 | G34: 0.8 | H34: =D34/E34*G34 -> 65.217391 | I34: =H34*TAN(ACOS(F34)) -> 36.960399 | J34: =SQRT(H34^2+I34^2) -> 74.962519 | L34: =J34/(3*$D$3)*1000 -> 108.19908 | M34: =H34/J34 -> 0.87 | N34: 125
B37: Saída 6 - Ponte rolante
D38: Pn (kW) | E38: h | F38: cos j | G38: Ku | H38: P (kW) | I38: Q (kVAr) | J38: S (kVAr) | L38: Ib (A) | M38: cos j | N38: In
D39: 110 | E39: 0.93 | F39: 0.87 | G39: 1 | H39: =D39/E39*G39 -> 118.27957 | I39: 0 | J39: =SQRT(H39^2+I39^2) -> 118.27957 | L39: =J39/(3*$D$3)*1000 -> 170.72185 | M39: =H39/J39 -> 1 | N39: 200
B41: Saída 7 - Oficina
E42: Stotal (kVA) | F42: Ks | G42: cos j | H42: P (kW) | I42: Q (kVAr) | J42: S (kVAr) | L42: Ib (A) | M42: cos j | N42: In
E43: 340 | F43: 0.8 | G43: 0.8 | H43: =J43*G43 -> 217.6 | I43: =SQRT(J43^2-H43^2) -> 163.2 | J43: =E43*F43 -> 272 | L43: =J43/SQRT(3)/$D$4*1000 -> 392.59818 | M43: =H43/J43 -> 0.8 | N43: 400
B45: QGBT
C47: Carga | D47: Saída | E47: P (kW) | F47: Q (kW) | G47: S (kVA) | H47: Ib (A) | I47: In (A)
C48: Escritório | D48: 3 | E48: =L18 -> 63.083777 | F48: =M18 -> 16.030555 | G48: =N18 -> 65.088721 | H48: =G48*1000/SQRT(3)/$D$4 -> 93.947477 | I48: 100
C49: Estação de bombagem | D49: 4 | E49: =H29 -> 78.47389 | F49: =I29 -> 46.563672 | G49: =J29 -> 91.24871 | H49: =G49*1000/SQRT(3)/$D$4 -> 131.70617 | I49: 160
C50: Extrator | D50: 5 | E50: =H34 -> 65.217391 | F50: =I34 -> 36.960399 | G50: =J34 -> 74.962519 | H50: =G50*1000/SQRT(3)/$D$4 -> 108.19908 | I50: 125
C51: Ponte rolante | D51: 6 | E51: =H39 -> 118.27957 | F51: =I39 -> 0 | G51: =J39 -> 118.27957 | H51: =G51*1000/SQRT(3)/$D$4 -> 170.72185 | I51: 200
C52: Oficina | D52: 7 | E52: =H43 -> 217.6 | F52: =I43 -> 163.2 | G52: =J43 -> 272 | H52: =G52*1000/SQRT(3)/$D$4 -> 392.59818 | I52: 400 | K52: Reserva | L52: Sc (kVA) | M52: Sn (kVA) | N52: IB (A) | O52: cos j
...

Sheet 12.1
B2: 1. -Fatores de Influências Externas
C4: Ordem | D4: 1.ª Letra | E4: 2.ª Letra | F4: Algarismo | G4: Estrutura do Código | H4: Situação Normal | I4: Designação da Influência
D5: Categoria Geral | E5: Natureza da Influência | F5: Classe da Influência
C6: 1 | D6: A (Ambientes) | E6: A | F6: 1 a 8 | G6: ="A"&E6&"X" -> AAX | H6: ="A"&E6&"4" -> AA4 | I6: Temperatura ambiente
C7: 2 | E7: B | F7: 1 a 8 | G7: ="A"&E7&"X" -> ABX | H7: ="A"&E7&"4" -> AB4 | I7: Condições climáticas
C8: 3 | E8: C | F8: 1 a 2 | G8: ="A"&E8&"X" -> ACX | H8: ="A"&E8&"1" -> AC1 | I8: Altitude
C9: 4 | E9: D | F9: 1 a 8 | G9: ="A"&E9&"X" -> ADX | H9: ="A"&E9&"1" -> AD1 | I9: Presença de água
C10: 5 | E10: E | F10: 1 a 6 | G10: ="A"&E10&"X" -> AEX | H10: ="A"&E10&"1" -> AE1 | I10: Presença de corpos sólidos (estranhos)
C11: 6 | E11: F | F11: 1 a 4 | G11: ="A"&E11&"X" -> AFX | H11: ="A"&E11&"1" -> AF1 | I11: Presença de corpos e substâncias corrosivas ou poluentes
C12: 7 | E12: G | F12: 1 a 3 | G12: ="A"&E12&"X" -> AGX | H12: ="A"&E12&"1" -> AG1 | I12: Ações mecânicas (impactos)
C13: 8 | E13: H | F13: 1 a 3 | G13: ="A"&E13&"X" -> AHX | H13: ="A"&E13&"1" -> AH1 | I13: Ações mecânicas (vibrações)
C14: 9 | E14: J | F14: 1 | G14: ="A"&E14&"X" -> AJX | H14: ="A"&E14&"1" -> AJ1 | I14: Ações mecânicas (outros)
C15: 10 | E15: K | F15: 1 a 2 | G15: ="A"&E15&"X" -> AKX | H15: ="A"&E15&"1" -> AK1 | I15: Presença da flora e bolores
C16: 11 | E16: L | F16: 1 a 2 | G16: ="A"&E16&"X" -> ALX | H16: ="A"&E16&"1" -> AL1 | I16: Presença de fauna
C17: 12 | E17: M | F17: 1 a 6 | G17: ="A"&E17&"X" -> AMX | H17: ="A"&E17&"1" -> AM1 | I17: Influências electromagnéticas, electrostáticas ou ionizantes
C18: 13 | E18: N | F18: 1 a 3 | G18: ="A"&E18&"X" -> ANX | H18: ="A"&E18&"1" -> AN1 | I18: Radiações solares
C19: 14 | E19: P | F19: 1 a 4 | G19: ="A"&E19&"X" -> APX | H19: ="A"&E19&"1" -> AP1 | I19: Efeitos sísmicos
C20: 15 | E20: Q | F20: 1 a 3 | G20: ="A"&E20&"X" -> AQX | H20: ="A"&E20&"1" -> AQ1 | I20: Descargas atmosféricas, nível cerâunico (N)
C21: 16 | E21: R | F21: 1 a 3 | G21: ="A"&E21&"X" -> ARX | H21: ="A"&E21&"1" -> AR1 | I21: Movimentos do ar
C22: 17 | E22: S | F22: 1 a 3 | G22: ="A"&E22&"X" -> ASX | H22: ="A"&E22&"1" -> AS1 | I22: Vento
C23: 18 | D23: B (Utilizações) | E23: A | F23: 1 a 5 | G23: ="B"&E23&"X" -> BAX | H23: ="B"&E23&"1" -> BA1 | I23: Competência das pessoas
C24: 19 | E24: B | F24: 1 a 3 | G24: ="B"&E24&"X" -> BBX | H24: ="B"&E24&"1" -> BB1 | I24: Resistência eléctrica do corpo humano
C25: 20 | E25: C | F25: 1 a 4 | G25: ="B"&E25&"X" -> BCX | H25: ="B"&E25&"2" -> BC2 | I25: Contacto das pessoas com o potencial da terra
C26: 21 | E26: D | F26: 1 a 4 | G26: ="B"&E26&"X" -> BDX | H26: ="B"&E26&"1" -> BD1 | I26: Evacuação das pessoas em caso de emergência
C27: 22 | E27: E | F27: 1 a 4 | G27: ="B"&E27&"X" -> BEX | H27: ="B"&E27&"1" -> BE1 | I27: Natureza dos produtos tratados ou armazenados
C28: 23 | D28: C (Construção dos Edifícios) | E28: A | F28: 1 a 2 | G28: ="A"&E28&"X" -> AAX | H28: ="B"&E28&"1" -> BA1 | I28: Materiais de construção
C29: 24 | E29: B | F29: 1 a 4 | G29: ="A"&E29&"X" -> ABX | H29: ="B"&E29&"1" -> BB1 | I29: Estrutura dos edifícios

Sheet 12.2
B3: 2. -Classificação dos Fatores de Influências Externas de uma VIVENDA
C5: ZONA | D5: DEPENDÊNCIA | E5: CLASSIFICAÇÃO | F5: IP | G5: IK
C6: Habitação | D6: Hall de entrada | E6: AA4 + AB4 + BC2 + XX1 | F6: IP 20 | G6: IK 04
D7: Corredores | E7: AA4 + AB4 + BC2 + XX1 | F7: IP 20 | G7: IK 04
D8: Escritórios | E8: AA4 + AB4 + BC2 + XX1 | F8: IP 20 | G8: IK 04
D9: Cozinhas | E9: AA4 + AB4 + BC2 + XX1 + AD2 | F9: IP 21 | G9: IK 04
D10: Salas de jantar | E10: AA4 + AB4 + BC2 + XX1 | F10: IP 20 | G10: IK 04
D11: Salas de estar | E11: AA4 + AB4 + BC2 + XX1 | F11: IP 20 | G11: IK 04
D12: Alpendres | E12: BC2 + XX1 + AA7 + AB7 + AD4 + AE4 + AL2 + AR2 + AS2 | F12: IP 54 | G12: IK 04
D13: Quartos | E13: AA4 + AB4 + BC2 + XX1 | F13: IP 20 | G13: IK 04
D14: Casas de Banho (Volume 0) | E14: AA4 + AB4 + XX1+ AD7 + BB3 + BC3 | F14: IP 27 | G14: IK 04
D15: Casas de Banho (Volume 1) | E15: AA4 + AB4 + XX1 + AD5 + BB3 + BC3 | F15: IP 25 | G15: IK 04
D16: Casas de Banho (Volume 2) | E16: AA4 + AB4 + XX1 + AD4 + BB3 + BC3 | F16: IP 24 | G16: IK 04
D17: Casas de Banho (Volume 3) | E17: AA4 + AB4 + XX1 + BB2 + BC3 | F17: IP 21 | G17: IK 04
D18: Terraços descobertos | E18: BC2 + XX1 + AA8 + AB8 + AD5 + AE3 + AN2 + AQ3 + AR3 + AS3 | F18: IP 45 | G18: IK 04
... D20: Varandas descobertas | E20: BC2 + XX1 + AA8 + AB8 + AD5 + AN2 + AR2 + AS2 | F20: IP 45 | G20: IK 04
C21: Anexo | D21: Garagens (h>2m) | E21: AA4 + AB4 + BC2 + XX1 + AE3 + AG3 + BE2 | F21: IP 40 | G21: IK 08
D22: Garagens (h<=2m) | E22: AA4 + AB4 + BC2 + XX1 + AE3 + AG3 + BE2 | F22: IP 40 | G22: IK 08
D23: Lavandarias | E23: AA4 + AB4 + BC2 + XX1 + AD2 + AE4 | F23: IP 51 | G23: IK 04
D24: Arrumos | E24: AA4 + AB4 + BC2 + XX1 + BB2 | F24: IP 20 | G24: IK 04
D25: Casas das máquinas | E25: AA4 + AB4 + XX1 + AG2 + AH2 + BA4 + BC3 | F25: IP 20 | G25: IK 07
D26: Churrasqueiras | E26: XX1 + AA7 + AB7 + AD2 + BC3 | F26: IP 21 | G26: IK 04
D27: Balneários (Volume 0) | E27: AA4 + AB4 + XX1+ AD7 + BB3 + BC3 | F27: IP 27 | G27: IK 04
D28: Balneários (Volume 1) | E28: AA4 + AB4 + XX1 + AD5 + BB3 + BC3 | F28: IP 25 | G28: IK 04
D29: Balneários (Volume 2) | E29: AA4 + AB4 + XX1 + AD4 + BB3 + BC3 | F29: IP 24 | G29: IK 04
D30: Balneários (Volume 3) | E30: AA4 + AB4 + XX1 + BB2 + BC3 | F30: IP 21 | G30: IK 04
C31: Jardim da frente | D31: Lago com ilum. (Volume 0) | E31: XX1 + AA8 + AB8 + AD8 + BB3 + BC3 | F31: IP 28 | G31: IK 04
D32: Lago com ilum. (Volume 1) | E32: XX1 + AA8 + AB8 + AD5 + BB3 + BC3 | F32: IP 25 | G32: IK 04
D33: Lago com ilum. (Volume 2) | E33: XX1 + AA8 + AB8 + AD4 + BB2 + BC3 | F33: IP 24 | G33: IK 04
C34: Jardim traseiro | D34: Piscina com ilum. (Volume 0) | E34: XX1 + AA8 + AB8 + AD8 + BB3 + BC3 | F34: IP 28 | G34: IK 04
D35: Piscina com ilum. (Volume 1) | E35: XX1 + AA8 + AB8 + AD5 + BB3 + BC3 | F35: IP 25 | G35: IK 04
D36: Piscina com ilum. (Volume 2) | E36: XX1 + AA8 + AB8 + AD4 + BB2 + BC3 | F36: IP 24 | G36: IK 04

Sheet 14
B3: 1. Queda de tensão da saída 5
C8: Queda de tensão | D8: u | E8: V | F8: =F11*(F12*F13/F14*F15+F16/1000*F13*SIN(ACOS(F15)))*F17 -> 6.6740772
C9: Queda de tensão | D9: Du | E9: % | F9: =F8/F10 -> 0.029017727 | M9: b
C10: Tensão simples | D10: U | E10: V | F10: 230 | L10: Trifásico equilibrado | M10: 1
C11: Sistema | D11: b | E11: mono, tri? | F11: 1 | L11: Monofásico ou trifásico desequilibrado | M11: 2
C12: Resistividade | D12: r1 | E12: W.mm2/m | F12: 0.0225
C13: Comprimento | D13: L | E13: m | F13: 75 | M13: r1
C14: Secção | D14: S | E14: mm2 | F14: 25 | L14: Cobre | M14: 0.0225
C15: Fator de potência | D15: cos j | E15: - | F15: ='11'!M34 -> 0.87 | L15: Alumínio | M15: 0.036
C16: Reatância linear | D16: l | E16: mW/m | F16: 0.08
C17: Corrente de serviço | D17: IB | E17: A | F17: ='11'!L34 -> 108.19908 | J17: Quadro 52O | L17: Iluminação | M17: Outros
K18: Alimentação BT | L18: 0.03 | M18: 0.05
K19: Alimentação MT/BT | L19: 0.06 | M19: 0.08
B26: 2. Intensidade estipulada de fusível gG
C28: Fusível gG
C29: LSVAV 4x95 mm2
M30: MR | O30: In
C31: Isolamento | D31: - | F31: PVC | G31: Anexo IIB | K31: PVC | M31: A | O31: 2
C32: Condutor | F32: Alumínio | G32: Anexo IIB | K32: XLPE, EPR | M32: A2 | O32: 4
C33: Método de referência | D33: - | F33: D | G33: Quadro 52H | M33: B | O33: 6
C34: Condutores carregados | D34: cond | F34: 3 | K34: Cobre | M34: B2 | O34: 8
C35: Corrente admissível | D35: Iz | E35: A | F35: 197 | G35: Quadro 52-C30 | K35: Alumínio | M35: C | O35: 10
C36: Fator de correção 52-D1 | D36: FC1 | F36: 1 | G36: Quadro 52-D1 | M36: D | O36: 12
C37: Fator de correção 52-D2 | D37: FC2 | F37: 0.95 | G37: Quadro 52-D2 | M37: E | O37: 16
C38: Fator de correção 52-E1 | D38: FC3 | F38: 1 | G38: Quadro 52-E1 | M38: F | O38: 20
C39: Fator de correção 52-E2 | D39: FC4 | F39: 1 | G39: Quadro 52-E2 | M39: G | O39: 25
C40: Fator de correção 52-E3 | D40: FC5 | F40: 1 | G40: Quadro 52-E3 | K40: k2 | O40: 32
C41: Fator de correção 52-E4 | D41: FC6 | F41: 1 | G41: Quadro 52-E4 | J41: Disjuntor modular | K41: 1.45 | O41: 40
C42: Fator de correção 52-E5 | D42: FC7 | F42: 1 | G42: Quadro 52-E5 | J42: Disjuntor outros | K42: 1.3 | O42: 50
C43: Fator de correção total | D43: FC.total | F43: =F36*F37*F38*F39*F40*F41*F42 -> 0.95 | J43: Fusível (In >= 16 A) | K43: 1.6 | O43: 63
C44: Corrente admissível corrigida | D44: I'z | E44: A | F44: =F35*F43 -> 187.15 | J44: Fusível (4 < In< 16 A) | K44: 1.9 | O44: 80
C45: Corrente estipulada do fusível | D45: In | E45: A | F45: 160 | J45: Fusível (In <= 4 A) | K45: 2.1 | O45: 100
C46: Condição In <= I'z? | D46: In <= I'z | E46: ? | F46: =IF($F$45<=$F$44,"OK!","!!!!!!!!!") -> OK! | O46: 125
C47: Relação entre I2 e In | D47: k2 | E47: - | F47: 1.6 | O47: 160
C48: Corrente convencional de funcionamento | D48: I2 | E48: A | F48: =F47*F45 -> 256 | O48: 200
C49: Valor limite térmico da canalização | D49: 1,45xI'z | E49: A | F49: =1.45*F44 -> 271.3675 | O49: 250
C50: Condição I2 <= 1.45.I'z | D50: I2 <= 1.45.I'z | E50: ? | F50: =IF($F$48<=$F$49,"OK!","!!!!!!!!!") -> OK! | O50: 315
C51: RESPOSTA: | D51: In | E51: A | F51: =F45 -> 160 | O51: 400
O52: 500
O53: 630
...

Sheet 07.1
H2: Valores em mW
H4: Resistência | I4: Reatância | J4: Impedância | K4: R.acum | L4: X.acum | M4: Z.acum | N4: Ik3
H5: mW | I5: mW | J5: mW | K5: mW | L5: mW | M5: mW | N5: kA
H7: Ra = 0,1.Xa | I7: Xa = 0,995.Za | J7: Za = (m.Un)^2/Scc
F8: Za | G8: Rede a montante | H8: =I8*0.1 -> 0.0351036 | I8: =J8*0.995 -> 0.351036 | J8: =(D29*D30)^2/(D28*10^6)*1000 -> 0.3528 | K8: =H8 -> 0.0351036 | L8: =I8 -> 0.351036 | M8: =J8 -> 0.3528 | N8: =$D$27*$D$29*$D$30/(SQRT(3)*M8) -> 721.68784
F10: Zt | G10: Transformador | H10: Rt = 0,31.Zt | I10: Xt = 0,95.Zt | J10: Zt = (mUn)^2.Ucc/(Sn.100)
H11: =0.31*J11 -> 4.1013 | I11: =0.95*J11 -> 12.5685 | J11: =(D29*D30)^2*D32/D31/1000/100*1000 -> 13.23 | K11: =H11+H8 -> 4.1364036 | L11: =I11+I8 -> 12.919536 | M11: =SQRT(K11^2+L11^2) -> 13.565554 | N11: =$D$27*$D$29*$D$30/(SQRT(3)*M11) -> 18.76897
F13: Zcabo1 | G13: Cabo QGBT-D1 | H13: Rc1 = r.L/S | I13: Xc1 = 0,08.L | J13: Zc1 = raizq(Rc1^2+Xc1^2)
H14: =D33*D35/D36*1000 -> 0.15625 | I14: =0.08*D35/3 -> 0.13333333 | J14: =SQRT(H14^2+I14^2) -> 0.20540652 | K14: =K11+H14 -> 4.2926536 | L14: =L11+I14 -> 13.052869 | M14: =SQRT(K14^2+L14^2) -> 13.740607 | N14: =$D$27*$D$29*$D$30/(SQRT(3)*M14) -> 18.529856
F16: Zd1 | G16: Disjuntor1 | H16: Rd = 0 | I16: Xd = 0,15 mW/pólo | J16: Zd = Xd
H17: 0 | I17: =0.15 -> 0.15 | J17: =I17 -> 0.15 | K17: =K14+H17 -> 4.2926536 | L17: =L14+I17 -> 13.202869 | M17: =SQRT(K17^2+L17^2) -> 13.883178 | N17: =$D$27*$D$29*$D$30/(SQRT(3)*M17) -> 18.339567
F19: Zb | G19: Barramento | H19: Rb = r.L/S | I19: Xb = 0,15 mW/m | J19: Zb = raizq(Rb^2+Xb^2)
H20: =D33*D37/D38*1000 -> 0.225 | I20: =0.15*D37 -> 0.75 | J20: =SQRT(H20^2+I20^2) -> 0.78302299 | K20: =K17+H20 -> 4.5176536 | L20: =L17+I20 -> 13.952869 | M20: =SQRT(K20^2+L20^2) -> 14.666007 | N20: =$D$27*$D$29*$D$30/(SQRT(3)*M20) -> 17.360654
F22: Zd2 | G22: Disjuntor2 | H22: Rd = 0 | I22: Xd = 0,15 mW/pólo | J22: Zd = Xd
H23: 0 | I23: =0.15 -> 0.15 | J23: =I23 -> 0.15 | K23: =K20+H23 -> 4.5176536 | L23: =L20+I23 -> 14.102869 | M23: =SQRT(K23^2+L23^2) -> 14.808785 | N23: =$D$27*$D$29*$D$30/(SQRT(3)*M23) -> 17.193272
F25: Zcabo2 | G25: Cabo QGBT-D1 | H25: Rc2 = r.L/S | I25: Xc2 = 0,08.L | J25: Zc1 = raizq(Rc2^2+Xc2^2)
H26: =D33*D39/D40*1000 -> 23.684211 | I26: =0.08*D39 -> 8 | J26: =SQRT(H26^2+I26^2) -> 24.998837 | K26: =K23+H26 -> 28.201864 | L26: =L23+I26 -> 22.102869 | M26: =SQRT(K26^2+L26^2) -> 35.831299 | N26: =$D$27*$D$29*$D$30/(SQRT(3)*M26) -> 7.1058398
B27: Cmax | C27: - | D27: 1.05
B28: Scc | C28: MVA | D28: 500
B29: m | C29: - | D29: 1.05 | H29: =H4 -> Resistência | I29: =I4 -> Reatância | J29: =J4 -> Impedância | K29: =K4 -> R.acum | L29: =L4 -> X.acum | M29: =M4 -> Z.acum | N29: =N4 -> Ik3
B30: Un | C30: V | D30: 400 | H30: mW | I30: mW | J30: mW | K30: mW | L30: mW | M30: mW | N30: =N5 -> kA
B31: Sn | C31: kVA | D31: 800 | F31: =F8 -> Za | G31: =G8 -> Rede a montante | H31: =H8 -> 0.0351036 | I31: =I8 -> 0.351036 | J31: =J8 -> 0.3528 | K31: =K8 -> 0.0351036 | L31: =L8 -> 0.351036 | M31: =M8 -> 0.3528 | N31: =N8 -> 721.68784
B32: Ucc | C32: % | D32: 6 | F32: =F10 -> Zt | G32: =G10 -> Transformador | H32: =H11 -> 4.1013 | I32: =I11 -> 12.5685 | J32: =J11 -> 13.23 | K32: =K11 -> 4.1364036 | L32: =L11 -> 12.919536 | M32: =M11 -> 13.565554 | N32: =N11 -> 18.76897
B33: rcu | C33: W.mm2/m | D33: 0.0225 | F33: =F13 -> Zcabo1 | G33: =G13 -> Cabo QGBT-D1 | H33: =H14 -> 0.15625 | I33: =I14 -> 0.13333333 | J33: =J14 -> 0.20540652 | K33: =K14 -> 4.2926536 | L33: =L14 -> 13.052869 | M33: =M14 -> 13.740607 | N33: =N14 -> 18.529856
B34: ral | C34: W.mm2/m | D34: 0.036 | F34: =F16 -> Zd1 | G34: =G16 -> Disjuntor1 | H34: =H17 -> 0 | I34: =I17 -> 0.15 | J34: =J17 -> 0.15 | K34: =K17 -> 4.2926536 | L34: =L17 -> 13.202869 | M34: =M17 -> 13.883178 | N34: =N17 -> 18.339567
B35: L.C1 | C35: m | D35: 5 | F35: =F19 -> Zb | G35: =G19 -> Barramento | H35: =H20 -> 0.225 | I35: =I20 -> 0.75 | J35: =J20 -> 0.78302299 | K35: =K20 -> 4.5176536 | L35: =L20 -> 13.952869 | M35: =M20 -> 14.666007 | N35: =N20 -> 17.360654
B36: S.C1 | C36: mm2 | D36: =240*3 -> 720 | F36: =F22 -> Zd2 | G36: =G22 -> Disjuntor2 | H36: =H23 -> 0 | I36: =I23 -> 0.15 | J36: =J23 -> 0.15 | K36: =K23 -> 4.5176536 | L36: =L23 -> 14.102869 | M36: =M23 -> 14.808785 | N36: =N23 -> 17.193272
B37: L.b | C37: m | D37: 5 | F37: =F25 -> Zcabo2 | G37: =G25 -> Cabo QGBT-D1 | H37: =H26 -> 23.684211 | I37: =I26 -> 8 | J37: =J26 -> 24.998837 | K37: =K26 -> 28.201864 | L37: =L26 -> 22.102869 | M37: =M26 -> 35.831299 | N37: =N26 -> 7.1058398
B38: S.b | C38: mm2 | D38: =100*5 -> 500
B39: L.C2 | C39: m | D39: 100
B40: S.C2 | C40: mm2 | D40: 95

Sheet 07.2
H2: Valores em mW
H4: Resistência | I4: Reatância | J4: Impedância | K4: R.acum | L4: X.acum | M4: Z.acum | N4: Ik3
H5: mW | I5: mW | J5: mW | K5: mW | L5: mW | M5: mW | N5: kA
H7: Ra = 0,1.Xa | I7: Xa = 0,995.Za | J7: Za = (m.Un)^2/Scc
F8: Za | G8: Rede a montante | H8: =I8*0.1 -> 0.0351036 | I8: =J8*0.995 -> 0.351036 | J8: =(D29*D30)^2/(D28*10^6)*1000 -> 0.3528 | K8: =H8 -> 0.0351036 | L8: =I8 -> 0.351036 | M8: =J8 -> 0.3528 | N8: =$D$27*$D$29*$D$30/(SQRT(3)*M8) -> 721.68784
B10: Saída Q41 | F10: Zt | G10: Transformador | H10: Rt = 0,31.Zt | I10: Xt = 0,95.Zt | J10: Zt = (mUn)^2.Ucc/(Sn.100)
H11: =0.31*J11 -> 1.3671 | I11: =0.95*J11 -> 4.1895 | J11: =(D29*D30)^2*D32/D31/1000/100*1000 -> 4.41 | K11: =H11+H8 -> 1.4022036 | L11: =I11+I8 -> 4.540536 | M11: =SQRT(K11^2+L11^2) -> 4.7521197 | N11: =$D$27*$D$29*$D$30/(SQRT(3)*M11) -> 53.578504
F13: Zcabo1 | G13: Cabo QGBT-D1 | H13: Rc1 = r.L/S/2 | I13: Xc1 = 0,085.L | J13: Zc1 = raizq(Rc1^2+Xc1^2)
F14: 1//2 | H14: =D33*D35/D36*1000/2 -> 0.1875 | I14: =0.085*D35/4/2 -> 0.10625 | J14: =SQRT(H14^2+I14^2) -> 0.21551175 | K14: =K11+H14 -> 1.5897036 | L14: =L11+I14 -> 4.646786 | M14: =SQRT(K14^2+L14^2) -> 4.911189 | N14: =$D$27*$D$29*$D$30/(SQRT(3)*M14) -> 51.843142
F16: Zd1 | G16: Disjuntor1 | H16: Rd = 0 | I16: Xd = 0,15 mW/pólo | J16: Zd = Xd
F17: d1//d2 | H17: 0 | I17: =0.15/2 -> 0.075 | J17: =I17 -> 0.075 | K17: =K14+H17 -> 1.5897036 | L17: =L14+I17 -> 4.721786 | M17: =SQRT(K17^2+L17^2) -> 4.9822104 | N17: =$D$27*$D$29*$D$30/(SQRT(3)*M17) -> 51.104118
F19: Zb1 | G19: Barramento1 | H19: Rb = r.L/S | I19: Xb = 0,15 mW/m | J19: Zb = raizq(Rb^2+Xb^2)
G20: 2x100x10, 5m | H20: =D33*D37/D38*1000 -> 0.05625 | I20: =0.15*D37 -> 0.75 | J20: =SQRT(H20^2+I20^2) -> 0.75210642 | K20: =K17+H20 -> 1.6459536 | L20: =L17+I20 -> 5.471786 | M20: =SQRT(K20^2+L20^2) -> 5.7139833 | N20: =$D$27*$D$29*$D$30/(SQRT(3)*M20) -> 44.559365
F22: Zd4 | G22: Disjuntor4 | H22: Rd = 0 | I22: Xd = 0,15 mW/pólo | J22: Zd = Xd
H23: 0 | I23: =0.15 -> 0.15 | J23: =I23 -> 0.15 | K23: =K20+H23 -> 1.6459536 | L23: =L20+I23 -> 5.621786 | M23: =SQRT(K23^2+L23^2) -> 5.8577847 | N23: =$D$27*$D$29*$D$30/(SQRT(3)*M23) -> 43.465488
F25: Zcabo4 | G25: Cabo Q4-Q40 | H25: Rc4 = r.L/S | I25: Xc4 = 0,08.L | J25: Zc1 = raizq(Rc4^2+Xc4^2)
H26: =D33*D39/D40*1000 -> 102.85714 | I26: =0.08*D39 -> 25.6 | J26: =SQRT(H26^2+I26^2) -> 105.99506 | K26: =K23+H26 -> 104.5031 | L26: =L23+I26 -> 31.221786 | M26: =SQRT(K26^2+L26^2) -> 109.0674 | N26: =$D$27*$D$29*$D$30/(SQRT(3)*M26) -> 2.3344416
B27: Cmax | C27: - | D27: 1.05
B28: Scc | C28: MVA | D28: 500 | F28: Zb2 | G28: Barramento2 | H28: Rb = r.L/S | I28: Xb = 0,15 mW/m | J28: Zb = raizq(Rb^2+Xb^2)
B29: m | C29: - | D29: 1.05 | G29: 1x15x3, 3m | H29: =D33*D43/D44*1000 -> 1.5 | I29: =0.15*D43 -> 0.45 | J29: =SQRT(H29^2+I29^2) -> 1.566046 | K29: =K26+H29 -> 106.0031 | L29: =L26+I29 -> 31.671786 | M29: =SQRT(K29^2+L29^2) -> 110.63344 | N29: =$D$27*$D$29*$D$30/(SQRT(3)*M29) -> 2.301397
B30: Un | C30: V | D30: 400
B31: Sn | C31: kVA | D31: ='11'!M53*2 -> 2000 | F31: Zd41 | G31: Disjuntor41 | H31: Rd = 0 | I31: Xd = 0,15 mW/pólo | J31: Zd = Xd
B32: Ucc | C32: % | D32: 5 | H32: 0 | I32: =0.15 -> 0.15 | J32: =I32 -> 0.15 | K32: =K29+H32 -> 106.0031 | L32: =L29+I32 -> 31.821786 | M32: =SQRT(K32^2+L32^2) -> 110.67648 | N32: =$D$27*$D$29*$D$30/(SQRT(3)*M32) -> 2.3005021
B33: rcu | C33: W.mm2/m | D33: 0.0225
B34: ral | C34: W.mm2/m | D34: 0.036 | F34: Zcabo41 | G34: Cabo Q40-Q41 | H34: Rc2 = r.L/S | I34: Xc2 = 0,08.L | J34: Zc1 = raizq(Rc2^2+Xc2^2)
B35: L.C1 | C35: m | D35: ='14'!F88 -> 10 | H35: =$D$33*D41/D42*1000 -> 56.25 | I35: =0.08*D41 -> 1.2 | J35: =SQRT(H35^2+I35^2) -> 56.262799 | K35: =K32+H35 -> 162.2531 | L35: =L32+I35 -> 33.021786 | M35: =SQRT(K35^2+L35^2) -> 165.5793 | N35: =$D$27*$D$29*$D$30/(SQRT(3)*M35) -> 1.5377011
B36: S.C1 | C36: mm2 | D36: ='14'!F89 -> 600
B37: L.b1 | C37: m | D37: 5
B38: S.b1 | C38: mm2 | D38: =2*100*10 -> 2000 | H38: =H4 -> Resistência | I38: =I4 -> Reatância | J38: =J4 -> Impedância | K38: =K4 -> R.acum | L38: =L4 -> X.acum | M38: =M4 -> Z.acum | N38: =N4 -> Ik3
B39: L.C2 | C39: m | D39: 320 | H39: mW | I39: mW | J39: mW | K39: mW | L39: mW | M39: mW | N39: =N5 -> kA
B40: S.C2 | C40: mm2 | D40: 70 | F40: =F8 -> Za | G40: =G8 -> Rede a montante | H40: =H8 -> 0.0351036 | I40: =I8 -> 0.351036 | J40: =J8 -> 0.3528 | K40: =K8 -> 0.0351036 | L40: =L8 -> 0.351036 | M40: =M8 -> 0.3528 | N40: =N8 -> 721.68784
B41: L.C3 | C41: m | D41: ='14'!M88 -> 15 | F41: =F10 -> Zt | G41: =G10 -> Transformador | H41: =0.31*J41 -> 1.3671 | I41: =J41*0.95 -> 4.1895 | J41: =(D29*D30)^2*D32/D31/1000/100*1000 -> 4.41 | K41: =K11 -> 1.4022036 | L41: =L11 -> 4.540536 | M41: =M11 -> 4.7521197 | N41: =N11 -> 53.578504
B42: S.C3 | C42: mm2 | D42: ='14'!M96 -> 6 | F42: =F13 -> Zcabo1 | G42: =G13 -> Cabo QGBT-D1 | H42: =H14 -> 0.1875 | I42: =I14 -> 0.10625 | J42: =J14 -> 0.21551175 | K42: =K14 -> 1.5897036 | L42: =L14 -> 4.646786 | M42: =M14 -> 4.911189 | N42: =N14 -> 51.843142
B43: L.b2 | C43: m | D43: 3 | F43: =F16 -> Zd1 | G43: =G16 -> Disjuntor1 | H43: =H17 -> 0 | I43: =I17 -> 0.075 | J43: =J17 -> 0.075 | K43: =K17 -> 1.5897036 | L43: =L17 -> 4.721786 | M43: =M17 -> 4.9822104 | N43: =N17 -> 51.104118
B44: S.b2 | C44: mm2 | D44: =15*3 -> 45 | F44: =F19 -> Zb1 | G44: =G19 -> Barramento1 | H44: =H20 -> 0.05625 | I44: =I20 -> 0.75 | J44: =J20 -> 0.75210642 | K44: =K20 -> 1.6459536 | L44: =L20 -> 5.471786 | M44: =M20 -> 5.7139833 | N44: =N20 -> 44.559365
F45: =F22 -> Zd4 | G45: =G22 -> Disjuntor4 | H45: =H23 -> 0 | I45: =I23 -> 0.15 | J45: =J23 -> 0.15 | K45: =K23 -> 1.6459536 | L45: =L23 -> 5.621786 | M45: =M23 -> 5.8577847 | N45: =N23 -> 43.465488
F46: =F25 -> Zcabo4 | G46: =G25 -> Cabo Q4-Q40 | H46: =H26 -> 102.85714 | I46: =I26 -> 25.6 | J46: =J26 -> 105.99506 | K46: =K26 -> 104.5031 | L46: =L26 -> 31.221786 | M46: =M26 -> 109.0674 | N46: =N26 -> 2.3344416
F47: =F28 -> Zb2 | G47: =G28 -> Barramento2 | H47: =H29 -> 1.5 | I47: =I29 -> 0.45 | J47: =J29 -> 1.566046 | K47: =K29 -> 106.0031 | L47: =L29 -> 31.671786 | M47: =M29 -> 110.63344 | N47: =N29 -> 2.301397
F48: =F31 -> Zd41 | G48: =G31 -> Disjuntor41 | H48: =H32 -> 0 | I48: =I32 -> 0.15 | J48: =J32 -> 0.15 | K48: =K32 -> 106.0031 | L48: =L32 -> 31.821786 | M48: =M32 -> 110.67648 | N48: =N32 -> 2.3005021
F49: =F34 -> Zcabo41 | G49: =G34 -> Cabo Q40-Q41 | H49: =H35 -> 56.25 | I49: =I35 -> 1.2 | J49: =J35 -> 56.262799 | K49: =K35 -> 162.2531 | L49: =L35 -> 33.021786 | M49: =M35 -> 165.5793 | N49: =N35 -> 1.5377011
...

Sheet 07.3
A1: Disjuntor
B4: Dados Máquina
C5: Potência de serviço | D5: kW | E5: 15
C6: Factor de simultaneidade | D6: % | E6: 87
C7: Factor de potência | D7: - | E7: 0.89
B8: Dados Rede
C9: Tensão composta | D9: V | E9: 400
C10: Comprimento | D10: m | E10: 200
C11: Ucc, transformador a montante | D11: % | E11: 4.245
C12: Potência, transformador a montante | D12: kVA | E12: 2000
C13: Ik3.máx | D13: kA | E13: =E12/SQRT(3)/E9/E11*100 -> 68.003565
C14: b, tipo de rede (1-trifásico equilibrado; 2 - outros) | D14: - | E14: 1
C15: Cmax, fator de tensão máximo | D15: - | E15: 1.05
C16: Cmin, fator de tensão mínimo | E16: 0.95
C17: m, fator de carga em vazio | D17: - | E17: 1.05
C18: Regime de neutro | D18: - | E18: TN-C
B19: Dados cabo
C20: Tipo de cabo | D20: - | E20: VAV
C21: Tipo de material condutor | D21: - | E21: Cobre
C22: Resistividade do material condutor a 20 ºC | D22: W.mm2/m | E22: 0.017241 | F22: Anexo VI
C23: Coeficiente de variação de resistividade a 20 ºC | D23: K-1 | E23: 0.00393 | F23: Anexo VI
C24: Temperatura máxima de funcionamento | D24: ºC | E24: 90 | F24: Quadro 52A [523]
C25: Isolamento | D25: - | E25: XLPE | F25: Anexo IIB
C26: k - constante do isolamento cabo | D26: - | E26: 143 | F26: Secção 434
C27: l - Reatância linear do cabo | D27: mW/m | E27: 0.08
C28: Polaridade cabo | D28: - | E28: Multicondutor
C29: Modo instalação | D29: - | E29: Fixados ao tecto
C30: Tipo de colocação | D30: - | E30: -
C31: Secção condutor PEN | D31: mm2 | E31: Igual ao da fase
C32: Agrupamento de cabos | D32: - | E32: 5
B33: Dados bioclimáticos
C34: Temperatura ambiente | D34: ºC | E34: 45
C35: Temperatura do solo | D35: ºC | E35: -
C36: Resistividade térmica terreno | D36: K.m/W | E36: -
B38: IB | C38: Corrente de serviço | D38: A | E38: =E5*E6/100/E7/SQRT(3)/E9*1000 -> 21.164104
C39: Referência do modo de instalação | D39: - | E39: 11A | F39: Quadro 52H
C40: Método de referência do modo de instalação | D40: - | E40: C | F40: Quadro 52H
B42: Factores de correcção
C43: Função da temperatura ambiente | D43: - | E43: 0.87 | F43: Quadro 52-D1
C44: Agrupamento de cabos | D44: - | E44: 0.66 | F44: Quadro 52-E1
...

Sheet 07.4
A1: Fusível
B4: Dados Máquina
C5: Potência instalada | D5: kVA | E5: 100
C6: Potência de serviço | D6: kW | E6: =E5*E8 -> 80
C7: Factor de simultaneidade | D7: % | E7: 100
C8: Factor de potência | D8: - | E8: 0.8
B9: Dados Rede
C10: Tensão composta | D10: V | E10: 400
C11: Comprimento | D11: m | E11: 210
C12: Ucc, transformador a montante | D12: % | E12: 4.5
C13: Potência, transformador a montante | D13: kVA | E13: 1000
C14: Ik3.máx | D14: kA | E14: =E13/SQRT(3)/E10/E12*100 -> 32.075015
C15: b, tipo de rede (1-trifásico equilibrado; 2 - outros) | D15: - | E15: 1
C16: Cmax, fator de tensão máximo | D16: - | E16: 1.05
C17: Cmin, fator de tensão mínimo | E17: 0.95
C18: m, fator de carga em vazio | D18: - | E18: 1.05
C19: Regime de neutro | D19: - | E19: TN-C
B20: Dados cabo
C21: Tipo de cabo | D21: - | E21: XV
C22: Tipo de material condutor | D22: - | E22: Cobre
C23: Resistividade do material condutor a 20 ºC | D23: W.mm2/m | E23: 0.017241 | F23: Anexo VI
C24: Coeficiente de variação de resistividade a 20 ºC | D24: K-1 | E24: 0.00393 | F24: Anexo VI
C25: Temperatura máxima de funcionamento | D25: ºC | E25: 90 | F25: Quadro 52A
C26: Isolamento | D26: - | E26: XLPE | F26: Anexo IIB
C27: k - constante do isolamento cabo | D27: - | E27: 143 | F27: Secção 434
C28: l - Reatância linear do cabo | D28: mW/m | E28: 0.08
C29: Polaridade cabo | D29: - | E29: Monocondutor
C30: Modo instalação | D30: - | E30: Caminho cabos perf.
C31: Tipo de colocação | D31: - | E31: triângulo
C32: Secção condutor PEN | D32: mm2 | E32: Igual ao da fase
C33: Agrupamento de cabos | D33: - | E33: 3
B34: Dados bioclimáticos
C35: Temperatura ambiente | D35: ºC | E35: 40
C36: Temperatura do solo | D36: ºC | E36: -
C37: Resistividade térmica terreno | D37: K.m/W | E37: -
B39: IB | C39: Corrente de serviço | D39: A | E39: =E6*E7/100/E8/SQRT(3)/E10*1000 -> 144.33757
C40: Referência do modo de instalação | D40: - | E40: 13 | F40: Quadro 52H
C41: Método de referência do modo de instalação | D41: - | E41: F | F41: Quadro 52H
B43: Factores de correcção
C44: Função da temperatura ambiente | D44: - | E44: 0.91 | F44: Quadro 52-D1
...

Sheet airo4
A1: Disjuntor
B4: Dados Máquina
C5: Potência de serviço | D5: kW | E5: 212
C6: Factor de simultaneidade | D6: % | E6: 77
C7: Factor de potência | D7: - | E7: 0.98
B8: Dados Rede
C9: Tensão composta | D9: V | E9: 400
C10: Comprimento | D10: m | E10: 50
C11: Ucc, transformador a montante | D11: % | E11: 4.245
C12: Potência, transformador a montante | D12: kVA | E12: 1000
C13: Ik3.máx | D13: kA | E13: =E12/SQRT(3)/E9/E11*100 -> 34.001783
C14: b, tipo de rede (1-trifásico equilibrado; 2 - outros) | D14: - | E14: 1
C15: Cmax, fator de tensão máximo | D15: - | E15: 1.05
C16: Cmin, fator de tensão mínimo | E16: 0.95
C17: m, fator de carga em vazio | D17: - | E17: 1.05
C18: Regime de neutro | D18: - | E18: TN-C
B19: Dados cabo
C20: Tipo de cabo | D20: - | E20: XV
C21: Tipo de material condutor | D21: - | E21: Cobre
C22: Resistividade do material condutor a 20 ºC | D22: W.mm2/m | E22: 0.017241 | F22: Anexo VI
C23: Coeficiente de variação de resistividade a 20 ºC | D23: K-1 | E23: 0.00393 | F23: Anexo VI
C24: Temperatura máxima de funcionamento | D24: ºC | E24: 90 | F24: Quadro 52A
C25: Isolamento | D25: - | E25: XLPE | F25: Anexo IIB
C26: k - constante do isolamento cabo | D26: - | E26: 143 | F26: Secção 434
C27: l - Reatância linear do cabo | D27: mW/m | E27: 0.08
C28: Polaridade cabo | D28: - | E28: Monocondutor
C29: Modo instalação | D29: - | E29: Condutas enterradas
C30: Tipo de colocação | D30: - | E30: triângulo
C31: Secção condutor PEN | D31: mm2 | E31: Igual ao da fase
C32: Agrupamento de cabos | D32: - | E32: 3
B33: Dados bioclimáticos
C34: Temperatura ambiente | D34: ºC | E34: 45
C35: Temperatura do solo | D35: ºC | E35: 30
C36: Resistividade térmica terreno | D36: K.m/W | E36: 1.2
B38: IB | C38: Corrente de serviço | D38: A | E38: =E5*E6/100/E7/SQRT(3)/E9*1000 -> 240.42515
C39: Referência do modo de instalação | D39: - | E39: 61 | F39: Quadro 52H
C40: Método de referência do modo de instalação | D40: - | E40: D | F40: Quadro 52H
B42: Factores de correcção
C43: Função da temperatura do solo | D43: - | E43: 0.93 | F43: Quadro 52-D2
C44: Resistividade térmica do solo | D44: - | E44: 0.94 | F44: Quadro 52-E6
...

Sheet 09
C8: 15. | K8: S.norm
D9: I | E9: A | F9: ='07.2'!N42*1000 -> 51843.142 | K9: mm2
D10: k | E10: - | F10: 143 | K10: 1.5
D11: t | E11: s | F11: 0.5 | G11: Tempo máximo p/ proteção MT | K11: 2.5
D12: Spe.1 | E12: mm2 | F12: =F9*SQRT(F11)/F10 -> 256.35411 | G12: [543.1.1] | K12: 4
D13: Spe.1.nor | E13: mm2 | F13: 2x150 | K13: 6
K14: 10
D15: Sfase | E15: mm2 | F15: 4x150 | K15: 16
D16: Spe.min | E16: mm2 | F16: 2x150 | G16: Quadro 54F | K16: 25
K17: 35
K18: 50
D19: Spe.min.nor | E19: mm2 | F19: 2x150 | K19: 70
K20: 95
K21: 120
K22: 150
C23: 16. | K23: 185
D24: I | E24: A | F24: ='07.2'!N44*1000 -> 44559.365 | K24: 240
D25: k | E25: - | F25: 176 | K25: 300
D26: t | E26: s | F26: 0.005 | G26: Tempo p/ disjuntor C1
D27: Spe.1 | E27: mm2 | F27: =F24*SQRT(F26)/F25 -> 17.902403 | G27: [543.1.1]
D28: Spe.1.nor | E28: mm2 | F28: 25
D30: Sfase | E30: mm2 | F30: 16
D31: Spe.min | E31: mm2 | F31: 16 | G31: Quadro 54F
D32: Spe.min.nor | E32: mm2 | F32: 16
D34: Spe.min.nor | E34: mm2 | F34: =F32 -> 16

Sheet ELT
C3: IT - neutro distribuído
C5: m = 1 | D5: 1
C6: UL = 50 V
C7: U | D7: 230
C8: Cobre | D8: 0.0225
C9: Imag = 10.Ir | D9: 10
C12: Secção (S) | D12: Intensidade de corrente Estipulada (In)
C13: mm2 | D13: 16 | E13: 20 | F13: 25 | G13: 32 | H13: 40 | I13: 50 | J13: 63 | K13: 80 | L13: 100 | M13: 125 | N13: 160 | O13: 200 | P13: 250 | Q13: 320 | R13: 400 | S13: 500 | T13: 630
C14: 1.5 | D14: =0.8*$D$7*$C14/(2*$D$8*(1+$D$5)*D$13*$D$9) -> 19.166667 | E14: =0.8*$D$7*$C14/(2*$D$8*(1+$D$5)*E$13*$D$9) -> 15.333333 | F14: =0.8*$D$7*$C14/(2*$D$8*(1+$D$5)*F$13*$D$9) -> 12.266667 | G14: =0.8*$D$7*$C14/(2*$D$8*(1+$D$5)*G$13*$D$9) -> 9.5833333 | H14: =0.8*$D$7*$C14/(2*$D$8*(1+$D$5)*H$13*$D$9) -> 7.6666667 | I14: =0.8*$D$7*$C14/(2*$D$8*(1+$D$5)*I$13*$D$9) -> 6.1333333 | J14: =0.8*$D$7*$C14/(2*$D$8*(1+$D$5)*J$13*$D$9) -> 4.8677249 | K14: =0.8*$D$7*$C14/(2*$D$8*(1+$D$5)*K$13*$D$9) -> 3.8333333
C15: 2.5 | D15: =0.8*$D$7*$C15/(2*$D$8*(1+$D$5)*D$13*$D$9) -> 31.944444 | E15: =0.8*$D$7*$C15/(2*$D$8*(1+$D$5)*E$13*$D$9) -> 25.555556 | F15: =0.8*$D$7*$C15/(2*$D$8*(1+$D$5)*F$13*$D$9) -> 20.444444 | G15: =0.8*$D$7*$C15/(2*$D$8*(1+$D$5)*G$13*$D$9) -> 15.972222 | H15: =0.8*$D$7*$C15/(2*$D$8*(1+$D$5)*H$13*$D$9) -> 12.777778 | I15: =0.8*$D$7*$C15/(2*$D$8*(1+$D$5)*I$13*$D$9) -> 10.222222 | J15: =0.8*$D$7*$C15/(2*$D$8*(1+$D$5)*J$13*$D$9) -> 8.1128748 | K15: =0.8*$D$7*$C15/(2*$D$8*(1+$D$5)*K$13*$D$9) -> 6.3888889 | ... M15: =0.8*$D$7*$C15/(2*$D$8*(1+$D$5)*M$13*$D$9) -> 4.0888889
C16: 4 | D16: =0.8*$D$7*$C16/(2*$D$8*(1+$D$5)*D$13*$D$9) -> 51.111111 | E16: =0.8*$D$7*$C16/(2*$D$8*(1+$D$5)*E$13*$D$9) -> 40.888889 | F16: =0.8*$D$7*$C16/(2*$D$8*(1+$D$5)*F$13*$D$9) -> 32.711111 | G16: =0.8*$D$7*$C16/(2*$D$8*(1+$D$5)*G$13*$D$9) -> 25.555556 | H16: =0.8*$D$7*$C16/(2*$D$8*(1+$D$5)*H$13*$D$9) -> 20.444444 | I16: =0.8*$D$7*$C16/(2*$D$8*(1+$D$5)*I$13*$D$9) -> 16.355556 | J16: =0.8*$D$7*$C16/(2*$D$8*(1+$D$5)*J$13*$D$9) -> 12.9806 | K16: =0.8*$D$7*$C16/(2*$D$8*(1+$D$5)*K$13*$D$9) -> 10.222222 | ... O16: =0.8*$D$7*$C16/(2*$D$8*(1+$D$5)*O$13*$D$9) -> 4.0888889
C17: 6 | D17: =0.8*$D$7*$C17/(2*$D$8*(1+$D$5)*D$13*$D$9) -> 76.666667 | E17: =0.8*$D$7*$C17/(2*$D$8*(1+$D$5)*E$13*$D$9) -> 61.333333 | F17: =0.8*$D$7*$C17/(2*$D$8*(1+$D$5)*F$13*$D$9) -> 49.066667 | G17: =0.8*$D$7*$C17/(2*$D$8*(1+$D$5)*G$13*$D$9) -> 38.333333 | H17: =0.8*$D$7*$C17/(2*$D$8*(1+$D$5)*H$13*$D$9) -> 30.666667 | I17: =0.8*$D$7*$C17/(2*$D$8*(1+$D$5)*I$13*$D$9) -> 24.533333 | J17: =0.8*$D$7*$C17/(2*$D$8*(1+$D$5)*J$13*$D$9) -> 19.470899 | K17: =0.8*$D$7*$C17/(2*$D$8*(1+$D$5)*K$13*$D$9) -> 15.333333 | ... P17: =0.8*$D$7*$C17/(2*$D$8*(1+$D$5)*P$13*$D$9) -> 4.9066667
C18: 10 | D18: =0.8*$D$7*$C18/(2*$D$8*(1+$D$5)*D$13*$D$9) -> 127.77778 | E18: =0.8*$D$7*$C18/(2*$D$8*(1+$D$5)*E$13*$D$9) -> 102.22222 | F18: =0.8*$D$7*$C18/(2*$D$8*(1+$D$5)*F$13*$D$9) -> 81.777778 | G18: =0.8*$D$7*$C18/(2*$D$8*(1+$D$5)*G$13*$D$9) -> 63.888889 | H18: =0.8*$D$7*$C18/(2*$D$8*(1+$D$5)*H$13*$D$9) -> 51.111111 | I18: =0.8*$D$7*$C18/(2*$D$8*(1+$D$5)*I$13*$D$9) -> 40.888889 | J18: =0.8*$D$7*$C18/(2*$D$8*(1+$D$5)*J$13*$D$9) -> 32.451499 | K18: =0.8*$D$7*$C18/(2*$D$8*(1+$D$5)*K$13*$D$9) -> 25.555556 | ... R18: =0.8*$D$7*$C18/(2*$D$8*(1+$D$5)*R$13*$D$9) -> 5.1111111
C19: 16 | D19: =0.8*$D$7*$C19/(2*$D$8*(1+$D$5)*D$13*$D$9) -> 204.44444 | E19: =0.8*$D$7*$C19/(2*$D$8*(1+$D$5)*E$13*$D$9) -> 163.55556 | F19: =0.8*$D$7*$C19/(2*$D$8*(1+$D$5)*F$13*$D$9) -> 130.84444 | G19: =0.8*$D$7*$C19/(2*$D$8*(1+$D$5)*G$13*$D$9) -> 102.22222 | H19: =0.8*$D$7*$C19/(2*$D$8*(1+$D$5)*H$13*$D$9) -> 81.777778 | I19: =0.8*$D$7*$C19/(2*$D$8*(1+$D$5)*I$13*$D$9) -> 65.422222 | J19: =0.8*$D$7*$C19/(2*$D$8*(1+$D$5)*J$13*$D$9) -> 51.922399 | K19: =0.8*$D$7*$C19/(2*$D$8*(1+$D$5)*K$13*$D$9) -> 40.888889 | ... T19: =0.8*$D$7*$C19/(2*$D$8*(1+$D$5)*T$13*$D$9) -> 5.1922399
C20: 25 | D20: =0.8*$D$7*$C20/(2*$D$8*(1+$D$5)*D$13*$D$9) -> 319.44444 | E20: =0.8*$D$7*$C20/(2*$D$8*(1+$D$5)*E$13*$D$9) -> 255.55556 | F20: =0.8*$D$7*$C20/(2*$D$8*(1+$D$5)*F$13*$D$9) -> 204.44444 | G20: =0.8*$D$7*$C20/(2*$D$8*(1+$D$5)*G$13*$D$9) -> 159.72222 | H20: =0.8*$D$7*$C20/(2*$D$8*(1+$D$5)*H$13*$D$9) -> 127.77778 | I20: =0.8*$D$7*$C20/(2*$D$8*(1+$D$5)*I$13*$D$9) -> 102.22222 | J20: =0.8*$D$7*$C20/(2*$D$8*(1+$D$5)*J$13*$D$9) -> 81.128748 | K20: =0.8*$D$7*$C20/(2*$D$8*(1+$D$5)*K$13*$D$9) -> 63.888889 | ... T20: =0.8*$D$7*$C20/(2*$D$8*(1+$D$5)*T$13*$D$9) -> 8.1128748
C21: 35 | D21: =0.8*$D$7*$C21/(2*$D$8*(1+$D$5)*D$13*$D$9) -> 447.22222 | E21: =0.8*$D$7*$C21/(2*$D$8*(1+$D$5)*E$13*$D$9) -> 357.77778 | F21: =0.8*$D$7*$C21/(2*$D$8*(1+$D$5)*F$13*$D$9) -> 286.22222 | G21: =0.8*$D$7*$C21/(2*$D$8*(1+$D$5)*G$13*$D$9) -> 223.61111 | H21: =0.8*$D$7*$C21/(2*$D$8*(1+$D$5)*H$13*$D$9) -> 178.88889 | I21: =0.8*$D$7*$C21/(2*$D$8*(1+$D$5)*I$13*$D$9) -> 143.11111 | J21: =0.8*$D$7*$C21/(2*$D$8*(1+$D$5)*J$13*$D$9) -> 113.58025 | K21: =0.8*$D$7*$C21/(2*$D$8*(1+$D$5)*K$13*$D$9) -> 89.444444 | ... T21: =0.8*$D$7*$C21/(2*$D$8*(1+$D$5)*T$13*$D$9) -> 11.358025
C22: 50 | E22: =0.8*$D$7*$C22/(2*$D$8*(1+$D$5)*E$13*$D$9) -> 511.11111 | F22: =0.8*$D$7*$C22/(2*$D$8*(1+$D$5)*F$13*$D$9) -> 408.88889 | G22: =0.8*$D$7*$C22/(2*$D$8*(1+$D$5)*G$13*$D$9) -> 319.44444 | H22: =0.8*$D$7*$C22/(2*$D$8*(1+$D$5)*H$13*$D$9) -> 255.55556 | I22: =0.8*$D$7*$C22/(2*$D$8*(1+$D$5)*I$13*$D$9) -> 204.44444 | J22: =0.8*$D$7*$C22/(2*$D$8*(1+$D$5)*J$13*$D$9) -> 162.2575 | K22: =0.8*$D$7*$C22/(2*$D$8*(1+$D$5)*K$13*$D$9) -> 127.77778 | L22: =0.8*$D$7*$C22/(2*$D$8*(1+$D$5)*L$13*$D$9) -> 102.22222 | ... T22: =0.8*$D$7*$C22/(2*$D$8*(1+$D$5)*T$13*$D$9) -> 16.22575
C23: 70 | F23: =0.8*$D$7*$C23/(2*$D$8*(1+$D$5)*F$13*$D$9) -> 572.44444 | G23: =0.8*$D$7*$C23/(2*$D$8*(1+$D$5)*G$13*$D$9) -> 447.22222 | H23: =0.8*$D$7*$C23/(2*$D$8*(1+$D$5)*H$13*$D$9) -> 357.77778 | I23: =0.8*$D$7*$C23/(2*$D$8*(1+$D$5)*I$13*$D$9) -> 286.22222 | J23: =0.8*$D$7*$C23/(2*$D$8*(1+$D$5)*J$13*$D$9) -> 227.16049 | K23: =0.8*$D$7*$C23/(2*$D$8*(1+$D$5)*K$13*$D$9) -> 178.88889 | L23: =0.8*$D$7*$C23/(2*$D$8*(1+$D$5)*L$13*$D$9) -> 143.11111 | M23: =0.8*$D$7*$C23/(2*$D$8*(1+$D$5)*M$13*$D$9) -> 114.48889 | ... T23: =0.8*$D$7*$C23/(2*$D$8*(1+$D$5)*T$13*$D$9) -> 22.716049
C24: 95 | G24: =0.8*$D$7*$C24/(2*$D$8*(1+$D$5)*G$13*$D$9) -> 606.94444 | H24: =0.8*$D$7*$C24/(2*$D$8*(1+$D$5)*H$13*$D$9) -> 485.55556 | I24: =0.8*$D$7*$C24/(2*$D$8*(1+$D$5)*I$13*$D$9) -> 388.44444 | J24: =0.8*$D$7*$C24/(2*$D$8*(1+$D$5)*J$13*$D$9) -> 308.28924 | K24: =0.8*$D$7*$C24/(2*$D$8*(1+$D$5)*K$13*$D$9) -> 242.77778 | L24: =0.8*$D$7*$C24/(2*$D$8*(1+$D$5)*L$13*$D$9) -> 194.22222 | M24: =0.8*$D$7*$C24/(2*$D$8*(1+$D$5)*M$13*$D$9) -> 155.37778 | N24: =0.8*$D$7*$C24/(2*$D$8*(1+$D$5)*N$13*$D$9) -> 121.38889 | ... T24: =0.8*$D$7*$C24/(2*$D$8*(1+$D$5)*T$13*$D$9) -> 30.828924
C25: 120 | H25: =0.8*$D$7*$C25/(2*$D$8*(1+$D$5)*H$13*$D$9) -> 613.33333 | I25: =0.8*$D$7*$C25/(2*$D$8*(1+$D$5)*I$13*$D$9) -> 490.66667 | J25: =0.8*$D$7*$C25/(2*$D$8*(1+$D$5)*J$13*$D$9) -> 389.41799 | K25: =0.8*$D$7*$C25/(2*$D$8*(1+$D$5)*K$13*$D$9) -> 306.66667 | L25: =0.8*$D$7*$C25/(2*$D$8*(1+$D$5)*L$13*$D$9) -> 245.33333 | M25: =0.8*$D$7*$C25/(2*$D$8*(1+$D$5)*M$13*$D$9) -> 196.26667 | N25: =0.8*$D$7*$C25/(2*$D$8*(1+$D$5)*N$13*$D$9) -> 153.33333 | O25: =0.8*$D$7*$C25/(2*$D$8*(1+$D$5)*O$13*$D$9) -> 122.66667 | ... T25: =0.8*$D$7*$C25/(2*$D$8*(1+$D$5)*T$13*$D$9) -> 38.941799
C26: 150 | I26: =0.8*$D$7*$C26/(2*$D$8*(1+$D$5)*I$13*$D$9) -> 613.33333 | J26: =0.8*$D$7*$C26/(2*$D$8*(1+$D$5)*J$13*$D$9) -> 486.77249 | K26: =0.8*$D$7*$C26/(2*$D$8*(1+$D$5)*K$13*$D$9) -> 383.33333 | L26: =0.8*$D$7*$C26/(2*$D$8*(1+$D$5)*L$13*$D$9) -> 306.66667 | M26: =0.8*$D$7*$C26/(2*$D$8*(1+$D$5)*M$13*$D$9) -> 245.33333 | N26: =0.8*$D$7*$C26/(2*$D$8*(1+$D$5)*N$13*$D$9) -> 191.66667 | O26: =0.8*$D$7*$C26/(2*$D$8*(1+$D$5)*O$13*$D$9) -> 153.33333 | P26: =0.8*$D$7*$C26/(2*$D$8*(1+$D$5)*P$13*$D$9) -> 122.66667 | ... T26: =0.8*$D$7*$C26/(2*$D$8*(1+$D$5)*T$13*$D$9) -> 48.677249
C27: 185 | J27: =0.8*$D$7*$C27/(2*$D$8*(1+$D$5)*J$13*$D$9) -> 600.35273 | K27: =0.8*$D$7*$C27/(2*$D$8*(1+$D$5)*K$13*$D$9) -> 472.77778 | L27: =0.8*$D$7*$C27/(2*$D$8*(1+$D$5)*L$13*$D$9) -> 378.22222 | M27: =0.8*$D$7*$C27/(2*$D$8*(1+$D$5)*M$13*$D$9) -> 302.57778 | N27: =0.8*$D$7*$C27/(2*$D$8*(1+$D$5)*N$13*$D$9) -> 236.38889 | O27: =0.8*$D$7*$C27/(2*$D$8*(1+$D$5)*O$13*$D$9) -> 189.11111 | P27: =0.8*$D$7*$C27/(2*$D$8*(1+$D$5)*P$13*$D$9) -> 151.28889 | Q27: =0.8*$D$7*$C27/(2*$D$8*(1+$D$5)*Q$13*$D$9) -> 118.19444 | ... T27: =0.8*$D$7*$C27/(2*$D$8*(1+$D$5)*T$13*$D$9) -> 60.035273
C28: 240 | K28: =0.8*$D$7*$C28/(2*$D$8*(1+$D$5)*K$13*$D$9) -> 613.33333 | L28: =0.8*$D$7*$C28/(2*$D$8*(1+$D$5)*L$13*$D$9) -> 490.66667 | M28: =0.8*$D$7*$C28/(2*$D$8*(1+$D$5)*M$13*$D$9) -> 392.53333 | N28: =0.8*$D$7*$C28/(2*$D$8*(1+$D$5)*N$13*$D$9) -> 306.66667 | O28: =0.8*$D$7*$C28/(2*$D$8*(1+$D$5)*O$13*$D$9) -> 245.33333 | P28: =0.8*$D$7*$C28/(2*$D$8*(1+$D$5)*P$13*$D$9) -> 196.26667 | Q28: =0.8*$D$7*$C28/(2*$D$8*(1+$D$5)*Q$13*$D$9) -> 153.33333 | R28: =0.8*$D$7*$C28/(2*$D$8*(1+$D$5)*R$13*$D$9) -> 122.66667 | ... T28: =0.8*$D$7*$C28/(2*$D$8*(1+$D$5)*T$13*$D$9) -> 77.883598

Sheet gerador
C5: Saída | D5: S (kVA) | E5: cos phi | F5: Rendi(%) | G5: P (kW) | H5: Q (kVAr) | I5: S (kVA) | K5: Id/I | L5: cos phi arr
C6: 4 | D6: 100 | E6: 0.8 | G6: =D6*E6 -> 80 | H6: =G6*TAN(ACOS(E6)) -> 60
C7: 5 | E7: 0.85 | F7: 0.9 | G7: =45/F7 -> 50 | H7: =G7*TAN(ACOS(E7)) -> 30.987217 | K7: 2 | L7: 0.45
C8: 6 | E8: 0.85 | F8: 0.9 | G8: =7.5/F8 -> 8.3333333 | H8: =G8*TAN(ACOS(E8)) -> 5.1645362 | K8: 5 | L8: 0.45
C9: 7 e 8 | D9: 200 | E9: 0.95 | G9: =D9*E9 -> 190 | H9: =G9*TAN(ACOS(E9)) -> 62.44998
G11: =SUM(G6:G10) -> 328.33333 | H11: =SUM(H6:H10) -> 158.60173 | I11: =SQRT(G11^2+H11^2) -> 364.63309

Sheet pt_ex1
A1: Dimensionamento Elétrodos de Terra PT
C3: Exemplo 1
B4: DADOS
B5: Tensão linha | C5: Ul | D5: V | E5: 26400
H6: VALORES ADMISSÍVEIS
B7: Neutro impedante | H7: tmin | I7: tmax | J7: K | K7: n | L7: Vpa
B8: Resistência do neutro | C8: Rn | D8: W | E8: 12 | H8: 0.1 | I8: 0.9 | J8: 72 | K8: 1 | L8: -
B9: Reatância do neutro | C9: Xn | D9: W | E9: 22.4 | H9: 0.9000001 | I9: 3 | J9: 78.5 | K9: 0.18 | L9: -
H10: =3.0000001 -> 3.0000001 | I10: 5 | J10: - | K10: - | L10: 640
B11: Tempo disparo MT | C11: t | D11: s | E11: 1 | H11: 5 | J11: - | K11: - | L11: 500
B12: Resistividade do terreno | C12: r | D12: W.m | E12: 200
B13: Resistividade superficial terremo do PT | C13: rs | D13: W.m | E13: 3000
B14: Tensão isolamento BT | C14: Ubt | D14: V | E14: 10000
B17: RESOLUÇÃO
B18: Configuração | D18: - | E18: 70-40/5/42
B19: Configuração | C19: Kr | D19: - | E19: 0.076
B20: Configuração | C20: Kp | D20: - | E20: 0.0165
B21: Configuração | C21: Kc | D21: - | E21: 0.0362
B22: Valores admissíveis | C22: K | D22: - | E22: =VLOOKUP(E11,$H$8:$L$11,3,TRUE) -> 78.5
B23: Valores admissíveis | C23: n | D23: - | E23: =VLOOKUP(E11,$H$8:$L$11,4,TRUE) -> 0.18
B24: Resistência elétrodos de terra | C24: Rt | D24: W | E24: =E19*E12 -> 15.2
B25: Corrente de defeito | C25: Id | D25: A | E25: =E5/(SQRT(3)*SQRT((E8+E24)^2+E9^2)) -> 432.56607
B26: Tensão de defeito | C26: Ud | D26: V | E26: =E24*E25 -> 6575.0042
B27: Tensão de passo | C27: Up | D27: V | E27: =E20*E12*E25 -> 1427.468
B28: Tensão de passo admissível | C28: Upa | D28: V | E28: =IF($E$11<$H$10,10*$E$22/($E$11^$E$23)*(1+6*$E$12/1000),IF($E$11<$H$11,$L$10*(1+6*$E$12/1000),$L$11*(1+6*$E$12/1000))) -> 1727
B29: Tensão de acesso e contacto | C29: Up(acc) | D29: V | E29: =E21*E12*E25 -> 3131.7783
B30: Tensão de acesso e contacto admissível | C30: Upa(acc) | D30: V | E30: =IF($E$11<$H$10,10*$E$22/($E$11^$E$23)*(1+(3*$E$12+3*$E$13)/1000),IF($E$11<$H$11,$L$10*(1+(3*$E$12+3*$E$13)/1000),$L$11*(1+(3*$E$12+3*$E$13)/1000))) -> 8321
B33: CONDIÇÕES
B34: Rt £ 20 W | D34: - | E34: =IF(E24<=20,"OK","!!!!!!") -> OK
B35: Up < Upa | D35: - | E35: =IF(E27<E28,"OK","!!!!!!") -> OK
B36: Up(acc) < Upa(acc) | D36: - | E36: =IF(E29<E30,"OK","!!!!!!") -> OK
B37: Ud < Ubt | D37: - | E37: =IF(E26<E14,"OK","!!!!!!") -> OK

Sheet pt_ex2
A1: Dimensionamento Elétrodos de Terra PT
C3: Exemplo 2
B4: DADOS
B5: Tensão linha | C5: Ul | D5: V | E5: 20000
H6: VALORES ADMISSÍVEIS
B7: Neutro impedante | H7: tmin | I7: tmax | J7: K | K7: n | L7: Vpa
B8: Resistência do neutro | C8: Rn | D8: W | E8: 0 | H8: 0.1 | I8: 0.9 | J8: 72 | K8: 1 | L8: -
B9: Reatância do neutro | C9: Xn | D9: W | E9: =E5/(SQRT(3)*E10) -> 23.094011 | H9: 0.9000001 | I9: 3 | J9: 78.5 | K9: 0.18 | L9: -
B10: Corrente de defeito máxima (subestação) | C10: Id.max | D10: A | E10: 500 | H10: =3.0000001 -> 3.0000001 | I10: 5 | J10: - | K10: - | L10: 640
H11: 5 | J11: - | K11: - | L11: 500
B12: Tempo disparo MT | C12: t | D12: s | E12: 1
B13: Resistividade do terreno | C13: r | D13: W.m | E13: 300
B14: Resistividade superficial terremo do PT | C14: rs | D14: W.m | E14: 3000
B15: Tensão isolamento BT | C15: Ubt | D15: V | E15: 10000
B18: RESOLUÇÃO
B19: Configuração | D19: - | E19: 8/44
B20: Configuração | C20: Kr | D20: - | E20: 0.0558
B21: Configuração | C21: Kp | D21: - | E21: 0.00633
B22: Configuração | C22: Kc | D22: - | E22: -
B23: Valores admissíveis | C23: K | D23: - | E23: =VLOOKUP(E12,$H$8:$L$11,3,TRUE) -> 78.5
B24: Valores admissíveis | C24: n | D24: - | E24: =VLOOKUP(E12,$H$8:$L$11,4,TRUE) -> 0.18
B25: Resistência elétrodos de terra | C25: Rt | D25: W | E25: =E20*E13 -> 16.74
B26: Corrente de defeito | C26: Id | D26: A | E26: =E5/(SQRT(3)*SQRT((E8+E25)^2+E9^2)) -> 404.83153
B27: Tensão de defeito | C27: Ud | D27: V | E27: =E25*E26 -> 6776.8797
B28: Tensão de passo | C28: Up | D28: V | E28: =E21*E13*E26 -> 768.77507
B29: Tensão de passo admissível | C29: Upa | D29: V | E29: =IF($E$12<$H$10,10*$E$23/($E$12^$E$24)*(1+6*$E$13/1000),IF($E$12<$H$11,$L$10*(1+6*$E$13/1000),$L$11*(1+6*$E$13/1000))) -> 2198
B30: Tensão de acesso e contacto | C30: Up(acc) | D30: V | E30: =E27 -> 6776.8797
B31: Tensão de acesso e contacto admissível | C31: Upa(acc) | D31: V | E31: =IF($E$12<$H$10,10*$E$23/($E$12^$E$24)*(1+(3*$E$13+3*$E$14)/1000),IF($E$12<$H$11,$L$10*(1+(3*$E$13+3*$E$14)/1000),$L$11*(1+(3*$E$13+3*$E$14)/1000))) -> 8556.5
B33: CONDIÇÕES
B34: Rt £ 20 W | D34: - | E34: =IF(E25<=20,"OK","!!!!!!") -> OK
B35: Up < Upa | D35: - | E35: =IF(E28<E29,"OK","!!!!!!") -> OK
B36: Up(acc) < Upa(acc) | D36: - | E36: =IF(E30<E31,"OK","!!!!!!") -> OK
B37: Ud < Ubt | D37: - | E37: =IF(E27<E15,"OK","!!!!!!") -> OK

Sheet pt_ex3
A1: Dimensionamento Elétrodos de Terra PT
C3: Exemplo 3
B4: DADOS
B5: Tensão linha | C5: Ul | D5: V | E5: 20000
H6: VALORES ADMISSÍVEIS
B7: Neutro impedante | H7: tmin | I7: tmax | J7: K | K7: n | L7: Vpa
B8: Resistência do neutro | C8: Rn | D8: W | E8: 11.5 | H8: 0.1 | I8: 0.9 | J8: 72 | K8: 1 | L8: -
B9: Reatância do neutro | C9: Xn | D9: W | E9: 20 | H9: 0.9000001 | I9: 3 | J9: 78.5 | K9: 0.18 | L9: -
H10: =3.0000001 -> 3.0000001 | I10: 5 | J10: - | K10: - | L10: 640
B11: Tempo disparo MT | C11: t | D11: s | E11: 0.9 | H11: 5 | J11: - | K11: - | L11: 500
B12: Resistividade do terreno | C12: r | D12: W.m | E12: 400
B13: Resistividade superficial terremo do PT | C13: rs | D13: W.m | E13: 3000
B14: Tensão isolamento BT | C14: Ubt | D14: V | E14: 10000
B17: RESOLUÇÃO
B18: Configuração | D18: - | E18: 40-40/8/86
B19: Configuração | C19: Kr | D19: - | E19: 0.044
B20: Configuração | C20: Kp | D20: - | E20: 0.0062
B21: Configuração | C21: Kc | D21: - | E21: 0.0131
B22: Valores admissíveis | C22: K | D22: - | E22: =VLOOKUP(E11,$H$8:$L$11,3,TRUE) -> 72
B23: Valores admissíveis | C23: n | D23: - | E23: =VLOOKUP(E11,$H$8:$L$11,4,TRUE) -> 1
B24: Resistência elétrodos de terra | C24: Rt | D24: W | E24: =E19*E12 -> 17.6
B25: Corrente de defeito | C25: Id | D25: A | E25: =E5/(SQRT(3)*SQRT((E8+E24)^2+E9^2)) -> 327.01617
B26: Tensão de defeito | C26: Ud | D26: V | E26: =E24*E25 -> 5755.4846
B27: Tensão de passo | C27: Up | D27: V | E27: =E20*E12*E25 -> 811.00011
B28: Tensão de passo admissível | C28: Upa | D28: V | E28: =IF($E$11<$H$10,10*$E$22/($E$11^$E$23)*(1+6*$E$12/1000),IF($E$11<$H$11,$L$10*(1+6*$E$12/1000),$L$11*(1+6*$E$12/1000))) -> 2720
B29: Tensão de acesso e contacto | C29: Up(acc) | D29: V | E29: =E21*E12*E25 -> 1713.5647
B30: Tensão de acesso e contacto admissível | C30: Upa(acc) | D30: V | E30: =IF($E$11<$H$10,10*$E$22/($E$11^$E$23)*(1+(3*$E$12+3*$E$13)/1000),IF($E$11<$H$11,$L$10*(1+(3*$E$12+3*$E$13)/1000),$L$11*(1+(3*$E$12+3*$E$13)/1000))) -> 8960
B32: CONDIÇÕES
B33: Rt £ 20 W | D33: - | E33: =IF(E24<=20,"OK","!!!!!!") -> OK
B34: Up < Upa | D34: - | E34: =IF(E27<E28,"OK","!!!!!!") -> OK
B35: Up(acc) < Upa(acc) | D35: - | E35: =IF(E29<E30,"OK","!!!!!!") -> OK
B36: Ud < Ubt | D36: - | E36: =IF(E26<E14,"OK","!!!!!!") -> OK

Sheet terras
A1: Dimensionamento de elétrodos de terra
C3: 1 - Resistência de terra de proteção das massas do PT - Rp | J3: Exercício 10.10
C4: 2 - Resistência de terra de serviço - Rb
C5: 3 - Resistência de terra de proteção das massas de utilização - Ra | J5: Varetas de cobre | K5: var | L5: 4
C6: 4 - Resistência de terra do para-raios - Rpr | J6: Comprimentos vareta | K6: m | L6: 8
J7: Chapas | K7: cha | L7: 10
D8: Resistividade | E8: Comprimento | F8: Quantidade | G8: Resistência | J8: Altura chapa | K8: m | L8: 0.5
D9: r (Ω.m) | E9: L (m) | F9: un. | G9: W | J9: Largura chapa | K9: m | L9: 1
J10: Perímetro chapa | K10: m | L10: =(L8+L9)*2 -> 3
B11: 1 - Resistência de terra de proteção das massas do PT - Rp | G11: =G12 -> 10.65 | J11: Comprimento condutores | K11: m | L11: 50
C12: Simulação visualpuc - descrição dos tipos de elétrodos | D12: … | E12: … | F12: … | G12: 10.65 | J12: Resistividade do terreno | K12: W.m | L12: 1000
B15: 2 - Resistência de terra de serviço - Rb | G15: =G16 -> 18 | J15: Resistência varetas | K15: W | L15: =L12/(L5*L6) -> 31.25
C16: Simulação visualpuc - descrição dos tipos de elétrodos | D16: … | E16: … | F16: … | G16: 18 | J16: Resistência chapas | K16: W | L16: =0.8*L12/(L7*L10) -> 26.666667
J17: Resistência condutores | K17: W | L17: =2*L12/L11 -> 40
J18: Resistência total | K18: W | L18: =1/(1/L15+1/L16+1/L17) -> 10.582011
B19: 3 - Resistência de terra de proteção das massas de utilização - Ra | G19: =1/(1/G20+1/G21+1/G22+1/G23) -> 2.7272727
C20: Varetas | D20: 150 | E20: 2 | F20: 8 | G20: =D20/E20/F20 -> 9.375
C21: Estruturas de betão armado (anéis) | D21: 500 | E21: 0.8 | F21: 500 | G21: =10*2*D21/E21/F21 -> 25
C22: Estruturas de betão armado (linhas) | D22: 500 | E22: 3 | F22: =4*100 -> 400 | G22: =10*2*D22/E22/F22 -> 8.3333333
C23: Fita de aço galvanizado 30x3,5 (perímetro) | D23: 500 | E23: 100 | F23: 1 | G23: =2*D23/E23/F23 -> 10
B26: 4 - Resistência de terra do para-raios - Rpr | G26: =1/(1/G27+1/G28+1/G29) -> 6.5217391
C27: Pé-de-galo - Condutor em cobre nu 25 mm2 | D27: 150 | E27: 4 | F27: 4 | G27: =2*D27/E27/F27 -> 18.75
C28: Pé-de-galo - Vareta em aço cobreado 250 mm | D28: 150 | E28: 4 | F28: 3 | G28: =D28/E28/F28 -> 12.5
C29: Pé-de-galo - Elétrodo de grafite | D29: 50 | E29: 1 | F29: 1 | G29: =D29/E29/F29 -> 50
C33: Referir na memória descritiva: tipo de elétrodos, acessórios, ligadores especiais, soldaduras aluminotérmicas, quantidades, etc.
C34: Todos os valores: deverão ser revistos
C35: Mencionar que a terra do para-raios deverá ser interligada com a terra de proteção das massas do para-raios , ficando uma resistência de
C36: =G19*G26/(G19+G26) -> 1.9230769

Sheet tubosPcabos
A1: TUBOS
C3: VD | F3: ERM ou ERFE ("gris") | I3: PEAD ou PEBD
B4: Diâmetro nominal (mm) | C4: Diâmetro interior (mm) | D4: Secção interior (mm2) | E4: Secção utilizável (mm2) | F4: Diâmetro interior (mm) | G4: Secção interior (mm2) | H4: Secção utilizável (mm2) | I4: Diâmetro interior (mm) | J4: Secção interior (mm2) | K4: Secção utilizável (mm2)
B5: 16 | C5: 13 | D5: =PI()*C5^2/4 -> 132.73229 | E5: =D5/3 -> 44.244097 | F5: 12 | G5: =PI()*F5^2/4 -> 113.09734 | H5: =G5/3 -> 37.699112
B6: 20 | C6: 17.4 | D6: =PI()*C6^2/4 -> 237.78715 | E6: =D6/3 -> 79.262383 | F6: 16.2 | G6: =PI()*F6^2/4 -> 206.11989 | H6: =G6/3 -> 68.706631
B7: 25 | C7: 21.6 | D7: =PI()*C7^2/4 -> 366.43537 | E7: =D7/3 -> 122.14512 | F7: 20.2 | G7: =PI()*F7^2/4 -> 320.47387 | H7: =G7/3 -> 106.82462
B8: 32 | C8: 28.4 | D8: =PI()*C8^2/4 -> 633.47074 | E8: =D8/3 -> 211.15691 | F8: 25.4 | G8: =PI()*F8^2/4 -> 506.70748 | H8: =G8/3 -> 168.90249
B9: 40 | C9: 35 | D9: =PI()*C9^2/4 -> 962.11275 | E9: =D9/3 -> 320.70425 | F9: 32.5 | G9: =PI()*F9^2/4 -> 829.57681 | H9: =G9/3 -> 276.5256 | I9: 30 | J9: =PI()*I9^2/4 -> 706.85835 | K9: =J9/3 -> 235.61945
B10: 50 | C10: 44 | D10: =PI()*C10^2/4 -> 1520.5308 | E10: =D10/3 -> 506.84361 | I10: 37 | J10: =PI()*I10^2/4 -> 1075.2101 | K10: =J10/3 -> 358.40336
B11: 63 | C11: 56.4 | D11: =PI()*C11^2/4 -> 2498.3201 | E11: =D11/3 -> 832.77338 | I11: 47 | J11: =PI()*I11^2/4 -> 1734.9445 | K11: =J11/3 -> 578.31485
B12: 75 | C12: 68 | D12: =PI()*C12^2/4 -> 3631.6811 | E12: =D12/3 -> 1210.5604 | I12: 56 | J12: =PI()*I12^2/4 -> 2463.0086 | K12: =J12/3 -> 821.00288
B13: 90 | C13: 83 | D13: =PI()*C13^2/4 -> 5410.6079 | E13: =D13/3 -> 1803.536 | I13: 67 | J13: =PI()*I13^2/4 -> 3525.6524 | K13: =J13/3 -> 1175.2175
B14: 110 | C14: 104 | D14: =PI()*C14^2/4 -> 8494.8665 | E14: =D14/3 -> 2831.6222 | I14: 82 | J14: =PI()*I14^2/4 -> 5281.0173 | K14: =J14/3 -> 1760.3391
B15: 125 | I15: 94 | J15: =PI()*I15^2/4 -> 6939.7782 | K15: =J15/3 -> 2313.2594
B16: 160 | I16: 120 | J16: =PI()*I16^2/4 -> 11309.734 | K16: =J16/3 -> 3769.9112
B17: 200 | I17: 150 | J17: =PI()*I17^2/4 -> 17671.459 | K17: =J17/3 -> 5890.4862
B19: Nota 1: A secção utilizável equivale a 1/3 da seção interior real.
B20: Nota 2: Tubos ERM ou ERFE estão limitados a 40 mm.
B22: Exemplos | C22: Diâmetro exterior (mm) | D22: Secção exterior (mm2) | E22: Diâmetro nominal tubo VD (mm) | F22: Diâmetro nominal tubo ERM ou ERFE (mm) | G22: Diâmetro nominal tubo PEAD ou PEBD (mm)
B23: Secção dos condutores
B24: XZ1 (frt,zh) 3G1,5 | C24: 10 | D24: =PI()*C24^2/4 -> 78.539816 | E24: =IF($D24<$E$5,$B$5,IF($D24<$E$6,$B$6,IF($D24<$E$7,$B$7,IF($D24<$E$8,$B$8,IF($D24<$E$9,$B$9,IF($D24<$E$10,$B$10,IF($D24<$E$11,$B$11,IF($D24<$E$12,$B$12,IF($D24<$E$13,$B$13,IF($D24<$E$14,$B$14,"---")))))))))) -> 20 | F24: =IF(D24<$H$5,$B$5,IF(D24<$H$6,$B$6,IF(D24<$H$7,$B$7,IF(D24<$H$8,$B$8,IF(D24<$H$9,$B$9,"---"))))) -> 25 | G24: =IF($D24<$K$5,$B$5,IF($D24<$K$6,$B$6,IF($D24<$K$7,$B$7,IF($D24<$K$8,$B$8,IF($D24<$K$9,$B$9,IF($D24<$K$10,$B$10,IF($D24<$K$11,$B$11,IF($D24<$K$12,$B$12,IF($D24<$K$13,$B$13,IF($D24<$K$14,$B$14,IF($D24<$K$15,$B$15,IF($D24<$K$16,$B$16,IF($D24<$K$17,$B$17,"---"))))))))))))) -> 40
B25: XZ1 (frt,zh) 3G2,5 | C25: 10.5 | D25: =PI()*C25^2/4 -> 86.590148 | E25: =IF(D25<$E$5,$B$5,IF(D25<$E$6,$B$6,IF(D25<$E$7,$B$7,IF(D25<$E$8,$B$8,IF(D25<$E$9,$B$9,IF(D25<$E$10,$B$10,IF(D25<$E$11,$B$11,IF(D25<$E$12,$B$12,IF(D25<$E$13,$B$13,IF(D25<$E$14,$B$14,"---")))))))))) -> 25 | F25: =IF(D25<$H$5,$B$5,IF(D25<$H$6,$B$6,IF(D25<$H$7,$B$7,IF(D25<$H$8,$B$8,IF(D25<$H$9,$B$9,"---"))))) -> 25 | G25: =IF($D25<$K$5,$B$5,IF($D25<$K$6,$B$6,IF($D25<$K$7,$B$7,IF($D25<$K$8,$B$8,IF($D25<$K$9,$B$9,IF($D25<$K$10,$B$10,IF($D25<$K$11,$B$11,IF($D25<$K$12,$B$12,IF($D25<$K$13,$B$13,IF($D25<$K$14,$B$14,IF($D25<$K$15,$B$15,IF($D25<$K$16,$B$16,IF($D25<$K$17,$B$17,"---"))))))))))))) -> 40
B26: XZ1 (frt,zh) 3G4 | C26: 11.5 | D26: =PI()*C26^2/4 -> 103.86891 | E26: =IF(D26<$E$5,$B$5,IF(D26<$E$6,$B$6,IF(D26<$E$7,$B$7,IF(D26<$E$8,$B$8,IF(D26<$E$9,$B$9,IF(D26<$E$10,$B$10,IF(D26<$E$11,$B$11,IF(D26<$E$12,$B$12,IF(D26<$E$13,$B$13,IF(D26<$E$14,$B$14,"---")))))))))) -> 25 | F26: =IF(D26<$H$5,$B$5,IF(D26<$H$6,$B$6,IF(D26<$H$7,$B$7,IF(D26<$H$8,$B$8,IF(D26<$H$9,$B$9,"---"))))) -> 25 | G26: =IF($D26<$K$5,$B$5,IF($D26<$K$6,$B$6,IF($D26<$K$7,$B$7,IF($D26<$K$8,$B$8,IF($D26<$K$9,$B$9,IF($D26<$K$10,$B$10,IF($D26<$K$11,$B$11,IF($D26<$K$12,$B$12,IF($D26<$K$13,$B$13,IF($D26<$K$14,$B$14,IF($D26<$K$15,$B$15,IF($D26<$K$16,$B$16,IF($D26<$K$17,$B$17,"---"))))))))))))) -> 40
