Workbook

Sheet CENTRO DE CARGAS
C1: CENTRO DE CARGAS - SIMULAÇÃO
E3: AMP | F3: m | G3: m
D4: Carga | E4: INTENSIDADE | F4: x | G4: y | I4: i | J4: j
D5: QEG | E5: =bal_pot_exemplo!L20 -> 1068.178 | F5: 10 | G5: 30 | I5: m.A^2 | J5: m.A^2
D6: QP1 | E6: =bal_pot_exemplo!L37 -> 154.06 | F6: -20 | G6: 30 | I6: =F5*E5^2+F6*E6^2+F7*E7^2+F8*E8^2+F9*E9^2+F10*E10^2+F11*E11 -> 29768467 | J6: =G5*E5^2+G6*E6^2+G7*E7^2+G8*E8^2+G9*E9^2+G10*E10^2+G11*E11 -> 21936512
D7: QP2 | E7: =bal_pot_exemplo!L54 -> 66.56 | F7: -4 | G7: 20
D8: QP3 | E8: =bal_pot_exemplo!L73 -> 430.62 | F8: 50 | G8: -10
D9: QP4 | E9: =bal_pot_exemplo!L92 -> 430.62 | F9: 70 | G9: -50
D10: QP5 | E10: =bal_pot_exemplo!L111 -> 310.62 | F10: -35 | G10: -20
D11: QP6 | E11: =bal_pot_exemplo!L130 -> 550.62 | F11: -44 | G11: -70
I12: i | J12: j
I13: m | J13: m
D14: Imq^2 | E14: A^2 | F14: =E5^2+E6^2+E7^2+E8^2+E9^2+E10^2+E11^2 -> 1939703.3 | I14: =I6/F14 -> 15.346918 | J14: =J6/F14 -> 11.30921
D15: Imq | E15: A | F15: =SQRT(F14) -> 1392.7323

Sheet bal_pot_exemplo
A1: Balanço de Potência
B2: QGE | P2: Exemplo (diagrama de QE)
B3: Equipamento | C3: Nº Equi. | D3: Pun (kW) | E3: cos j | F3: Ku | G3: Ks | H3: Ke | I3: P (kW) | J3: Q (kvar) | K3: S (kVA)
B4: Iluminação | C4: 100 | D4: 0.25 | E4: 0.8 | F4: 1 | G4: 1 | H4: 1 | I4: =C4*D4*F4*G4*H4 -> 25 | J4: =I4*TAN(ACOS(E4)) -> 18.75 | K4: =SQRT(I4^2+J4^2) -> 31.25 | Q4: QGE | R4: =L20 -> 1068.178
B5: Tomadas monofásicas | C5: 6 | D5: =230*16/1000 -> 3.68 | E5: 1 | F5: 1 | G5: 0.3 | H5: 1 | I5: =C5*D5*F5*G5*H5 -> 6.624 | J5: =I5*TAN(ACOS(E5)) -> 0 | K5: =SQRT(I5^2+J5^2) -> 6.624
B6: Tomadas trifásicas | C6: 2 | D6: =3*230*16/1000 -> 11.04 | E6: 0.85 | F6: 1 | G6: 0.3 | H6: 1 | I6: =C6*D6*F6*G6*H6 -> 6.624 | J6: =I6*TAN(ACOS(E6)) -> 4.1051865 | K6: =SQRT(I6^2+J6^2) -> 7.7929412
B7: Máquina tipo 1 | C7: 5 | D7: 10 | E7: 0.85 | F7: 0.6 | G7: 1 | H7: 1 | I7: =C7*D7*F7*G7*H7 -> 30 | J7: =I7*TAN(ACOS(E7)) -> 18.59233 | K7: =SQRT(I7^2+J7^2) -> 35.294118
B8: Máquina tipo 2 | C8: 4 | D8: 12 | E8: 0.82 | F8: 0.5 | G8: 1 | H8: 2 | I8: =C8*D8*F8*G8*H8 -> 48 | J8: =I8*TAN(ACOS(E8)) -> 33.504206 | K8: =SQRT(I8^2+J8^2) -> 58.536585 | X8: QP5 | AA8: QP6
B9: Máquina tipo 3 | C9: 4 | D9: 20 | E9: 0.84 | F9: 0.7 | G9: 1 | H9: 1 | I9: =C9*D9*F9*G9*H9 -> 56 | J9: =I9*TAN(ACOS(E9)) -> 36.172427 | K9: =SQRT(I9^2+J9^2) -> 66.666667 | V9: =L111 -> 310.62 | Y9: =L130 -> 550.62
B10: QP1 | C10: 1 | D10: =I37 -> 88.248 | E10: =I37/K37 -> 0.8540844 | F10: 1 | G10: 0.9 | H10: 1 | I10: 100 | J10: =I10*TAN(ACOS(E10)) -> 60.899654 | K10: =SQRT(I10^2+J10^2) -> 117.08445
X12: QP3 | AA12: QP4
V13: =L73 -> 430.62 | Y13: =L92 -> 430.62
P16: QP1 | V16: QP2
Q17: =L37 -> 154.06 | T17: =L73 -> 430.62
B19: QP2 | C19: 1 | D19: =I73 -> 172.248 | E19: =I73/K73 -> 0.84030463 | F19: 1 | G19: 0.9 | H19: 1 | I19: =C19*D19*F19*G19*H19 -> 155.0232 | J19: =I19*TAN(ACOS(E19)) -> 100.01173 | K19: =SQRT(I19^2+J19^2) -> 184.48452
B20: Total | I20: =SUM(I4:I19) -> 427.2712 | J20: =SUM(J4:J19) -> 272.03554 | K20: =SQRT(I20^2+J20^2) -> 506.52148 | L20: =I20/400*1000 -> 1068.178
B22: QP1
B23: Equipamento | C23: Nº Equi. | D23: Pun (kW) | E23: cos j | F23: Ku | G23: Ks | H23: Ke | I23: P (kW) | J23: Q (kvar) | K23: S (kVA)
B24: Iluminação | C24: 50 | D24: 0.1 | E24: 0.8 | F24: 1 | G24: 1 | H24: 1 | I24: =C24*D24*F24*G24*H24 -> 5 | J24: =I24*TAN(ACOS(E24)) -> 3.75 | K24: =SQRT(I24^2+J24^2) -> 6.25
B25: Tomadas monofásicas | C25: 3 | D25: =230*16/1000 -> 3.68 | E25: 1 | F25: 1 | G25: 0.3 | H25: 1 | I25: =C25*D25*F25*G25*H25 -> 3.312 | J25: =I25*TAN(ACOS(E25)) -> 0 | K25: =SQRT(I25^2+J25^2) -> 3.312
B26: Tomadas trifásicas | C26: 1 | D26: =3*230*16/1000 -> 11.04 | E26: 0.85 | F26: 1 | G26: 0.3 | H26: 1 | I26: =C26*D26*F26*G26*H26 -> 3.312 | J26: =I26*TAN(ACOS(E26)) -> 2.0525932 | K26: =SQRT(I26^2+J26^2) -> 3.8964706
B27: Máquina tipo 1 | C27: 4 | D27: 10 | E27: 0.85 | F27: 0.6 | G27: 1 | H27: 1 | I27: =C27*D27*F27*G27*H27 -> 24 | J27: =I27*TAN(ACOS(E27)) -> 14.873864 | K27: =SQRT(I27^2+J27^2) -> 28.235294
B28: Máquina tipo 2 | C28: 1 | D28: 12 | E28: 0.82 | F28: 0.5 | G28: 1 | H28: 2 | I28: =C28*D28*F28*G28*H28 -> 12 | J28: =I28*TAN(ACOS(E28)) -> 8.3760515 | K28: =SQRT(I28^2+J28^2) -> 14.634146
B29: Máquina tipo 3 | C29: 1 | D29: 20 | E29: 0.84 | F29: 0.7 | G29: 1 | H29: 1 | I29: =C29*D29*F29*G29*H29 -> 14 | J29: =I29*TAN(ACOS(E29)) -> 9.0431066 | K29: =SQRT(I29^2+J29^2) -> 16.666667
B36: QP1.1 | C36: 1 | D36: =I54 -> 26.624 | E36: =I54/K54 -> 0.8621332 | F36: 1 | G36: 1 | H36: 1 | I36: =C36*D36*F36*G36*H36 -> 26.624 | J36: =I36*TAN(ACOS(E36)) -> 15.647111 | K36: =SQRT(I36^2+J36^2) -> 30.881539
B37: Parcial | I37: =SUM(I24:I36) -> 88.248 | J37: =SUM(J24:J36) -> 53.742726 | K37: =SQRT(I37^2+J37^2) -> 103.32468 | L37: =I37/400*1000-I36/400*1000 -> 154.06
B40: QP2
B41: Equipamento | C41: Nº Equi. | D41: Pun (kW) | E41: cos j | F41: Ku | G41: Ks | H41: Ke | I41: P (kW) | J41: Q (kvar) | K41: S (kVA)
B42: Iluminação | C42: 20 | D42: 0.1 | E42: 0.8 | F42: 1 | G42: 1 | H42: 1 | I42: =C42*D42*F42*G42*H42 -> 2 | J42: =I42*TAN(ACOS(E42)) -> 1.5 | K42: =SQRT(I42^2+J42^2) -> 2.5
B43: Tomadas monofásicas | C43: 3 | D43: =230*16/1000 -> 3.68 | E43: 1 | F43: 1 | G43: 0.3 | H43: 1 | I43: =C43*D43*F43*G43*H43 -> 3.312 | J43: =I43*TAN(ACOS(E43)) -> 0 | K43: =SQRT(I43^2+J43^2) -> 3.312
B44: Tomadas trifásicas | C44: 1 | D44: =3*230*16/1000 -> 11.04 | E44: 0.85 | F44: 1 | G44: 0.3 | H44: 1 | I44: =C44*D44*F44*G44*H44 -> 3.312 | J44: =I44*TAN(ACOS(E44)) -> 2.0525932 | K44: =SQRT(I44^2+J44^2) -> 3.8964706
B45: Máquina tipo 1 | C45: 1 | D45: 10 | E45: 0.85 | F45: 0.6 | G45: 1 | H45: 1 | I45: =C45*D45*F45*G45*H45 -> 6 | J45: =I45*TAN(ACOS(E45)) -> 3.718466 | K45: =SQRT(I45^2+J45^2) -> 7.0588235
B53: Máquina tipo 2 | C53: 1 | D53: 12 | E53: 0.82 | F53: 0.5 | G53: 1 | H53: 2 | I53: =C53*D53*F53*G53*H53 -> 12 | J53: =I53*TAN(ACOS(E53)) -> 8.3760515 | K53: =SQRT(I53^2+J53^2) -> 14.634146
B54: Parcial | I54: =SUM(I42:I53) -> 26.624 | J54: =SUM(J42:J53) -> 15.647111 | K54: =SQRT(I54^2+J54^2) -> 30.881539 | L54: =I54/400*1000 -> 66.56
B57: QP3
B58: Equipamento | C58: Nº Equi. | D58: Pun (kW) | E58: cos j | F58: Ku | G58: Ks | H58: Ke | I58: P (kW) | J58: Q (kvar) | K58: S (kVA)
B59: Iluminação | C59: 100 | D59: 0.25 | E59: 0.8 | F59: 1 | G59: 1 | H59: 1 | I59: =C59*D59*F59*G59*H59 -> 25 | J59: =I59*TAN(ACOS(E59)) -> 18.75 | K59: =SQRT(I59^2+J59^2) -> 31.25
B60: Tomadas monofásicas | C60: 6 | D60: =230*16/1000 -> 3.68 | E60: 1 | F60: 1 | G60: 0.3 | H60: 1 | I60: =C60*D60*F60*G60*H60 -> 6.624 | J60: =I60*TAN(ACOS(E60)) -> 0 | K60: =SQRT(I60^2+J60^2) -> 6.624
B61: Tomadas trifásicas | C61: 2 | D61: =3*230*16/1000 -> 11.04 | E61: 0.85 | F61: 1 | G61: 0.3 | H61: 1 | I61: =C61*D61*F61*G61*H61 -> 6.624 | J61: =I61*TAN(ACOS(E61)) -> 4.1051865 | K61: =SQRT(I61^2+J61^2) -> 7.7929412
B62: Máquina tipo 1 | C62: 5 | D62: 10 | E62: 0.85 | F62: 0.6 | G62: 1 | H62: 1 | I62: =C62*D62*F62*G62*H62 -> 30 | J62: =I62*TAN(ACOS(E62)) -> 18.59233 | K62: =SQRT(I62^2+J62^2) -> 35.294118
...
