Workbook

Sheet Balanço de Potências
A1: BALANÇO DE POTÊNCIA
C4: QP 1 (Oficina)
C5: Nº Equip | D5: NºCirc | E5: Nº Máq | F5: Descrição do equipamento | G5: Sref (kVA) | H5: FP | I5: ku | J5: ks | K5: ke | L5: ko | M5: S (kVA) | N5: P (kW) | O5: Q (kvar)
C6: 1 | D6: 10 | F6: Tomadas Monofásicas | G6: =((230*16)*D6)/1000 -> 36.8 | H6: 1 | I6: 1 | J6: 0.3 | K6: 1 | L6: 1 | M6: =G6*J6 -> 11.04 | N6: =M6*H6 -> 11.04 | O6: 0
C7: 1 | D7: 10 | F7: Tomadas Trifásicas | G7: =(SQRT(3)*400*16*D7)/1000 -> 110.85125 | H7: 1 | I7: 1 | J7: 0.3 | K7: 1 | L7: 1 | M7: =G7*I7*J7 -> 33.255376 | N7: =M7*H7 -> 33.255376 | O7: 0
C8: 30 | D8: 3 | F8: Iluminação | G8: =M8 -> 1.5697674 | H8: 0.86 | I8: 1 | J8: 1 | K8: 1 | L8: 1.25 | M8: =SQRT(N8^2+O8^2) -> 1.5697674 | N8: =0.036*C8*L8 -> 1.35 | O8: =N8*TAN(ACOS(H8)) -> 0.80104296
C9: 1 | D9: 1 | F9: ESG-618 | G9: =L9/H9 -> 1.25 | H9: 0.8 | I9: 0.75 | J9: 1 | K9: 1 | L9: 1 | M9: =SQRT(N9^2+O9^2) -> 1.03125 | N9: =J9*I9*1.1 -> 0.825 | O9: =N9*TAN(ACOS(H9)) -> 0.61875
C10: 1 | D10: 1 | F10: Microcut 8371 | G10: =L10/H10 -> 1.25 | H10: 0.8 | I10: 0.75 | J10: 1 | K10: 1 | L10: 1 | M10: =SQRT(N10^2+O10^2) -> 2.0625 | N10: =2.2*J10*I10 -> 1.65 | O10: =N10*TAN(ACOS(H10)) -> 1.2375
C11: 1 | D11: 1 | F11: Microcut 1500 | G11: =L11/H11 -> 1.25 | H11: 0.8 | I11: 0.75 | J11: 1 | K11: 1 | L11: 1 | M11: =SQRT(N11^2+O11^2) -> 2.8125 | N11: =3*J11*I11 -> 2.25 | O11: =N11*TAN(ACOS(H11)) -> 1.6875
C12: 1 | D12: 1 | F12: Microcut 1440E | G12: =L12/H12 -> 1.25 | H12: 0.8 | I12: 0.75 | J12: 1 | K12: 1 | L12: 1 | M12: =SQRT(N12^2+O12^2) -> 2.0625 | N12: =2.2*J12*I12 -> 1.65 | O12: =N12*TAN(ACOS(H12)) -> 1.2375
C13: 1 | D13: 1 | F13: Microcut 5600B | G13: =L13/H13 -> 1.25 | H13: 0.8 | I13: 0.75 | J13: 1 | K13: 1 | L13: 1 | M13: =SQRT(N13^2+O13^2) -> 1.5 | N13: =1.6*J13*I13 -> 1.2 | O13: =N13*TAN(ACOS(H13)) -> 0.9
C14: 1 | D14: 1 | F14: CNC | G14: 25 | H14: 0.8 | I14: 0.75 | J14: 1 | K14: 1 | L14: 1 | M14: =SQRT(N14^2+O14^2) -> 18.75 | N14: =20*J14*I14 -> 15 | O14: =N14*TAN(ACOS(H14)) -> 11.25
M15: =SUM(M6:M14) -> 74.083893 | N15: =SUM(N6:N14) -> 68.220376 | O15: =SUM(O6:O14) -> 17.732293
C18: QP 2 (Sala 6)
C19: Nº Equip | D19: NºCirc | E19: Nº Máq | F19: Descrição do equipamento | G19: Sref (kVA) | H19: FP | I19: ku | J19: ks | K19: ke | L19: ko | M19: S (kVA) | N19: P (kW) | O19: Q (kvar)
C20: 14 | D20: 3 | F20: Tomadas Monofásicas | G20: =((230*16)*D20)/1000 -> 11.04 | H20: 1 | I20: 1 | J20: 0.3 | K20: 1 | L20: 1 | M20: =G20*J20 -> 3.312 | N20: =M20*H20 -> 3.312 | O20: 0
C21: 1 | D21: 1 | F21: Tomadas Trifásicas | G21: =(SQRT(3)*400*16*D21)/1000 -> 11.085125 | H21: 1 | I21: 1 | J21: 0.3 | K21: 1 | L21: 1 | M21: =G21*I21*J21 -> 3.3255376 | N21: =M21*H21 -> 3.3255376 | O21: 0
C22: 20 | F22: Iluminação | H22: 0.86 | I22: 1 | J22: 1 | L22: =1.25 -> 1.25 | M22: =SQRT(N22^2+O22^2) -> 1.0465116 | N22: =(0.036*C22*L22) -> 0.9 | O22: =N22*TAN(ACOS(H22)) -> 0.53402864
M23: =SUM(M20:M22) -> 7.6840492 | N23: =SUM(N20:N22) -> 7.5375376 | O23: =SUM(O20:O22) -> 0.53402864
C26: QP 3 (Sala 5)
C27: Nº Equip | D27: NºCirc | E27: Nº Máq | F27: Descrição do equipamento | G27: Sref (kVA) | H27: FP | I27: ku | J27: ks | K27: ke | L27: ko | M27: S (kVA) | N27: P (kW) | O27: Q (kvar)
C28: 14 | D28: 3 | F28: Tomadas Monofásicas | G28: =((230*16)*D28)/1000 -> 11.04 | H28: 1 | I28: 1 | J28: 0.3 | K28: 1 | L28: 1 | M28: =G28*I28*J28 -> 3.312 | N28: =M28*H28 -> 3.312 | O28: 0
C29: 1 | D29: 1 | F29: Tomadas Trifásicas | G29: =(SQRT(3)*230*16*C29*D29)/1000 -> 6.373947 | H29: 1 | I29: 1 | J29: 0.3 | K29: 1 | L29: 1 | M29: =G29*I29*J29 -> 1.9121841 | N29: =M29*H29 -> 1.9121841 | O29: 0
C30: 20 | F30: Iluminação | G30: =M30 -> 1.0465116 | H30: 0.86 | I30: 1 | J30: 1 | K30: 1 | L30: 1.25 | M30: =SQRT(N30^2+O30^2) -> 1.0465116 | N30: =(36*C30*L30)/1000 -> 0.9 | O30: =N30*TAN(ACOS(H30)) -> 0.53402864
M31: =SUM(M28:M30) -> 6.2706957 | N31: =SUM(N28:N30) -> 6.1241841 | O31: =SUM(O28:O30) -> 0.53402864
C34: QP 4 (Sala 4)
C35: Nº Equip | D35: NºCirc | E35: Nº Máq | F35: Descrição do equipamento | G35: Sref (kVA) | H35: FP | I35: ku | J35: ks | K35: ke | L35: ko | M35: S (kVA) | N35: P (kW) | O35: Q (kvar)
C36: 14 | D36: 3 | F36: Tomadas Monofásicas | G36: =((230*16)*D36)/1000 -> 11.04 | H36: 1 | I36: 1 | J36: 0.3 | K36: 1 | L36: 1 | M36: =G36*I36*J36 -> 3.312 | N36: =M36*H36 -> 3.312 | O36: 0
C37: 1 | D37: 1 | F37: Tomadas Trifásicas | G37: =(SQRT(3)*230*16*C37*D37)/1000 -> 6.373947 | H37: 1 | I37: 1 | J37: 0.3 | K37: 1 | L37: 1 | M37: =G37*I37*J37 -> 1.9121841 | N37: =M37*H37 -> 1.9121841 | O37: 0
C38: 20 | F38: Iluminação | G38: =M38 -> 1.0465116 | H38: 0.86 | I38: 1 | J38: 1 | K38: 1 | L38: 1.25 | M38: =SQRT(N38^2+O38^2) -> 1.0465116 | N38: =(36*C38*L38)/1000 -> 0.9 | O38: =N38*TAN(ACOS(H38)) -> 0.53402864
M39: =SUM(M36:M38) -> 6.2706957 | N39: =SUM(N36:N38) -> 6.1241841 | O39: =SUM(O36:O38) -> 0.53402864
C42: QP 5 (Lab 5)
C43: Nº Equip | D43: NºCirc | E43: Nº Máq | F43: Descrição do equipamento | G43: Sref (kVA) | H43: FP | I43: ku | J43: ks | K43: ke | L43: ko | M43: S (kVA) | N43: P (kW) | O43: Q (kvar)
C44: 14 | D44: 3 | F44: Tomadas Monofásicas | G44: =((230*16)*D44)/1000 -> 11.04 | H44: 1 | I44: 1 | J44: 0.3 | K44: 1 | L44: 1 | M44: =G44*I44*J44 -> 3.312 | N44: =M44*H44 -> 3.312 | O44: 0
C45: 1 | D45: 1 | F45: Tomadas Trifásicas | G45: =(SQRT(3)*230*16*C45*D45)/1000 -> 6.373947 | H45: 1 | I45: 1 | J45: 0.3 | K45: 1 | L45: 1 | M45: =G45*I45*J45 -> 1.9121841 | N45: =M45*H45 -> 1.9121841 | O45: 0
C46: 20 | F46: Iluminação | G46: =M46 -> 1.0465116 | H46: 0.86 | I46: 1 | J46: 1 | K46: 1 | L46: 1.25 | M46: =SQRT(N46^2+O46^2) -> 1.0465116 | N46: =(36*C46*L46)/1000 -> 0.9 | O46: =N46*TAN(ACOS(H46)) -> 0.53402864
M47: =SUM(M44:M46) -> 6.2706957 | N47: =SUM(N44:N46) -> 6.1241841 | O47: =SUM(O44:O46) -> 0.53402864
C50: QP 6 (Lab 4)
C51: Nº Equip | D51: NºCirc | E51: Nº Máq | F51: Descrição do equipamento | G51: Sref (kVA) | H51: FP | I51: ku | J51: ks | K51: ke | L51: ko | M51: S (kVA) | N51: P (kW) | O51: Q (kvar)
D52: 10 | F52: Tomadas Monofásicas | G52: =((230*16)*D52)/1000 -> 36.8 | H52: 1 | I52: 1 | J52: 0.3 | K52: 1 | L52: 1 | M52: =G52*I52*J52 -> 11.04 | N52: =M52*H52 -> 11.04 | O52: 0
...

Sheet Sobrecarga e Queda de Tensão
A1: Sobrecargas e quedas de tensão
B3: Local | C3: Distância (m) | D3: S (kVA) | E3: FP | F3: Método de instalação | G3: Ref | H3: Ib (A) | I3: In (A) | J3: Ir (A) | K3: Fatores de Correção | L3: Iz_min (A) | M3: Condutor | N3: Isolamento | O3: Secção (mm2) | P3: Iz' (A) | Q3: Iz | R3: Ib ≤ Ir ≤ Iz | S3: I2 (A) | T3: I2 £ 1,45.Iz | U3: Queda de Tensão (V) | V3: Queda de Tensão % | W3: Du.max (%) | X3: Du <= Du.max | Y3: Designação do cabo | Z3: Proteção | AA3: Disparador
B4: QGBT - QGE | C4: =30+3 -> 33 | D4: ='Balanço de Potências'!O132 -> 148.0284 | E4: ='Balanço de Potências'!J119 -> 0.96222114 | F4: Cabos mono ou mult. Em cond. Ent. | G4: D | H4: =(D4*1000)/(400*SQRT(3)) -> 213.6606 | I4: 250 | J4: =I4 -> 250 | K4: =0.8*0.89*1.05 -> 0.7476 | L4: =I4/(K4) -> 334.40342 | M4: Cobre | N4: PVC | O4: 185 | P4: 367 | Q4: =P4*K4 -> 274.3692 | R4: =IF(AND(H4<=I4,I4<=Q4),"VERDADEIRO","FALSO") -> VERDADEIRO | S4: =1.3*J4 -> 325 | T4: =IF(S4<=1.45*Q4,"VERDADEIRO","FALSO") -> VERDADEIRO | U4: =((0.0225*(C4/O4))*E4+0.08/1000*C4*SIN(ACOS(E4)))*H4 -> 0.97871039 | V4: =(100*U4)/230 -> 0.42552626 | W4: 3 | X4: =IF(V4<=W4,"VERDADEIRO","FALSO") -> VERDADEIRO | Y4: 3x[VAV(frt)(zh) 1x185 0,6/1 kV] + VAV(frt)(zh) 1x150 0,6/1 kV + VAV(frt)(zh) 1G150 0,6/1 kV | Z4: Compact NSX400B 4P4D | AA4: Micrologic 2.3
B5: QGE - QP1 | C5: =33.4+3 -> 36.4 | D5: ='Balanço de Potências'!G120 -> 74.083893 | E5: ='Balanço de Potências'!J120 -> 0.92085301 | F5: Condutores isolados em condutas circulares embedidas nos elementos da construção, alvenaria | G5: B | H5: =(D5*1000)/(400*SQRT(3)) -> 106.93089 | I5: 125 | J5: =I5 -> 125 | K5: =0.57 -> 0.57 | L5: =I5/(K5) -> 219.29825 | M5: Cobre | N5: PVC | O5: 120 | P5: 239 | Q5: =P5*K5 -> 136.23 | R5: =IF(AND(H5<=I5,I5<=Q5),"VERDADEIRO","FALSO") -> VERDADEIRO | S5: =1.3*J5 -> 162.5 | T5: =IF(S5<=1.45*Q5,"VERDADEIRO","FALSO") -> VERDADEIRO | U5: =((0.0225*(C5/O5))*E5+0.08/1000*C5*SIN(ACOS(E5)))*H5 -> 0.7934528 | V5: =(100*U5)/230 -> 0.34497948 | W5: 3 | X5: =IF(V5<=W5,"VERDADEIRO","FALSO") -> VERDADEIRO | Y5: 3x[VV(frt)(zh) 1x120 0,6/1 kV] + VV(frt)(zh) 1x70 0,6/1 kV + VV(frt)(zh) 1G70 0,6/1 kV | Z5: Compact NSX160B 4P4D | AA5: TM125D
B6: QGE - QP2 | C6: =27.2+3 -> 30.2 | D6: ='Balanço de Potências'!G121 -> 7.6840492 | E6: ='Balanço de Potências'!J121 -> 0.98093302 | G6: B | H6: =(D6*1000)/(400*SQRT(3)) -> 11.09097 | I6: 25 | J6: =I6 -> 25 | K6: =0.57 -> 0.57 | L6: =I6/(K6) -> 43.859649 | M6: Cobre | N6: PVC | O6: 10 | P6: 50 | Q6: =P6*K6 -> 28.5 | R6: =IF(AND(H6<=I6,I6<=Q6),"VERDADEIRO","FALSO") -> VERDADEIRO | S6: =1.3*J6 -> 32.5 | T6: =IF(S6<=1.45*Q6,"VERDADEIRO","FALSO") -> VERDADEIRO | U6: =((0.0225*(C6/O6))*E6+0.08/1000*C6*SIN(ACOS(E6)))*H6 -> 0.74446957 | V6: =(100*U6)/230 -> 0.32368242 | W6: 3 | X6: =IF(V6<=W6,"VERDADEIRO","FALSO") -> VERDADEIRO | Y6: VV(frt)(zh) 5G10 0,6/1 kV | Z6: Compact NSX100B 4P3D | AA6: TM25D
B7: QGE - QP3 | C7: =22.6+3 -> 25.6 | D7: ='Balanço de Potências'!G122 -> 6.2706957 | E7: ='Balanço de Potências'!J122 -> 0.97663551 | G7: B | H7: =(D7*1000)/(400*SQRT(3)) -> 9.0509697 | I7: 25 | J7: =I7 -> 25 | K7: =0.57 -> 0.57 | L7: =I7/(K7) -> 43.859649 | M7: Cobre | N7: PVC | O7: 10 | P7: 50 | Q7: =P7*K7 -> 28.5 | R7: =IF(AND(H7<=I7,I7<=Q7),"VERDADEIRO","FALSO") -> VERDADEIRO | S7: =1.3*J7 -> 32.5 | T7: =IF(S7<=1.45*Q7,"VERDADEIRO","FALSO") -> VERDADEIRO | U7: =((0.0225*(C7/O7))*E7+0.08/1000*C7*SIN(ACOS(E7)))*H7 -> 0.51313862 | V7: =(100*U7)/230 -> 0.22310375 | W7: 3 | X7: =IF(V7<=W7,"VERDADEIRO","FALSO") -> VERDADEIRO | Y7: VV(frt)(zh) 5G10 0,6/1 kV | Z7: Compact NSX100B 4P3D | AA7: TM25D
B8: QGE - QP4 | C8: =14.1+3 -> 17.1 | D8: ='Balanço de Potências'!G123 -> 6.2706957 | E8: ='Balanço de Potências'!J123 -> 0.97663551 | G8: B | H8: =(D8*1000)/(400*SQRT(3)) -> 9.0509697 | I8: 25 | J8: =I8 -> 25 | K8: =0.57 -> 0.57 | L8: =I8/(K8) -> 43.859649 | M8: Cobre | N8: PVC | O8: 10 | P8: 50 | Q8: =P8*K8 -> 28.5 | R8: =IF(AND(H8<=I8,I8<=Q8),"VERDADEIRO","FALSO") -> VERDADEIRO | S8: =1.3*J8 -> 32.5 | T8: =IF(S8<=1.45*Q8,"VERDADEIRO","FALSO") -> VERDADEIRO | U8: =((0.0225*(C8/O8))*E8+0.08/1000*C8*SIN(ACOS(E8)))*H8 -> 0.34276056 | V8: =(100*U8)/230 -> 0.14902633 | W8: 3 | X8: =IF(V8<=W8,"VERDADEIRO","FALSO") -> VERDADEIRO | Y8: VV(frt)(zh) 5G10 0,6/1 kV | Z8: Compact NSX100B 4P | AA8: TM25D
B9: QGE - QP5 | C9: =9.3+3 -> 12.3 | D9: ='Balanço de Potências'!G124 -> 6.2706957 | E9: ='Balanço de Potências'!J124 -> 0.97663551 | G9: B | H9: =(D9*1000)/(400*SQRT(3)) -> 9.0509697 | I9: 25 | J9: =I9 -> 25 | K9: =0.57 -> 0.57 | L9: =I9/(K9) -> 43.859649 | M9: Cobre | N9: PVC | O9: 10 | P9: 50 | Q9: =P9*K9 -> 28.5 | R9: =IF(AND(H9<=I9,I9<=Q9),"VERDADEIRO","FALSO") -> VERDADEIRO | S9: =1.3*J9 -> 32.5 | T9: =IF(S9<=1.45*Q9,"VERDADEIRO","FALSO") -> VERDADEIRO | U9: =((0.0225*(C9/O9))*E9+0.08/1000*C9*SIN(ACOS(E9)))*H9 -> 0.24654707 | V9: =(100*U9)/230 -> 0.10719438 | W9: 3 | X9: =IF(V9<=W9,"VERDADEIRO","FALSO") -> VERDADEIRO | Y9: VV(frt)(zh) 5G10 0,6/1 kV | Z9: Compact NSX100B 4P3D | AA9: TM25D
B10: QGE - QP6 | C10: =7.7+3 -> 10.7 | D10: ='Balanço de Potências'!G125 -> 25.937814 | E10: ='Balanço de Potências'!J125 -> 0.97552958 | G10: B | H10: =(D10*1000)/(400*SQRT(3)) -> 37.43801 | I10: 80 | J10: =I10 -> 80 | K10: =0.57 -> 0.57 | L10: =I10/(K10) -> 140.35088 | M10: Cobre | N10: PVC | O10: 70 | P10: 171 | Q10: =P10*K10 -> 97.47 | R10: =IF(AND(H10<=I10,I10<=Q10),"VERDADEIRO","FALSO") -> VERDADEIRO | S10: =1.3*J10 -> 104 | T10: =IF(S10<=1.45*Q10,"VERDADEIRO","FALSO") -> VERDADEIRO | U10: =((0.0225*(C10/O10))*E10+0.08/1000*C10*SIN(ACOS(E10)))*H10 -> 0.1326553 | V10: =(100*U10)/230 -> 0.057676219 | W10: 3 | X10: =IF(V10<=W10,"VERDADEIRO","FALSO") -> VERDADEIRO | Y10: 3x[VV(frt)(zh) 1x70 0,6/1 kV] + VV(frt)(zh) 1x35 0,6/1 kV + VV(frt)(zh) 1G35 0,6/1 kV | Z10: Compact NSX100B 4P4D | AA10: TM80D
B11: QGE - QP7 | C11: =1.16+3 -> 4.16 | D11: ='Balanço de Potências'!G126 -> 34.31105 | E11: ='Balanço de Potências'!J126 -> 0.99658392 | G11: B | H11: =(D11*1000)/(400*SQRT(3)) -> 49.523735 | I11: 80 | J11: =I11 -> 80 | K11: =0.57 -> 0.57 | L11: =I11/(K11) -> 140.35088 | M11: Cobre | N11: PVC | O11: 70 | P11: 171 | Q11: =P11*K11 -> 97.47 | R11: =IF(AND(H11<=I11,I11<=Q11),"VERDADEIRO","FALSO") -> VERDADEIRO | S11: =1.3*J11 -> 104 | T11: =IF(S11<=1.45*Q11,"VERDADEIRO","FALSO") -> VERDADEIRO | U11: =((0.0225*(C11/O11))*E11+0.08/1000*C11*SIN(ACOS(E11)))*H11 -> 0.06735524 | V11: =(100*U11)/230 -> 0.029284887 | W11: 3 | X11: =IF(V11<=W11,"VERDADEIRO","FALSO") -> VERDADEIRO | Y11: 3x[VV(frt)(zh) 1x70 0,6/1 kV] + VV(frt)(zh) 1x35 0,6/1 kV + VV(frt)(zh) 1G35 0,6/1 kV | Z11: Compact NSX100B 4P4D | AA11: TM80D
B12: QGE - QP8 | C12: =5.4+3 -> 8.4 | D12: ='Balanço de Potências'!G127 -> 7.3746957 | E12: ='Balanço de Potências'!J127 -> 0.9801332 | G12: B | H12: =(D12*1000)/(400*SQRT(3)) -> 10.644456 | I12: 25 | J12: =I12 -> 25 | K12: =0.57 -> 0.57 | L12: =I12/(K12) -> 43.859649 | M12: Cobre | N12: PVC | O12: 10 | P12: 50 | Q12: =P12*K12 -> 28.5 | R12: =IF(AND(H12<=I12,I12<=Q12),"VERDADEIRO","FALSO") -> VERDADEIRO | S12: =1.3*J12 -> 32.5 | T12: =IF(S12<=1.45*Q12,"VERDADEIRO","FALSO") -> VERDADEIRO | U12: =((0.0225*(C12/O12))*E12+0.08/1000*C12*SIN(ACOS(E12)))*H12 -> 0.19860216 | V12: =(100*U12)/230 -> 0.086348766 | W12: 3 | X12: =IF(V12<=W12,"VERDADEIRO","FALSO") -> VERDADEIRO | Y12: VV(frt)(zh) 5G10 0,6/1 kV | Z12: Compact NSX100B 4P3D | AA12: TM25D
B13: QGE - QP9 | C13: =10.6+3 -> 13.6 | D13: ='Balanço de Potências'!G128 -> 20.839248 | E13: ='Balanço de Potências'!J128 -> 0.99296944 | G13: B | H13: =(D13*1000)/(400*SQRT(3)) -> 30.078864 | I13: 32 | J13: =I13 -> 32 | K13: =0.57 -> 0.57 | L13: =I13/(K13) -> 56.140351 | M13: Cobre | N13: PVC | O13: 16 | P13: 68 | Q13: =P13*K13 -> 38.76 | R13: =IF(AND(H13<=I13,I13<=Q13),"VERDADEIRO","FALSO") -> VERDADEIRO | S13: =1.3*J13 -> 41.6 | T13: =IF(S13<=1.45*Q13,"VERDADEIRO","FALSO") -> VERDADEIRO | U13: =((0.0225*(C13/O13))*E13+0.08/1000*C13*SIN(ACOS(E13)))*H13 -> 0.57508766 | V13: =(100*U13)/230 -> 0.25003811 | W13: 3 | X13: =IF(V13<=W13,"VERDADEIRO","FALSO") -> VERDADEIRO | Y13: VV(frt)(zh) 5G16 0,6/1 kV | Z13: Compact NSX100B 4P3D | AA13: TM32D
B14: QGE - QP10 | C14: =15.8+3 -> 18.8 | D14: ='Balanço de Potências'!G129 -> 20.839248 | E14: ='Balanço de Potências'!J129 -> 0.99296944 | G14: B | H14: =(D14*1000)/(400*SQRT(3)) -> 30.078864 | I14: 32 | J14: =I14 -> 32 | K14: =0.57 -> 0.57 | L14: =I14/(K14) -> 56.140351 | M14: Cobre | N14: PVC | O14: 16 | P14: 68 | Q14: =P14*K14 -> 38.76 | R14: =IF(AND(H14<=I14,I14<=Q14),"VERDADEIRO","FALSO") -> VERDADEIRO | S14: =1.3*J14 -> 41.6 | T14: =IF(S14<=1.45*Q14,"VERDADEIRO","FALSO") -> VERDADEIRO | U14: =((0.0225*(C14/O14))*E14+0.08/1000*C14*SIN(ACOS(E14)))*H14 -> 0.79497412 | V14: =(100*U14)/230 -> 0.34564092 | W14: 3 | X14: =IF(V14<=W14,"VERDADEIRO","FALSO") -> VERDADEIRO | Y14: VV(frt)(zh) 5G16 0,6/1 kV | Z14: Compact NSX100B 4P3D | AA14: TM32D
B15: QGE - QP11 | C15: =29+3 -> 32 | D15: ='Balanço de Potências'!G130 -> 19.388366 | E15: ='Balanço de Potências'!J130 -> 0.88968391 | G15: B | H15: =(D15*1000)/(400*SQRT(3)) -> 27.984696 | I15: 32 | J15: =I15 -> 32 | K15: =0.57 -> 0.57 | L15: =I15/(K15) -> 56.140351 | M15: Cobre | N15: PVC | O15: 16 | P15: 68 | Q15: =P15*K15 -> 38.76 | R15: =IF(AND(H15<=I15,I15<=Q15),"VERDADEIRO","FALSO") -> VERDADEIRO | S15: =1.3*J15 -> 41.6 | T15: =IF(S15<=1.45*Q15,"VERDADEIRO","FALSO") -> VERDADEIRO | U15: =((0.0225*(C15/O15))*E15+0.08/1000*C15*SIN(ACOS(E15)))*H15 -> 1.1530986 | V15: =(100*U15)/230 -> 0.50134721 | W15: 3 | X15: =IF(V15<=W15,"VERDADEIRO","FALSO") -> VERDADEIRO | Y15: VV(frt)(zh) 5G16 0,6/1 kV | Z15: Compact NSX100B 4P3D | AA15: TM32D
B16: QGE - QP12 | C16: =32.8+3 -> 35.8 | D16: ='Balanço de Potências'!G131 -> 4.2248353 | E16: ='Balanço de Potências'!J131 -> 0.99653213 | G16: B | H16: =(D16*1000)/(400*SQRT(3)) -> 6.0980244 | I16: 25 | J16: =I16 -> 25 | K16: =0.57 -> 0.57 | L16: =I16/(K16) -> 43.859649 | M16: Cobre | N16: PVC | O16: 10 | P16: 50 | Q16: =P16*K16 -> 28.5 | R16: =IF(AND(H16<=I16,I16<=Q16),"VERDADEIRO","FALSO") -> VERDADEIRO | S16: =1.3*J16 -> 32.5 | T16: =IF(S16<=1.45*Q16,"VERDADEIRO","FALSO") -> VERDADEIRO | U16: =((0.0225*(C16/O16))*E16+0.08/1000*C16*SIN(ACOS(E16)))*H16 -> 0.49094569 | V16: =(100*U16)/230 -> 0.21345465 | W16: 3 | X16: =IF(V16<=W16,"VERDADEIRO","FALSO") -> VERDADEIRO | Y16: VV(frt)(zh) 5G10 0,6/1 kV | Z16: Compact NSX100B 4P3D | AA16: TM25D
B17: QGE - QPUPS | C17: 1 | D17: 30 | E17: 0.98 | G17: B | H17: =(D17*1000)/(400*SQRT(3)) -> 43.30127 | I17: 80 | J17: =I17 -> 80 | K17: =0.57 -> 0.57 | L17: =I17/(K17) -> 140.35088 | M17: Cobre | N17: PVC | O17: 70 | P17: 171 | Q17: =P17*K17 -> 97.47 | R17: =IF(AND(H17<=I17,I17<=Q17),"VERDADEIRO","FALSO") -> VERDADEIRO | S17: =1.3*J17 -> 104 | T17: =IF(S17<=1.45*Q17,"VERDADEIRO","FALSO") -> VERDADEIRO | U17: =((0.0225*(C17/O17))*E17+0.08/1000*C17*SIN(ACOS(E17)))*H17 -> 0.014329248 | V17: =(100*U17)/230 -> 0.0062301077 | W17: 3 | X17: =IF(V17<=W17,"VERDADEIRO","FALSO") -> VERDADEIRO | Y17: VV(frt)(zh)3G70 0,6/1kV | Z17: Compact NSX100B 2P | AA17: TM80D
B19: Carga QP1 | C19: Distância (m) | D19: S (kVA) | E19: FP | F19: Método de instalação | G19: Ref | H19: Ib (A) | I19: In (A) | J19: Ir (A) | K19: Fatores de correção | L19: Iz_min (A) | M19: Condutor | N19: Isolamento | O19: Secção (mm2) | P19: Iz' (A) | Q19: Iz | R19: Ib≤In≤Iz | S19: I2 (A) | T19: I2 £ 1,45.Iz | U19: Queda de Tensão (V) | V19: Queda de Tensão % | W19: Du.max (%) | X19: Du <= Du.max | Y19: Designação do cabo | Z19: Proteção
B20: ESG-618 | C20: =1.5+0.45+5.8+1.5 -> 9.25 | D20: ='Balanço de Potências'!M9 -> 1.03125 | E20: ='Balanço de Potências'!H9 -> 0.8 | F20: Multicondutores, condutas circulares embebidos em elementos da construção | G20: A2 | H20: =(D20*1000)/(400*SQRT(3)) -> 1.4884812 | I20: 10 | J20: =I20 -> 10 | K20: =0.57 -> 0.57 | L20: =H20/K20 -> 2.6113705 | M20: Cobre | N20: PVC | O20: 4 | P20: 23 | Q20: =P20*K20 -> 13.11 | R20: =IF(AND(H20<=I20,I20<=Q20),"VERDADEIRO","FALSO") -> VERDADEIRO | S20: =1.3*J20 -> 13 | T20: =IF(S20<=1.45*Q20,"VERDADEIRO","FALSO") -> VERDADEIRO | U20: =((0.0225*(C20/O20))*E20+0.08/1000*C20*SIN(ACOS(E20)))*H20 -> 0.062618914 | V20: =(100*U20)/230 -> 0.027225615 | W20: 5 | X20: =IF(V20<=W20,"VERDADEIRO","FALSO") -> VERDADEIRO | Y20: VV(frt)(zh) 5G4 0,6/1 kV | Z20: IC60N D 10A 10kA 4P
B21: Microcut 8371 | C21: =1.5+0.4+7.1+4+1.5 -> 14.5 | D21: ='Balanço de Potências'!M10 -> 2.0625 | E21: ='Balanço de Potências'!H10 -> 0.8 | G21: A2 | H21: =(D21*1000)/(400*SQRT(3)) -> 2.9769623 | I21: 10 | J21: =I21 -> 10 | K21: =0.57 -> 0.57 | L21: =H21/K21 -> 5.2227409 | M21: Cobre | N21: PVC | O21: 4 | P21: 23 | Q21: =P21*K21 -> 13.11 | R21: =IF(AND(H21<=I21,I21<=Q21),"VERDADEIRO","FALSO") -> VERDADEIRO | S21: =1.3*J21 -> 13 | T21: =IF(S21<=1.45*Q21,"VERDADEIRO","FALSO") -> VERDADEIRO | U21: =((0.0225*(C21/O21))*E21+0.08/1000*C21*SIN(ACOS(E21)))*H21 -> 0.19631876 | V21: =(100*U21)/230 -> 0.085355982 | W21: 5 | X21: =IF(V21<=W21,"VERDADEIRO","FALSO") -> VERDADEIRO | Y21: VV(frt)(zh) 5G4 0,6/1 kV | Z21: IC60N D 10A 10kA 4P
B22: Microcut 1500 | C22: =1.5+0.45+7.1+9.7+1.5 -> 20.25 | D22: ='Balanço de Potências'!M11 -> 2.8125 | E22: ='Balanço de Potências'!H11 -> 0.8 | G22: A2 | H22: =(D22*1000)/(400*SQRT(3)) -> 4.0594941 | I22: 10 | J22: =I22 -> 10 | K22: =0.57 -> 0.57 | L22: =H22/K22 -> 7.1219194 | M22: Cobre | N22: PVC | O22: 4 | P22: 23 | Q22: =P22*K22 -> 13.11 | R22: =IF(AND(H22<=I22,I22<=Q22),"VERDADEIRO","FALSO") -> VERDADEIRO | S22: =1.3*J22 -> 13 | T22: =IF(S22<=1.45*Q22,"VERDADEIRO","FALSO") -> VERDADEIRO | U22: =((0.0225*(C22/O22))*E22+0.08/1000*C22*SIN(ACOS(E22)))*H22 -> 0.37386723 | V22: =(100*U22)/230 -> 0.16255097 | W22: 5 | X22: =IF(V22<=W22,"VERDADEIRO","FALSO") -> VERDADEIRO | Y22: VV(frt)(zh) 5G4 0,6/1 kV | Z22: IC60N D 10A 10kA 4P
B23: Microcut 1440E | C23: =1.5+0.45+7.1+12.7+1.5 -> 23.25 | D23: ='Balanço de Potências'!M12 -> 2.0625 | E23: ='Balanço de Potências'!H12 -> 0.8 | G23: A2 | H23: =(D23*1000)/(400*SQRT(3)) -> 2.9769623 | I23: 10 | J23: =I23 -> 10 | K23: =0.57 -> 0.57 | L23: =H23/K23 -> 5.2227409 | M23: Cobre | N23: PVC | O23: 4 | P23: 23 | Q23: =P23*K23 -> 13.11 | R23: =IF(AND(H23<=I23,I23<=Q23),"VERDADEIRO","FALSO") -> VERDADEIRO | S23: =1.3*J23 -> 13 | T23: =IF(S23<=1.45*Q23,"VERDADEIRO","FALSO") -> VERDADEIRO | U23: =((0.0225*(C23/O23))*E23+0.08/1000*C23*SIN(ACOS(E23)))*H23 -> 0.31478697 | V23: =(100*U23)/230 -> 0.1368639 | W23: 5 | X23: =IF(V23<=W23,"VERDADEIRO","FALSO") -> VERDADEIRO | Y23: VV(frt)(zh) 5G4 0,6/1 kV | Z23: IC60N D 10A 10kA 4P
B24: Microcut 5600B | C24: =1.5+0.45+7.1+13.7+6.7+1.5 -> 30.95 | D24: ='Balanço de Potências'!M13 -> 1.5 | E24: ='Balanço de Potências'!H13 -> 0.8 | G24: A2 | H24: =(D24*1000)/(400*SQRT(3)) -> 2.1650635 | I24: 10 | J24: =I24 -> 10 | K24: =0.57 -> 0.57 | L24: =H24/K24 -> 3.798357 | M24: Cobre | N24: PVC | O24: 4 | P24: 23 | Q24: =P24*K24 -> 13.11 | R24: =IF(AND(H24<=I24,I24<=Q24),"VERDADEIRO","FALSO") -> VERDADEIRO | S24: =1.3*J24 -> 13 | T24: =IF(S24<=1.45*Q24,"VERDADEIRO","FALSO") -> VERDADEIRO | U24: =((0.0225*(C24/O24))*E24+0.08/1000*C24*SIN(ACOS(E24)))*H24 -> 0.30475564 | V24: =(100*U24)/230 -> 0.13250245 | W24: 5 | X24: =IF(V24<=W24,"VERDADEIRO","FALSO") -> VERDADEIRO | Y24: VV(frt)(zh) 5G4 0,6/1 kV | Z24: IC60N D 10A 10kA 4P
B25: CNC | C25: =1.5+0.45+7.1+7+1.5 -> 17.55 | D25: ='Balanço de Potências'!M14 -> 18.75 | E25: ='Balanço de Potências'!H14 -> 0.8 | G25: A2 | H25: =(D25*1000)/(400*SQRT(3)) -> 27.063294 | I25: 32 | J25: =I25 -> 32 | K25: =0.57 -> 0.57 | L25: =H25/K25 -> 47.479463 | M25: Cobre | N25: PVC | O25: 25 | P25: 68 | Q25: =P25*K25 -> 38.76 | R25: =IF(AND(H25<=I25,I25<=Q25),"VERDADEIRO","FALSO") -> VERDADEIRO | S25: =1.3*J25 -> 41.6 | T25: =IF(S25<=1.45*Q25,"VERDADEIRO","FALSO") -> VERDADEIRO | U25: =((0.0225*(C25/O25))*E25+0.08/1000*C25*SIN(ACOS(E25)))*H25 -> 0.3647699 | V25: =(100*U25)/230 -> 0.15859561 | W25: 5 | X25: =IF(V25<=W25,"VERDADEIRO","FALSO") -> VERDADEIRO | Y25: VV(frt)(zh) 5G25 0,6/1 kV | Z25: IC60N D 32A 10kA 4P
B27: Compressor | C27: 7 | D27: ='Balanço de Potências'!G96 -> 15.32567 | E27: ='Balanço de Potências'!H96 -> 0.87 | F27: Multicondutores, condutas circulares embebidos em elementos da construção | G27: A2 | H27: =(D27*1000)/(400*SQRT(3)) -> 22.1207 | I27: 25 | J27: 25 | K27: 1 | L27: =H27/K27 -> 22.1207 | M27: cobre | N27: PVC | O27: 6 | P27: 29 | Q27: =P27*K27 -> 29 | R27: =IF(AND(H27<=I27,I27<=Q27),"VERDADEIRO","FALSO") -> VERDADEIRO | S27: =1.3*J27 -> 32.5 | T27: =IF(S27<=1.45*Q27,"VERDADEIRO","FALSO") -> VERDADEIRO | U27: =((0.0225*(C27/O27))*E27+0.08/1000*C27*SIN(ACOS(E27)))*H27 -> 0.51128921 | V27: =(100*U27)/230 -> 0.22229966 | W27: 5 | X27: =IF(V27<=W27,"VERDADEIRO","FALSO") -> VERDADEIRO | Y27: VV(frt)(zh) 5G6 0,6/1 kV | Z27: IC60N D 32A 10kA 4P
B28: Tomadas mono | C28: 37 | D28: ='Balanço de Potências'!M6/10 -> 1.104 | E28: 1 | G28: A2 | H28: =D28*1000/230 -> 4.8 | I28: 16 | J28: 16 | K28: 1 | L28: =H28/K28 -> 4.8 | M28: cobre | N28: PVC | O28: 2.5 | P28: 18.5 | Q28: =P28*K28 -> 18.5 | R28: =IF(AND(H28<=I28,I28<=Q28),"VERDADEIRO","FALSO") -> VERDADEIRO | S28: =1.3*J28 -> 20.8 | T28: =IF(S28<=1.45*Q28,"VERDADEIRO","FALSO") -> VERDADEIRO | U28: =((0.0225*(C28/O28))*E28+0.08/1000*C28*SIN(ACOS(E28)))*H28 -> 1.5984 | V28: =(100*U28)/230 -> 0.69495652 | W28: 5 | X28: =IF(V28<=W28,"VERDADEIRO","FALSO") -> VERDADEIRO | Y28: VV(frt)(zh) 3G2,5 0,6/1 kV | Z28: C60N D 16A 10kA 4P
B29: Tomadas tri | C29: 36 | D29: ='Balanço de Potências'!M7/10 -> 3.3255376 | E29: 1 | G29: A2 | H29: =(D29*1000)/(400*SQRT(3)) -> 4.8 | I29: 16 | J29: 16 | K29: 1 | L29: =H29/K29 -> 4.8 | M29: cobre | N29: PVC | O29: 2.5 | P29: 17.5 | Q29: =P29*K29 -> 17.5 | R29: =IF(AND(H29<=I29,I29<=Q29),"VERDADEIRO","FALSO") -> VERDADEIRO | S29: =1.3*J29 -> 20.8 | T29: =IF(S29<=1.45*Q29,"VERDADEIRO","FALSO") -> VERDADEIRO | U29: =((0.0225*(C29/O29))*E29+0.08/1000*C29*SIN(ACOS(E29)))*H29 -> 1.5552 | V29: =(100*U29)/230 -> 0.67617391 | W29: 5 | X29: =IF(V29<=W29,"VERDADEIRO","FALSO") -> VERDADEIRO | Y29: VV(frt)(zh) 5G2,5 0,6/1 kV | Z29: C60N D 16A 10kA 4P
B30: Iluminação | C30: 37 | D30: 1.3 | E30: 0.86 | G30: A2 | H30: =D30*1000/230 -> 5.6521739 | I30: 10 | J30: 10 | K30: 1 | L30: =H30/K30 -> 5.6521739 | M30: cobre | N30: PVC | O30: 1.5 | P30: 14 | Q30: =P30*K30 -> 14 | R30: =IF(AND(H30<=I30,I30<=Q30),"VERDADEIRO","FALSO") -> VERDADEIRO | S30: =1.3*J30 -> 13 | T30: =IF(S30<=1.45*Q30,"VERDADEIRO","FALSO") -> VERDADEIRO | U30: =((0.0225*(C30/O30))*E30+0.08/1000*C30*SIN(ACOS(E30)))*H30 -> 2.70632 | V30: =(100*U30)/230 -> 1.1766609 | W30: 3 | X30: =IF(V30<=W30,"VERDADEIRO","FALSO") -> VERDADEIRO | Y30: VV(frt)(zh) 5G1,5 0,6/1 kV | Z30: C60N D 10A 10kA 4P
Z32: Sobrecargas e Queda de Tensão

Sheet Curto-Circuito2
A1: Curto-circuitos
C3: Rede | D3: Transformador | F3: Cabo | M3: Disjun. | N3: Barram. | O3: Rede
C4: Scc | D4: Sn | E4: ucc | F4: ρ.cu.max | G4: ρ.al.max | H4: ρ.cu.min | I4: ρ.al.min | J4: k (PVC; cu) | K4: k (XLPE; cu) | L4: l | M4: XL | N4: XL | O4: m | P4: cmáx | Q4: cmin | R4: Un
C5: (MVA) | D5: (kVA) | E5: (%) | F5: Ω.mm2/m | J5: - | K5: - | L5: mW/m | M5: mW/polo | N5: mW/m | O5: - | P5: - | Q5: - | R5: V
C6: 500 | D6: 250 | E6: 4 | F6: 0.0225 | G6: 0.036 | H6: 0.01724 | I6: 0.02826 | J6: 115 | K6: 143 | L6: =0.08 -> 0.08 | M6: 0.15 | N6: 0.18 | O6: 1.05 | P6: 1.05 | Q6: 0.95 | R6: 400
H9: Correntes de curto-circuito máximas | U9: Proteção
B10: Localização | D10: Sf (mm2) | E10: Sn (mm2) | F10: L (m) | G10: Ir (A) | H10: R3.min (mW) | I10: X3.min (mW) | J10: Z3.min (mW) | K10: Z3.acum (mW) | L10: R1.min (mW) | M10: X1.min (mW) | N10: Z1.min (mW) | O10: Z1.acum (mW) | P10: Ik3.max (kA) | Q10: Ik2.max (kA) | R10: Ik1.max (kA) | S10: Ics (kA) | T10: Ik3.max < Ics | U10: Proteção (designação completa) | V10: Disparador
B11: Terminais do Transformador | C11: Rede a montante | H11: =0.1*I11 -> 0.0351036 | I11: =0.995*J11 -> 0.351036 | J11: =((($O$6*$R$6)^2)/($C$6*10^6))*1000 -> 0.3528 | K11: =J11 -> 0.3528 | L11: =0.1*M11 -> 0.0351036 | M11: =0.995*N11 -> 0.351036 | N11: =((($O$6*$R$6)^2)/($C$6*10^6))*1000 -> 0.3528 | O11: =N11 -> 0.3528 | P11: =($R$6*$P$6*$O$6)/(SQRT(3)*K11) -> 721.68784 | Q11: =SQRT(3)/2*P11 -> 625 | R11: =($R$6*$P$6*$O$6)/(SQRT(3)*(O11)) -> 721.68784
C12: Transformador | H12: =0.31*J12 -> 8.74944 | I12: =0.95*J12 -> 26.8128 | J12: =((($O$6*$R$6)^2)/($D$6*10^3))*($E$6/100)*1000 -> 28.224 | K12: =K11+J12 -> 28.5768 | L12: =0.31*N12 -> 8.74944 | M12: =0.95*N12 -> 26.8128 | N12: =((($O$6*$R$6)^2)/($D$6*10^3))*($E$6/100)*1000 -> 28.224 | O12: =O11+N12 -> 28.5768 | P12: =($R$6*$P$6*$O$6)/(SQRT(3)*K12) -> 8.9097264 | Q12: =SQRT(3)/2*P12 -> 7.7160494 | R12: =($R$6*$P$6*$O$6)/(SQRT(3)*(O12)) -> 8.9097264 | S12: 25 | T12: =IF(P12<S12,TRUE,FALSE) -> TRUE
B13: QGBT - QGE | C13: Condutor | D13: ='Sobrecarga e Queda de Tensão'!O4 -> 185 | E13: 150 | F13: ='Sobrecarga e Queda de Tensão'!C4 -> 33 | G13: ='Sobrecarga e Queda de Tensão'!J4 -> 250 | H13: =$H$6*$F13/$D13*1000 -> 3.0752432 | I13: =$L$6*$F13 -> 2.64 | J13: =SQRT(H13^2+I13^2) -> 4.0529891 | K13: =K12+J13 -> 32.629789 | L13: =$H$6*$F13*(1/$D13+1/$E13)*1000 -> 6.8680432 | M13: =2*$L$6*$F13 -> 5.28 | N13: =SQRT(L13^2+M13^2) -> 8.663049 | O13: =O12+N13 -> 37.239849 | P13: =($R$6*$P$6*$O$6)/(SQRT(3)*K13) -> 7.8030375 | Q13: =SQRT(3)/2*P13 -> 6.7576287 | R13: =($R$6*$P$6*$O$6)/(SQRT(3)*(O13)) -> 6.8370704 | S13: 25 | T13: =IF(P13<S13,TRUE,FALSE) -> TRUE | U13: Compact NSX400B 4P4D 25kA | V13: Micrologic 2.3
C14: Disjuntor | H14: 0 | I14: =M6 -> 0.15 | J14: =SQRT(H14^2+I14^2) -> 0.15 | K14: =K13+J14 -> 32.779789 | L14: 0 | M14: =$M$6 -> 0.15 | N14: =SQRT(L14^2+M14^2) -> 0.15 | O14: =O13+N14 -> 37.389849 | P14: =($R$6*$P$6*$O$6)/(SQRT(3)*K14) -> 7.7673309 | Q14: =SQRT(3)/2*P14 -> 6.7267059 | R14: =($R$6*$P$6*$O$6)/(SQRT(3)*(O14)) -> 6.8096415 | S14: 25 | T14: =IF(P14<S14,TRUE,FALSE) -> TRUE
C15: Barramento | D15: =30*10 -> 300 | E15: =D15 -> 300 | F15: 1.2 | H15: =$F$6*$F$15/$D$15 -> 9e-05 | I15: =$N$6*$F$15 -> 0.216 | J15: =SQRT(H15^2+I15^2) -> 0.21600002 | K15: =K14+J15 -> 32.995789 | L15: =$F$6*$F$15/$D$15 -> 9e-05 | M15: =$N$6*$F$15 -> 0.216 | N15: =SQRT(L15^2+M15^2) -> 0.21600002 | O15: =O14+N15 -> 37.605849 | P15: =($R$6*$P$6*$O$6)/(SQRT(3)*K15) -> 7.7164837 | Q15: =SQRT(3)/2*P15 -> 6.6826709 | R15: =($R$6*$P$6*$O$6)/(SQRT(3)*(O15)) -> 6.7705284 | S15: 25 | T15: =IF(P15<S15,TRUE,FALSE) -> TRUE
B16: QGE - Tomadas trifásicas | C16: Condutor | D16: 2.5 | E16: 2.5 | F16: 36 | G16: 16 | H16: =$H$6*F16/D16*1000 -> 248.256 | I16: =$L$6*$F16 -> 2.88 | J16: =SQRT(H16^2+I16^2) -> 248.2727 | K16: =$K$15+J16 -> 281.26849 | L16: =$H$6*$F16*(1/$D16+1/$E16)*1000 -> 496.512 | M16: =2*$L$6*$F16 -> 5.76 | N16: =SQRT(L16^2+M16^2) -> 496.54541 | O16: =$O$15+N16 -> 534.15126 | P16: =($R$6*$P$6*$O$6)/(SQRT(3)*K16) -> 0.9052257 | Q16: =SQRT(3)/2*P16 -> 0.78394845 | R16: =($R$6*$P$6*$O$6)/(SQRT(3)*(O16)) -> 0.47666548 | S16: 10 | T16: =IF(P16<S16,TRUE,FALSE) -> TRUE
B17: QGE - Tomadas mono | C17: Condutor | D17: 2.5 | E17: 2.5 | F17: 37 | G17: 16 | H17: =$H$6*F17/D17*1000 -> 255.152 | I17: =$L$6*$F17 -> 2.96 | J17: =SQRT(H17^2+I17^2) -> 255.16917 | K17: =$K$15+J17 -> 288.16496 | L17: =$H$6*$F17*(1/$D17+1/$E17)*1000 -> 510.304 | M17: =2*$L$6*$F17 -> 5.92 | N17: =SQRT(L17^2+M17^2) -> 510.33834 | O17: =$O$15+N17 -> 547.94419 | P17: =($R$6*$P$6*$O$6)/(SQRT(3)*K17) -> 0.88356152 | Q17: =SQRT(3)/2*P17 -> 0.76518672 | R17: =($R$6*$P$6*$O$6)/(SQRT(3)*(O17)) -> 0.46466679 | S17: 10 | T17: =IF(P17<S17,TRUE,FALSE) -> TRUE
B18: QGE - QP1 | C18: Condutor | D18: ='Sobrecarga e Queda de Tensão'!O5 -> 120 | E18: 70 | F18: ='Sobrecarga e Queda de Tensão'!C5 -> 36.4 | G18: ='Sobrecarga e Queda de Tensão'!J5 -> 125 | H18: =$H$6*F18/D18*1000 -> 5.2294667 | I18: =$L$6*$F18 -> 2.912 | J18: =SQRT(H18^2+I18^2) -> 5.9855715 | K18: =$K$15+J18 -> 38.981361 | L18: =$H$6*$F18*(1/$D18+1/$E18)*1000 -> 14.194267 | M18: =2*$L$6*$F18 -> 5.824 | N18: =SQRT(L18^2+M18^2) -> 15.342626 | O18: =$O$15+N18 -> 52.948475 | P18: =($R$6*$P$6*$O$6)/(SQRT(3)*K18) -> 6.5316209 | Q18: =SQRT(3)/2*P18 -> 5.6565496 | R18: =($R$6*$P$6*$O$6)/(SQRT(3)*(O18)) -> 4.8086648 | S18: 25 | T18: =IF(P18<S18,TRUE,FALSE) -> TRUE | U18: Compact NSX160B 4P4D 25kA | V18: TM125D
B19: QP1 -ESG-618 | C19: Condutor | D19: 4 | E19: 4 | F19: =1.5+0.45+5.8+1.5 -> 9.25 | G19: 10 | H19: =$H$6*F19/D19*1000 -> 39.8675 | I19: =$L$6*$F19 -> 0.74 | J19: =SQRT(H19^2+I19^2) -> 39.874367 | K19: =$K$18+J19 -> 78.855728 | L19: =$H$6*$F19*(1/$D19+1/$E19)*1000 -> 79.735 | M19: =2*$L$6*$F19 -> 1.48 | N19: =SQRT(L19^2+M19^2) -> 79.748734 | O19: =$O$18+N19 -> 132.69721 | P19: =($R$6*$P$6*$O$6)/(SQRT(3)*K19) -> 3.2288266 | Q19: =SQRT(3)/2*P19 -> 2.7962458 | R19: =($R$6*$P$6*$O$6)/(SQRT(3)*(O19)) -> 1.9187402 | S19: 10 | T19: =IF(P19<S19,TRUE,FALSE) -> TRUE | U19: IC60N D 10A 10kA 4P
B20: QP1 - Microcut 8371 | C20: Condutor | D20: 4 | E20: 4 | F20: =1.5+0.4+7.1+4+1.5 -> 14.5 | G20: 10 | H20: =$H$6*F20/D20*1000 -> 62.495 | I20: =$L$6*$F20 -> 1.16 | J20: =SQRT(H20^2+I20^2) -> 62.505765 | K20: =$K$15+J20 -> 95.501554 | L20: =$H$6*$F20*(1/$D20+1/$E20)*1000 -> 124.99 | M20: =2*$L$6*$F20 -> 2.32 | N20: =SQRT(L20^2+M20^2) -> 125.01153 | O20: =$O$15+N20 -> 162.61738 | P20: =($R$6*$P$6*$O$6)/(SQRT(3)*K20) -> 2.6660453 | Q20: =SQRT(3)/2*P20 -> 2.308863 | R20: =($R$6*$P$6*$O$6)/(SQRT(3)*(O20)) -> 1.5657089 | S20: 10 | T20: =IF(P20<S20,TRUE,FALSE) -> TRUE | U20: IC60N D 10A 10kA 4P
B21: QP1 - Microcut 1500 | C21: Condutor | D21: 4 | E21: 4 | F21: =1.5+0.45+7.1+9.7+1.5 -> 20.25 | G21: 10 | H21: =$H$6*F21/D21*1000 -> 87.2775 | I21: =$L$6*$F21 -> 1.62 | J21: =SQRT(H21^2+I21^2) -> 87.292534 | K21: =$K$15+J21 -> 120.28832 | L21: =$H$6*$F21*(1/$D21+1/$E21)*1000 -> 174.555 | M21: =2*$L$6*$F21 -> 3.24 | N21: =SQRT(L21^2+M21^2) -> 174.58507 | O21: =$O$15+N21 -> 212.19092 | P21: =($R$6*$P$6*$O$6)/(SQRT(3)*K21) -> 2.1166765 | Q21: =SQRT(3)/2*P21 -> 1.8330956 | R21: =($R$6*$P$6*$O$6)/(SQRT(3)*(O21)) -> 1.1999169 | S21: 10 | T21: =IF(P21<S21,TRUE,FALSE) -> TRUE | U21: IC60N D 10A 10kA 4P
B22: QP1 - Microcut 1440E | C22: Condutor | D22: 4 | E22: 4 | F22: =1.5+0.45+7.1+12.7+1.5 -> 23.25 | G22: 10 | H22: =$H$6*F22/D22*1000 -> 100.2075 | I22: =$L$6*$F22 -> 1.86 | J22: =SQRT(H22^2+I22^2) -> 100.22476 | K22: =$K$15+J22 -> 133.22055 | L22: =$H$6*$F22*(1/$D22+1/$E22)*1000 -> 200.415 | M22: =2*$L$6*$F22 -> 3.72 | N22: =SQRT(L22^2+M22^2) -> 200.44952 | O22: =$O$15+N22 -> 238.05537 | P22: =($R$6*$P$6*$O$6)/(SQRT(3)*K22) -> 1.9112027 | Q22: =SQRT(3)/2*P22 -> 1.6551501 | R22: =($R$6*$P$6*$O$6)/(SQRT(3)*(O22)) -> 1.0695473 | S22: 10 | T22: =IF(P22<S22,TRUE,FALSE) -> TRUE | U22: IC60N D 10A 10kA 4P
B23: QP1 - Microcut 5600B | C23: Condutor | D23: 4 | E23: 4 | F23: =1.5+0.45+7.1+13.7+6.7+1.5 -> 30.95 | G23: 10 | H23: =$H$6*F23/D23*1000 -> 133.3945 | I23: =$L$6*$F23 -> 2.476 | J23: =SQRT(H23^2+I23^2) -> 133.41748 | K23: =$K$15+J23 -> 166.41327 | L23: =$H$6*$F23*(1/$D23+1/$E23)*1000 -> 266.789 | M23: =2*$L$6*$F23 -> 4.952 | N23: =SQRT(L23^2+M23^2) -> 266.83495 | O23: =$O$15+N23 -> 304.4408 | P23: =($R$6*$P$6*$O$6)/(SQRT(3)*K23) -> 1.529995 | Q23: =SQRT(3)/2*P23 -> 1.3250146 | R23: =($R$6*$P$6*$O$6)/(SQRT(3)*(O23)) -> 0.83632505 | S23: 10 | T23: =IF(P23<S23,TRUE,FALSE) -> TRUE | U23: IC60N D 10A 10kA 4P
B24: QP1 - Iluminação | C24: condutor | D24: 2.5 | E24: 2.5 | F24: 37 | G24: 10 | H24: =$H$6*F24/D24*1000 -> 255.152 | I24: =$L$6*$F24 -> 2.96 | J24: =SQRT(H24^2+I24^2) -> 255.16917 | K24: =$K$15+J24 -> 288.16496 | L24: =$H$6*$F24*(1/$D24+1/$E24)*1000 -> 510.304 | M24: =2*$L$6*$F24 -> 5.92 | N24: =SQRT(L24^2+M24^2) -> 510.33834 | O24: =$O$15+N24 -> 547.94419 | P24: =($R$6*$P$6*$O$6)/(SQRT(3)*K24) -> 0.88356152 | Q24: =SQRT(3)/2*P24 -> 0.76518672 | R24: =($R$6*$P$6*$O$6)/(SQRT(3)*(O24)) -> 0.46466679 | S24: 10 | T24: =IF(P24<S24,TRUE,FALSE) -> TRUE | U24: C60N D 10A 10kA 4P
B25: QP1 - CNC | C25: Condutor | D25: 25 | E25: 25 | F25: =1.5+0.45+7.1+7+1.5 -> 17.55 | G25: 32 | H25: =$H$6*F25/D25*1000 -> 12.10248 | I25: =$L$6*$F25 -> 1.404 | J25: =SQRT(H25^2+I25^2) -> 12.183646 | K25: =$K$15+J25 -> 45.179436 | L25: =$H$6*$F25*(1/$D25+1/$E25)*1000 -> 24.20496 | M25: =2*$L$6*$F25 -> 2.808 | N25: =SQRT(L25^2+M25^2) -> 24.367293 | O25: =$O$15+N25 -> 61.973142 | P25: =($R$6*$P$6*$O$6)/(SQRT(3)*K25) -> 5.6355611 | Q25: =SQRT(3)/2*P25 -> 4.8805391 | R25: =($R$6*$P$6*$O$6)/(SQRT(3)*(O25)) -> 4.1084164 | S25: 10 | T25: =IF(P25<S25,TRUE,FALSE) -> TRUE | U25: IC60N D 32A 10kA 4P
B26: QGE- QP2 | C26: Condutor | D26: ='Sobrecarga e Queda de Tensão'!O6 -> 10 | E26: =D26 -> 10 | F26: ='Sobrecarga e Queda de Tensão'!C6 -> 30.2 | G26: ='Sobrecarga e Queda de Tensão'!J6 -> 25 | H26: =$H$6*F26/D26*1000 -> 52.0648 | I26: =$L$6*$F26 -> 2.416 | J26: =SQRT(H26^2+I26^2) -> 52.120826 | K26: =$K$15+J26 -> 85.116615 | L26: =$H$6*$F26*(1/$D26+1/$E26)*1000 -> 104.1296 | M26: =2*$L$6*$F26 -> 4.832 | N26: =SQRT(L26^2+M26^2) -> 104.24165 | O26: =$O$15+N26 -> 141.8475 | P26: =($R$6*$P$6*$O$6)/(SQRT(3)*K26) -> 2.9913251 | Q26: =SQRT(3)/2*P26 -> 2.5905636 | R26: =($R$6*$P$6*$O$6)/(SQRT(3)*(O26)) -> 1.7949662 | S26: 25 | T26: =IF(P26<S26,TRUE,FALSE) -> TRUE | U26: Compact NSX100B 4P3D 25kA | V26: TM25D
B27: QGE - QP3 | C27: Condutor | D27: ='Sobrecarga e Queda de Tensão'!O7 -> 10 | E27: =D27 -> 10 | F27: ='Sobrecarga e Queda de Tensão'!C7 -> 25.6 | G27: ='Sobrecarga e Queda de Tensão'!J7 -> 25 | H27: =$H$6*F27/D27*1000 -> 44.1344 | I27: =$L$6*$F27 -> 2.048 | J27: =SQRT(H27^2+I27^2) -> 44.181892 | K27: =$K$15+J27 -> 77.177681 | L27: =$H$6*$F27*(1/$D27+1/$E27)*1000 -> 88.2688 | M27: =2*$L$6*$F27 -> 4.096 | N27: =SQRT(L27^2+M27^2) -> 88.363784 | O27: =$O$15+N27 -> 125.96963 | P27: =($R$6*$P$6*$O$6)/(SQRT(3)*K27) -> 3.2990298 | Q27: =SQRT(3)/2*P27 -> 2.8570436 | R27: =($R$6*$P$6*$O$6)/(SQRT(3)*(O27)) -> 2.0212131 | S27: 25 | T27: =IF(P27<S27,TRUE,FALSE) -> TRUE | U27: Compact NSX100B 4P3D 25kA | V27: TM25D
B28: QGE - QP4 | C28: Condutor | D28: ='Sobrecarga e Queda de Tensão'!O8 -> 10 | E28: =D28 -> 10 | F28: ='Sobrecarga e Queda de Tensão'!C8 -> 17.1 | G28: ='Sobrecarga e Queda de Tensão'!J8 -> 25 | H28: =$H$6*F28/D28*1000 -> 29.4804 | I28: =$L$6*$F28 -> 1.368 | J28: =SQRT(H28^2+I28^2) -> 29.512123 | K28: =$K$15+J28 -> 62.507912 | L28: =$H$6*$F28*(1/$D28+1/$E28)*1000 -> 58.9608 | M28: =2*$L$6*$F28 -> 2.736 | N28: =SQRT(L28^2+M28^2) -> 59.024246 | O28: =$O$15+N28 -> 96.630095 | P28: =($R$6*$P$6*$O$6)/(SQRT(3)*K28) -> 4.0732678 | Q28: =SQRT(3)/2*P28 -> 3.5275534 | R28: =($R$6*$P$6*$O$6)/(SQRT(3)*(O28)) -> 2.6349086 | S28: 25 | T28: =IF(P28<S28,TRUE,FALSE) -> TRUE | U28: Compact NSX100B 4P3D 25kA | V28: TM25D
B29: QGE - QP5 | C29: Condutor | D29: ='Sobrecarga e Queda de Tensão'!O9 -> 10 | E29: =D29 -> 10 | F29: ='Sobrecarga e Queda de Tensão'!C9 -> 12.3 | G29: ='Sobrecarga e Queda de Tensão'!J9 -> 25 | H29: =$H$6*F29/D29*1000 -> 21.2052 | I29: =$L$6*$F29 -> 0.984 | J29: =SQRT(H29^2+I29^2) -> 21.228018 | K29: =$K$15+J29 -> 54.223808 | L29: =$H$6*$F29*(1/$D29+1/$E29)*1000 -> 42.4104 | M29: =2*$L$6*$F29 -> 1.968 | N29: =SQRT(L29^2+M29^2) -> 42.456037 | O29: =$O$15+N29 -> 80.061886 | P29: =($R$6*$P$6*$O$6)/(SQRT(3)*K29) -> 4.695566 | Q29: =SQRT(3)/2*P29 -> 4.0664795 | R29: =($R$6*$P$6*$O$6)/(SQRT(3)*(O29)) -> 3.1801833 | S29: 25 | T29: =IF(P29<S29,TRUE,FALSE) -> TRUE | U29: Compact NSX100B 4P3D 25kA | V29: TM25D
B30: QGE - QP6 | C30: Condutor | D30: ='Sobrecarga e Queda de Tensão'!O10 -> 70 | E30: =D30/2 -> 35 | F30: ='Sobrecarga e Queda de Tensão'!C10 -> 10.7 | G30: ='Sobrecarga e Queda de Tensão'!J10 -> 80 | H30: =$H$6*F30/D30*1000 -> 2.6352571 | I30: =$L$6*$F30 -> 0.856 | J30: =SQRT(H30^2+I30^2) -> 2.770797 | K30: =$K$15+J30 -> 35.766586 | L30: =$H$6*$F30*(1/$D30+1/$E30)*1000 -> 7.9057714 | M30: =2*$L$6*$F30 -> 1.712 | N30: =SQRT(L30^2+M30^2) -> 8.0890151 | O30: =$O$15+N30 -> 45.694864 | P30: =($R$6*$P$6*$O$6)/(SQRT(3)*K30) -> 7.1186964 | Q30: =SQRT(3)/2*P30 -> 6.1649719 | R30: =($R$6*$P$6*$O$6)/(SQRT(3)*(O30)) -> 5.5719931 | S30: 25 | T30: =IF(P30<S30,TRUE,FALSE) -> TRUE | U30: Compact NSX100B 4P4D 25kA | V30: TM80D
B31: QGE - QP7 | C31: Condutor | D31: ='Sobrecarga e Queda de Tensão'!O11 -> 70 | E31: =D31/2 -> 35 | F31: ='Sobrecarga e Queda de Tensão'!C11 -> 4.16 | G31: ='Sobrecarga e Queda de Tensão'!J11 -> 80 | H31: =$H$6*F31/D31*1000 -> 1.0245486 | I31: =$L$6*$F31 -> 0.3328 | J31: =SQRT(H31^2+I31^2) -> 1.0772445 | K31: =$K$15+J31 -> 34.073034 | L31: =$H$6*$F31*(1/$D31+1/$E31)*1000 -> 3.0736457 | M31: =2*$L$6*$F31 -> 0.6656 | N31: =SQRT(L31^2+M31^2) -> 3.1448881 | O31: =$O$15+N31 -> 40.750737 | P31: =($R$6*$P$6*$O$6)/(SQRT(3)*K31) -> 7.4725213 | Q31: =SQRT(3)/2*P31 -> 6.4713933 | R31: =($R$6*$P$6*$O$6)/(SQRT(3)*(O31)) -> 6.2480212 | S31: 25 | T31: =IF(P31<S31,TRUE,FALSE) -> TRUE | U31: Compact NSX100B 4P4D 25kA | V31: TM80D
B32: QGE - QP8 | C32: Condutor | D32: ='Sobrecarga e Queda de Tensão'!O12 -> 10 | E32: 10 | F32: ='Sobrecarga e Queda de Tensão'!C12 -> 8.4 | G32: ='Sobrecarga e Queda de Tensão'!J12 -> 25 | H32: =$H$6*F32/D32*1000 -> 14.4816 | I32: =$L$6*$F32 -> 0.672 | J32: =SQRT(H32^2+I32^2) -> 14.497183 | K32: =$K$15+J32 -> 47.492972 | L32: =$H$6*$F32*(1/$D32+1/$E32)*1000 -> 28.9632 | M32: =2*$L$6*$F32 -> 1.344 | N32: =SQRT(L32^2+M32^2) -> 28.994367 | O32: =$O$15+N32 -> 66.600216 | P32: =($R$6*$P$6*$O$6)/(SQRT(3)*K32) -> 5.3610346 | Q32: =SQRT(3)/2*P32 -> 4.6427922 | R32: =($R$6*$P$6*$O$6)/(SQRT(3)*(O32)) -> 3.8229827 | S32: 25 | T32: =IF(P32<S32,TRUE,FALSE) -> TRUE | U32: Compact NSX100B 4P3D 25kA | V32: TM25D
B33: QGE - QP9 | C33: Condutor | D33: ='Sobrecarga e Queda de Tensão'!O13 -> 16 | E33: 16 | F33: ='Sobrecarga e Queda de Tensão'!C13 -> 13.6 | G33: ='Sobrecarga e Queda de Tensão'!J13 -> 32 | H33: =$H$6*F33/D33*1000 -> 14.654 | I33: =$L$6*$F33 -> 1.088 | J33: =SQRT(H33^2+I33^2) -> 14.694334 | K33: =$K$15+J33 -> 47.690123 | L33: =$H$6*$F33*(1/$D33+1/$E33)*1000 -> 29.308 | M33: =2*$L$6*$F33 -> 2.176 | N33: =SQRT(L33^2+M33^2) -> 29.388669 | O33: =$O$15+N33 -> 66.994518 | P33: =($R$6*$P$6*$O$6)/(SQRT(3)*K33) -> 5.3388721 | Q33: =SQRT(3)/2*P33 -> 4.6235989 | R33: =($R$6*$P$6*$O$6)/(SQRT(3)*(O33)) -> 3.8004822 | S33: 25 | T33: =IF(P33<S33,TRUE,FALSE) -> TRUE | U33: Compact NSX100B 4P3D 25kA | V33: TM32D
B34: QGE - QP10 | C34: Condutor | D34: ='Sobrecarga e Queda de Tensão'!O14 -> 16 | E34: 16 | F34: ='Sobrecarga e Queda de Tensão'!C14 -> 18.8 | G34: ='Sobrecarga e Queda de Tensão'!J14 -> 32 | H34: =$H$6*F34/D34*1000 -> 20.257 | I34: =$L$6*$F34 -> 1.504 | J34: =SQRT(H34^2+I34^2) -> 20.312756 | K34: =$K$15+J34 -> 53.308545 | L34: =$H$6*$F34*(1/$D34+1/$E34)*1000 -> 40.514 | M34: =2*$L$6*$F34 -> 3.008 | N34: =SQRT(L34^2+M34^2) -> 40.625512 | O34: =$O$15+N34 -> 78.231361 | P34: =($R$6*$P$6*$O$6)/(SQRT(3)*K34) -> 4.7761849 | Q34: =SQRT(3)/2*P34 -> 4.1362974 | R34: =($R$6*$P$6*$O$6)/(SQRT(3)*(O34)) -> 3.2545959 | S34: 25 | T34: =IF(P34<S34,TRUE,FALSE) -> TRUE | U34: Compact NSX100B 4P3D 25kA | V34: TM32D
B35: QGE - QP11 | C35: Condutor | D35: ='Sobrecarga e Queda de Tensão'!O15 -> 16 | E35: 16 | F35: ='Sobrecarga e Queda de Tensão'!C15 -> 32 | G35: ='Sobrecarga e Queda de Tensão'!J15 -> 32 | H35: =$H$6*F35/D35*1000 -> 34.48 | I35: =$L$6*$F35 -> 2.56 | J35: =SQRT(H35^2+I35^2) -> 34.574904 | K35: =$K$15+J35 -> 67.570693 | L35: =$H$6*$F35*(1/$D35+1/$E35)*1000 -> 68.96 | M35: =2*$L$6*$F35 -> 5.12 | N35: =SQRT(L35^2+M35^2) -> 69.149808 | O35: =$O$15+N35 -> 106.75566 | P35: =($R$6*$P$6*$O$6)/(SQRT(3)*K35) -> 3.7680754 | Q35: =SQRT(3)/2*P35 -> 3.263249 | R35: =($R$6*$P$6*$O$6)/(SQRT(3)*(O35)) -> 2.3849927 | S35: 25 | T35: =IF(P35<S35,TRUE,FALSE) -> TRUE | U35: Compact NSX100B 4P3D 25kA | V35: TM32D
B36: QP11-Compressor | C36: Condutor | D36: 6 | E36: 6 | F36: 7 | G36: 25 | H36: =$H$6*F36/D36*1000 -> 20.113333 | I36: =$L$6*$F36 -> 0.56 | J36: =SQRT(H36^2+I36^2) -> 20.121128 | K36: =$K$35+J36 -> 87.691821 | L36: =$H$6*$F36*(1/$D36+1/$E36)*1000 -> 40.226667 | M36: =2*$L$6*$F36 -> 1.12 | N36: =SQRT(L36^2+M36^2) -> 40.242255 | O36: =$O$35+N36 -> 146.99791 | P36: =($R$6*$P$6*$O$6)/(SQRT(3)*K36) -> 2.9034802 | Q36: =SQRT(3)/2*P36 -> 2.5144876 | R36: =($R$6*$P$6*$O$6)/(SQRT(3)*(O36)) -> 1.7320754 | S36: 10 | T36: =IF(P36<S36,TRUE,FALSE) -> TRUE | U36: IC60N D 32A 10kA 4P
B37: QGE - QP12 | C37: Condutor | D37: ='Sobrecarga e Queda de Tensão'!O16 -> 10 | E37: 6 | F37: ='Sobrecarga e Queda de Tensão'!C16 -> 35.8 | G37: ='Sobrecarga e Queda de Tensão'!J16 -> 25 | H37: =$H$6*F37/D37*1000 -> 61.7192 | I37: =$L$6*$F37 -> 2.864 | J37: =SQRT(H37^2+I37^2) -> 61.785614 | K37: =$K$15+J37 -> 94.781404 | L37: =$H$6*$F37*(1/$D37+1/$E37)*1000 -> 164.58453 | M37: =2*$L$6*$F37 -> 5.728 | N37: =SQRT(L37^2+M37^2) -> 164.68418 | O37: =$O$15+N37 -> 202.29003 | P37: =($R$6*$P$6*$O$6)/(SQRT(3)*K37) -> 2.6863019 | Q37: =SQRT(3)/2*P37 -> 2.3264057 | R37: =($R$6*$P$6*$O$6)/(SQRT(3)*(O37)) -> 1.2586457 | S37: 25 | T37: =IF(P37<S37,TRUE,FALSE) -> TRUE | U37: Compact NSX100B 4P3D 25kA | V37: TM25D
B38: QGE-UPS | C38: Condutor | D38: 70 | E38: 35 | F38: 1 | G38: 80 | H38: =$H$6*F38/D38*1000 -> 0.24628571 | I38: =$L$6*$F38 -> 0.08 | J38: =SQRT(H38^2+I38^2) -> 0.25895299 | K38: =$K$15+J38 -> 33.254742 | L38: =$H$6*$F38*(1/$D38+1/$E38)*1000 -> 0.73885714 | M38: =2*$L$6*$F38 -> 0.16 | N38: =SQRT(L38^2+M38^2) -> 0.75598272 | O38: =$O$15+N38 -> 38.361832 | P38: =($R$6*$P$6*$O$6)/(SQRT(3)*K38) -> 7.6563958 | Q38: =SQRT(3)/2*P38 -> 6.6306333 | R38: =($R$6*$P$6*$O$6)/(SQRT(3)*(O38)) -> 6.637104 | S38: 25 | T38: =IF(P38<S38,TRUE,FALSE) -> TRUE | U38: Compact NSX100B 2P 25kA | V38: TM80D
D42: IK2.min - Curto-circuitos bifásicos mínimos | N42: IK1.min - Curto-circuitos monofásicos mínimos
B43: Localização | D43: R2.max (mW) | E43: X2.max (mW) | F43: Z2.max (mW) | G43: Z2.acum (mW) | H43: Ik2.min (kA) | I43: tft.2 (s) | J43: Ik2.min/Ir | K43: tc2 (s) | L43: tc2 < tft2 | M43: tc2 ≤ 5 s | N43: R1.max (mW) | O43: X1.max (mW) | P43: Z1.max (mW) | Q43: Z1.acum (mW) | R43: Ik1.min (kA) | S43: tft.1 (s) | T43: Ik1.min/Ir | U43: tc1(s) | V43: tc < tft | W43: tc ≤ 5 s
B44: Terminais do Transformador | C44: Rede a montante | D44: =0.1*E44 -> 0.0702072 | E44: =0.995*F44 -> 0.702072 | F44: =((($O$6*$R$6)^2)/($C$6*10^6))*1000*2 -> 0.7056 | G44: =F44 -> 0.7056 | H44: =($R$6*$Q$6*$O$6)/G44 -> 565.47619 | N44: =0.1*O44 -> 0.0351036 | O44: =0.995*P44 -> 0.351036 | P44: =((($O$6*$R$6)^2)/($C$6*10^6))*1000 -> 0.3528 | Q44: =P44 -> 0.3528 | R44: =($R$6*$Q$6*$O$6)/(SQRT(3)*(Q44)) -> 652.95566
C45: Transformador | D45: =0.31*F45 -> 17.49888 | E45: =0.95*F45 -> 53.6256 | F45: =((($O$6*$R$6)^2)/($D$6*10^3))*($E$6/100)*1000*2 -> 56.448 | G45: =G44+F45 -> 57.1536 | H45: =($R$6*$Q$6*$O$6)/G45 -> 6.9811875 | N45: =0.31*P45 -> 8.74944 | O45: =0.95*P45 -> 26.8128 | P45: =((($O$6*$R$6)^2)/($D$6*10^3))*($E$6/100)*1000 -> 28.224 | Q45: =Q44+P45 -> 28.5768 | R45: =($R$6*$Q$6*$O$6)/(SQRT(3)*(Q45)) -> 8.061181
B46: QGBT - QGE | C46: Condutor | D46: =$F$6*$F13*(2/$D13)*1000 -> 8.027027 | E46: =2*$L$6*$F13 -> 5.28 | F46: =SQRT(D46^2+E46^2) -> 9.6078907 | G46: =G45+F46 -> 66.761491 | H46: =($R$6*$Q$6*$O$6)/G46 -> 5.9764993 | I46: =($K$6*($D13/(H46*1000)))^2 -> 19.593941 | J46: =H46/G13*1000 -> 23.905997 | K46: 0.08 | L46: =IF(K46<I46,TRUE,FALSE) -> TRUE | M46: =IF(K46<=5,TRUE,FALSE) -> TRUE | N46: =$F$6*$F13*(1/$D13+1/$E13)*1000 -> 8.9635135 | O46: =2*$L$6*$F13 -> 5.28 | P46: =SQRT(N46^2+O46^2) -> 10.403027 | Q46: =Q45+P46 -> 38.979827 | R46: =($R$6*$Q$6*$O$6)/(SQRT(3)*(Q46)) -> 5.9097942 | S46: =($J$6*(MIN($D13:$E13)/(R46*1000)))^2 -> 8.5198801 | T46: =R46/G13*1000 -> 23.639177 | U46: 0.08 | V46: =IF(U46<S46,TRUE,FALSE) -> TRUE | W46: =IF(U46<=5,TRUE,FALSE) -> TRUE
...

Sheet Barramento
C2: Quadro | D2: Ib | E2: IK3max | F2: Temperatura ambiente (ºc) | G2: Coeficiente de temperatura | H2: IP | I2: Iz_min | J2: Material | K2: Barramento (mm2) | L2: I suportado pelo barramento
C3: Q.G.E. | D3: ='Sobrecarga e Queda de Tensão'!H4 -> 213.6606 | E3: ='Curto-Circuito2'!P13 -> 7.8030375 | F3: 40 | G3: 0.87 | H3: 54 | I3: =D3/G3 -> 245.58689 | J3: Cobre não pintado | K3: 60*5 | L3: 825
C4: Q.G.1 | D4: ='Sobrecarga e Queda de Tensão'!H5 -> 106.93089 | E4: ='Curto-Circuito2'!P18 -> 6.5316209 | F4: 40 | G4: 0.87 | H4: 54 | I4: =D4/G4 -> 122.90907 | J4: Cobre não pintado | K4: 40*2 | L4: 600
C5: Q.G.2 | D5: ='Sobrecarga e Queda de Tensão'!H6 -> 11.09097 | E5: ='Curto-Circuito2'!P26 -> 2.9913251 | F5: 40 | G5: 0.87 | H5: 54 | I5: =D5/G5 -> 12.748241 | J5: Cobre não pintado | K5: 12*2 | L5: 110
C6: Q.G.3 | D6: ='Sobrecarga e Queda de Tensão'!H7 -> 9.0509697 | E6: ='Curto-Circuito2'!P27 -> 3.2990298 | F6: 40 | G6: 0.87 | H6: 54 | I6: =D6/G6 -> 10.403413 | J6: Cobre não pintado | K6: 12*2 | L6: 110
C7: Q.G.4 | D7: ='Sobrecarga e Queda de Tensão'!H8 -> 9.0509697 | E7: ='Curto-Circuito2'!P28 -> 4.0732678 | F7: 40 | G7: 0.87 | H7: 54 | I7: =D7/G7 -> 10.403413 | J7: Cobre não pintado | K7: 12*2 | L7: 110
C8: Q.G.5 | D8: ='Sobrecarga e Queda de Tensão'!H9 -> 9.0509697 | E8: ='Curto-Circuito2'!P29 -> 4.695566 | F8: 40 | G8: 0.87 | H8: 54 | I8: =D8/G8 -> 10.403413 | J8: Cobre não pintado | K8: 12*2 | L8: 110
C9: Q.G.6 | D9: ='Sobrecarga e Queda de Tensão'!H10 -> 37.43801 | E9: ='Curto-Circuito2'!P30 -> 7.1186964 | F9: 40 | G9: 0.87 | H9: 54 | I9: =D9/G9 -> 43.032195 | J9: Cobre não pintado | K9: 12*2 | L9: 110
C10: Q.G.7 | D10: ='Sobrecarga e Queda de Tensão'!H11 -> 49.523735 | E10: ='Curto-Circuito2'!P31 -> 7.4725213 | F10: 40 | G10: 0.87 | H10: 54 | I10: =D10/G10 -> 56.923834 | J10: Cobre não pintado | K10: 12*2 | L10: 110
C11: Q.G.8 | D11: ='Sobrecarga e Queda de Tensão'!H12 -> 10.644456 | E11: ='Curto-Circuito2'!P32 -> 5.3610346 | F11: 40 | G11: 0.87 | H11: 54 | I11: =D11/G11 -> 12.235007 | J11: Cobre não pintado | K11: 12*2 | L11: 110
C12: Q.G.9 | D12: ='Sobrecarga e Queda de Tensão'!H13 -> 30.078864 | E12: ='Curto-Circuito2'!P33 -> 5.3388721 | F12: 40 | G12: 0.87 | H12: 54 | I12: =D12/G12 -> 34.573406 | J12: Cobre não pintado | K12: 12*2 | L12: 110
C13: Q.G.10 | D13: ='Sobrecarga e Queda de Tensão'!H14 -> 30.078864 | E13: ='Curto-Circuito2'!P34 -> 4.7761849 | F13: 40 | G13: 0.87 | H13: 54 | I13: =D13/G13 -> 34.573406 | J13: Cobre não pintado | K13: 12*2 | L13: 110
C14: Q.G.11 | D14: ='Sobrecarga e Queda de Tensão'!H15 -> 27.984696 | E14: ='Curto-Circuito2'!P35 -> 3.7680754 | F14: 40 | G14: 0.87 | H14: 54 | I14: =D14/G14 -> 32.166317 | J14: Cobre não pintado | K14: 12*2 | L14: 110
C15: Q.G.12 | D15: ='Sobrecarga e Queda de Tensão'!H16 -> 6.0980244 | E15: ='Curto-Circuito2'!P37 -> 2.6863019 | F15: 40 | G15: 0.87 | H15: 54 | I15: =D15/G15 -> 7.0092235 | J15: Cobre não pintado | K15: 12*2 | L15: 110

Sheet Centro de cargas
A1: Cargas | B1: I (A) | C1: x (m) | D1: y (m)
A2: QP1 | B2: 574.99695 | C2: 20 | D2: 14 | F2: = | G2: =SUMPRODUCT(C2:C13,B2:B13^2) -> 6411558.6 | H2: (m.A2)
A3: QP2 | B3: 13.113844 | C3: 14 | D3: 17
A4: QP3 | B4: 13.113844 | C4: 7 | D4: 17
A5: QP4 | B5: 13.113844 | C5: 1 | D5: 17 | F5: = | G5: =SUMPRODUCT(D2:D13,B2:B13^2) -> 4686992.9 | H5: (m.A2)
A6: QP5 | B6: 13.113844 | C6: -6 | D6: 17
A7: QP6 | B7: 51.866513 | C7: -13 | D7: 17
A8: QP7 | B8: 79.669945 | C8: -14 | D8: 6 | F8: = | G8: =SUMSQ(B2:B13) -> 345700.47 | H8: (A²)
A9: QP8 | B9: 15.885125 | C9: -14 | D9: 0.5
A10: QP9 | B10: 49.684094 | C10: -15 | D10: -5
A11: QP10 | B11: 49.684094 | C11: -15 | D11: -9
A12: QP11 | B12: 7.5712813 | C12: -16 | D12: -15 | K12: = | L12: =G2/G8 -> 18.546572 | M12: + | N12: =G5/G8 -> 13.557959 | O12: (m)
A13: QP12 | B13: 10.342563 | C13: -12 | D13: -18

Sheet Centro de cargas oficina
A1: Cargas | B1: I (A) | C1: x (m) | D1: y (m)
A2: Tomadas Monofásicas | B2: 32 | C2: 0 | D2: 0 | F2: = | G2: =SUMPRODUCT(C2:C10,B2:B10^2) -> -235124.41 | H2: (m.A2)
A3: Tomadas Trifásicas | B3: 556.52174 | C3: 0 | D3: 0
A4: Iluminação | B4: 2.3345306 | C4: 0 | D4: 0
A5: ESG-618 | B5: 0.65607072 | C5: 2 | D5: 2 | F5: = | G5: =SUMPRODUCT(D2:D10,B2:B10^2) -> 188225.4 | H5: (m.A2)
A6: Microcut 8371 | B6: 2.6242829 | C6: -3 | D6: -6
A7: Microcut 1500 | B7: 4.8798649 | C7: 3 | D7: 6
A8: Microcut 1440E | B8: 2.6242829 | C8: 3 | D8: -6 | F8: = | G8: =SUMSQ(B2:B10) -> 357824.03 | H8: (A²)
A9: Microcut 5600B | B9: 1.3880505 | C9: -3 | D9: 6
A10: CNC | B10: 216.88288 | C10: -5 | D10: 4
K12: = | L12: =G2/G8 -> -0.65709508 | M12: + | N12: =G5/G8 -> 0.52602784 | O12: (m)
