Workbook
Name aaaaaaaa: '[1]11'!#REF!
Name mono__tri?: '[1]11'!#REF!
Name mono__tri?: #REF!
Name mono__tri?: '[1]11'!#REF!
Name mono__tri?: '[1]11'!#REF!
Name mono__tri?: '[1]11'!#REF!
Name mono__tri?: '[1]11'!#REF!
Name mono__tri?: #REF!

Sheet i_arr
B2: Corrente de dimensionamento da canalização de alimentação de motor trifásico
C5: Potência mecânica | D5: P | E5: kW | F5: 30
C6: Tensão entre fases | D6: U | E6: V | F6: 400
C7: Rendimento | D7: h | E7: % | F7: 0.88
C8: cos j | D8: cos j | E8: - | F8: 0.85
C9: Ia/I | D9: n | E9: - | F9: 7
C11: Potência elétrica | D11: Pe | E11: kW | F11: =F5/F7 -> 34.090909
C13: Corrente | D13: I | E13: A | F13: =F11*1000/(SQRT(3)*F6*F8) -> 57.889399
C15: Corrente de arranque | D15: Ia | E15: A | F15: =F13*F9 -> 405.22579
C17: Corrente de serviço | D17: IB | E17: A | F17: =F13+F15/3 -> 192.96466
C23: Secção 553.2 das RTIEBT

Sheet dis_dom
B2: CORRENTES ESTIPULADAS E CONVENCIONAIS DE DISJUNTORES DO TIPO DOMÉSTICO (EN 60898)
B4: Corrente Estipulada | C4: Corrente Convencional de não funcionamento | D4: Corrente Convencional de funcionamento
B5: In (A) | C5: Inf (A) = 1,13In | D5: I2 (A) = 1,45In
B7: 10 | C7: =B7*1.13 -> 11.3 | D7: =B7*1.45 -> 14.5
B8: 16 | C8: =B8*1.13 -> 18.08 | D8: =B8*1.45 -> 23.2
B9: 20 | C9: =B9*1.13 -> 22.6 | D9: =B9*1.45 -> 29
B10: 25 | C10: =B10*1.13 -> 28.25 | D10: =B10*1.45 -> 36.25
B11: 32 | C11: =B11*1.13 -> 36.16 | D11: =B11*1.45 -> 46.4
B12: 40 | C12: =B12*1.13 -> 45.2 | D12: =B12*1.45 -> 58
B13: 50 | C13: =B13*1.13 -> 56.5 | D13: =B13*1.45 -> 72.5
B14: 63 | C14: =B14*1.13 -> 71.19 | D14: =B14*1.45 -> 91.35
B15: 80 | C15: =B15*1.13 -> 90.4 | D15: =B15*1.45 -> 116
B16: 100 | C16: =B16*1.13 -> 113 | D16: =B16*1.45 -> 145
B17: 125 | C17: =B17*1.13 -> 141.25 | D17: =B17*1.45 -> 181.25

Sheet dis_fusiveisgg
B2: CORRENTES ESTIPULADAS E CONVENCIONAIS DE FUSÍVEIS gG (EN 60269-2)
B4: Corrente Estipulada | C4: Corrente Convencional de não funcionamento | D4: Corrente Convencional de funcionamento
B5: In (A) | C5: Inf (A) | D5: I2 (A)
B7: 2 | C7: =D7/1.28 -> 3.28125 | D7: =IF(B7<=4,B7*2.1,IF(B7<=16,B7*1.9,B7*1.6)) -> 4.2
B8: 4 | C8: =D8/1.28 -> 6.5625 | D8: =IF(B8<=4,B8*2.1,IF(B8<=16,B8*1.9,B8*1.6)) -> 8.4
B9: 6 | C9: =D9/1.28 -> 8.90625 | D9: =IF(B9<=4,B9*2.1,IF(B9<=16,B9*1.9,B9*1.6)) -> 11.4
B10: 8 | C10: =D10/1.28 -> 11.875 | D10: =IF(B10<=4,B10*2.1,IF(B10<=16,B10*1.9,B10*1.6)) -> 15.2
B11: 10 | C11: =D11/1.28 -> 14.84375 | D11: =IF(B11<=4,B11*2.1,IF(B11<=16,B11*1.9,B11*1.6)) -> 19
B12: 12 | C12: =D12/1.28 -> 17.8125 | D12: =IF(B12<=4,B12*2.1,IF(B12<=16,B12*1.9,B12*1.6)) -> 22.8
B13: 16 | C13: =B13*1.25 -> 20 | D13: =IF(B13<=4,B13*2.1,IF(B13<=16,B13*1.9,B13*1.6)) -> 30.4
B14: 20 | C14: =B14*1.25 -> 25 | D14: =IF(B14<=4,B14*2.1,IF(B14<=16,B14*1.9,B14*1.6)) -> 32
B15: 25 | C15: =B15*1.25 -> 31.25 | D15: =IF(B15<=4,B15*2.1,IF(B15<=16,B15*1.9,B15*1.6)) -> 40
B16: 32 | C16: =B16*1.25 -> 40 | D16: =IF(B16<=4,B16*2.1,IF(B16<=16,B16*1.9,B16*1.6)) -> 51.2
B17: 40 | C17: =B17*1.25 -> 50 | D17: =IF(B17<=4,B17*2.1,IF(B17<=16,B17*1.9,B17*1.6)) -> 64
B18: 50 | C18: =B18*1.25 -> 62.5 | D18: =IF(B18<=4,B18*2.1,IF(B18<=16,B18*1.9,B18*1.6)) -> 80
B19: 63 | C19: =B19*1.25 -> 78.75 | D19: =IF(B19<=4,B19*2.1,IF(B19<=16,B19*1.9,B19*1.6)) -> 100.8
B20: 80 | C20: =B20*1.25 -> 100 | D20: =IF(B20<=4,B20*2.1,IF(B20<=16,B20*1.9,B20*1.6)) -> 128
B21: 100 | C21: =B21*1.25 -> 125 | D21: =IF(B21<=4,B21*2.1,IF(B21<=16,B21*1.9,B21*1.6)) -> 160
B22: 125 | C22: =B22*1.25 -> 156.25 | D22: =IF(B22<=4,B22*2.1,IF(B22<=16,B22*1.9,B22*1.6)) -> 200
B23: 160 | C23: =B23*1.25 -> 200 | D23: =IF(B23<=4,B23*2.1,IF(B23<=16,B23*1.9,B23*1.6)) -> 256
B24: 200 | C24: =B24*1.25 -> 250 | D24: =IF(B24<=4,B24*2.1,IF(B24<=16,B24*1.9,B24*1.6)) -> 320
... B31: 1000 | C31: =B31*1.25 -> 1250 | D31: =IF(B31<=4,B31*2.1,IF(B31<=16,B31*1.9,B31*1.6)) -> 1600

Sheet resistividades
A1: RESISTIVIDADES
C4: Condutor | F4: Cobre | G4: Alumínio
C5: Resistividade a 20 oC | D5: r20 | E5: W.mm2/m | F5: 0.017241 | G5: 0.028264
C6: Coeficiente | D6: a | E6: oC | F6: 0.00393 | G6: 0.00403
C9: QUEDAS DE TENSÃO
C11: Isolante | F11: PVC | G11: XLPE/EPR
C12: Temperatura máxima DU | D12: qmax | E12: oC | F12: 70 | G12: 90
C14: Resistividade para DU | F14: Cobre | G14: Alumínio
C15: PVC | E15: W.mm2/m | F15: =F5*(1+F6*(F12-20)) -> 0.020628856 | G15: =G5*(1+G6*(F12-20)) -> 0.033959196
C16: XLPE/EPR | E16: W.mm2/m | F16: =F5*(1+F6*(G12-20)) -> 0.021983999 | G16: =G5*(1+G6*(G12-20)) -> 0.036237274
C20: CURTO-CIRCUITOS MÍNIMOS
C22: Isolante | F22: PVC | G22: XLPE/EPR
C23: Temperatura máxima c.c. | D23: qmax | E23: oC | F23: 70 | G23: 90
C25: Resistividade para cc | F25: Cobre | G25: Alumínio
C26: PVC | E26: W.mm2/m | F26: =F5*(1+F6*(F23-20)) -> 0.020628856 | G26: =G5*(1+G6*(F23-20)) -> 0.033959196
C27: XLPE/EPR | E27: W.mm2/m | F27: =F5*(1+F6*(G23-20)) -> 0.021983999 | G27: =G5*(1+G6*(G23-20)) -> 0.036237274
C31: CURTO-CIRCUITOS MÁXIMOS
C33: Isolante | F33: PVC | G33: XLPE/EPR
C34: Temperatura máxima c.c. | D34: qmax | E34: oC | F34: 20 | G34: 20
C36: Resistividade para cc | F36: Cobre | G36: Alumínio
C37: PVC | E37: W.mm2/m | F37: =F5*(1+F6*(F34-20)) -> 0.017241 | G37: =G5*(1+G6*(F34-20)) -> 0.028264
C38: XLPE/EPR | E38: W.mm2/m | F38: =F5*(1+F6*(G34-20)) -> 0.017241 | G38: =G5*(1+G6*(G34-20)) -> 0.028264

Sheet airo4
A1: Disjuntor
B4: Dados Máquina
C5: Potência de serviço | D5: kW | E5: 212
C6: Factor de simultaneidade | D6: % | E6: 77
C7: Factor de potência | D7: - | E7: 0.98
B8: Dados Rede
C9: Tensão composta | D9: V | E9: 400
C10: Comprimento | D10: m | E10: 50
C11: Ucc, transformador a montante | D11: % | E11: 4.245
C12: Potência, transformador a montante | D12: kVA | E12: 1000
C13: Ik3.máx | D13: kA | E13: =E12/SQRT(3)/E9/E11*100 -> 34.001783
C14: b, tipo de rede (1-trifásico equilibrado; 2 - outros) | D14: - | E14: 1
C15: Cmax, fator de tensão máximo | D15: - | E15: 1.05
C16: Cmin, fator de tensão mínimo | E16: 0.95
C17: m, fator de carga em vazio | D17: - | E17: 1.05
C18: Regime de neutro | D18: - | E18: TN-C
B19: Dados cabo
C20: Tipo de cabo | D20: - | E20: XV
C21: Tipo de material condutor | D21: - | E21: Cobre
C22: Resistividade do material condutor a 20 ºC | D22: W.mm2/m | E22: 0.017241 | F22: Anexo VI
C23: Coeficiente de variação de resistividade a 20 ºC | D23: K-1 | E23: 0.00393 | F23: Anexo VI
C24: Temperatura máxima de funcionamento | D24: ºC | E24: 90 | F24: Quadro 52A
C25: Isolamento | D25: - | E25: XLPE | F25: Anexo IIB
C26: k - constante do isolamento cabo | D26: - | E26: 143 | F26: Secção 434
C27: l - Reatância linear do cabo | D27: mW/m | E27: 0.08
C28: Polaridade cabo | D28: - | E28: Monocondutor
C29: Modo instalação | D29: - | E29: Condutas enterradas
C30: Tipo de colocação | D30: - | E30: triângulo
C31: Secção condutor PEN | D31: mm2 | E31: Igual ao da fase
C32: Agrupamento de cabos | D32: - | E32: 3
B33: Dados bioclimáticos
C34: Temperatura ambiente | D34: ºC | E34: 45
C35: Temperatura do solo | D35: ºC | E35: 30
C36: Resistividade térmica terreno | D36: K.m/W | E36: 1.2
B38: IB | C38: Corrente de serviço | D38: A | E38: =E5*E6/100/E7/SQRT(3)/E9*1000 -> 240.42515
C39: Referência do modo de instalação | D39: - | E39: 61 | F39: Quadro 52H
C40: Método de referência do modo de instalação | D40: - | E40: D | F40: Quadro 52H
B42: Factores de correcção
C43: Função da temperatura do solo | D43: - | E43: 0.93 | F43: Quadro 52-D2
C44: Resistividade térmica do solo | D44: - | E44: 0.94 | F44: Quadro 52-E6
...

Sheet exemplo_SST
A1: Disjuntor
I2: BALANÇO DE POTÊNCIA
I3: Novo Secador Sem Tensão
B4: Dados Máquina
C5: Potência de Aparente | D5: kVA | E5: =K17 -> 268.77563
C6: Factor de potência | D6: - | E6: =K20 -> 0.87098474 | K6: Ventil. | L6: D.Axial | M6: Foulard | N6: Tipo 4 | O6: Tipo 5
B7: Dados Rede
C8: Tensão composta | D8: V | E8: 400 | I8: Potência nominal | J8: kW | K8: 18.5 | L8: 15 | M8: 15
C9: Comprimento | D9: m | E9: 90 | I9: Rendimento estimado | J9: % | K9: 0.9 | L9: 0.895 | M9: 0.895
C10: Scc, potência de curto-circuito da rede a montante | D10: MVA | E10: 500 | I10: Fator de potência | J10: - | K10: 0.88 | L10: 0.82 | M10: 0.82
C11: Ucc, transformador a montante | D11: % | E11: 4.5 | I11: Quantidade | J11: - | K11: 10 | L11: 1 | M11: 1
C12: Potência, transformador a montante | D12: kVA | E12: 1000 | I12: Fator de utilização - ku | J12: - | K12: 0.96 | L12: 0.97 | M12: 0.97
C13: Número de transformadores | D13: transf | E13: 2 | I13: Fator de simultaneidade - ks | J13: - | K13: 0.97 | L13: 0.97 | M13: 0.97
C14: b, tipo de rede (1-trifásico equilibrado; 2 - outros) | D14: - | E14: 1 | I14: Fator de evolução de cargas - ke | J14: - | K14: 1.05 | L14: 1.05 | M14: 1.05
C15: Cmax, fator de tensão máximo | D15: - | E15: 1.05 | I15: POTÊNCIA APARENTE | J15: kVA | K15: =K8/K9/K10*K11*K12*K13*K14 -> 228.39091 | L15: =L8/L9/L10*L11*L12*L13*L14 -> 20.192363 | M15: =M8/M9/M10*M11*M12*M13*M14 -> 20.192363
C16: Cmin, fator de tensão mínimo | E16: 0.95
C17: m, fator de carga em vazio | D17: - | E17: 1.05 | I17: POTÊNCIA APARENTE TOTAL | J17: kVA | K17: =SUM(K15:O15) -> 268.77563
C18: Regime de neutro | D18: - | E18: TN-C
B19: Dados cabo | I19: Intensidade de Corrente | J19: A | K19: =K17/(SQRT(3)*400)*1000 -> 387.94421
C20: Tipo de cabo | D20: - | E20: XV | I20: Fator de potência médio | J20: - | K20: =(K10*K15+L10*L15+M10*M15)/SUM(K15:M15) -> 0.87098474
C21: Tipo de material condutor | D21: - | E21: Cobre
C22: Resistividade do material condutor a 20 ºC | D22: W.mm2/m | E22: 0.017241 | F22: Anexo VI
C23: Coeficiente de variação de resistividade a 20 ºC | D23: K-1 | E23: 0.00393 | F23: Anexo VI
C24: Temperatura máxima de funcionamento | D24: ºC | E24: 90 | F24: Quadro 52A [523]
C25: Isolamento | D25: - | E25: XLPE | F25: Anexo IIB
C26: k - constante do isolamento cabo | D26: - | E26: 143 | F26: Secção 434
C27: l - Reatância linear do cabo | D27: mW/m | E27: 0.08
C28: Polaridade cabo | D28: - | E28: Monocondutor
C29: Modo instalação | D29: - | E29: Enterrado | F29: Enterrado e calha metálica perfurada, 3 condut.
C30: Tipo de colocação | D30: - | E30: -
C31: Secção condutor PEN | D31: mm2 | E31: Igual ao da fase
C32: Agrupamento de cabos | D32: - | E32: 2
B33: Dados bioclimáticos
C34: Temperatura ambiente | D34: ºC | E34: -
C35: Temperatura do solo | D35: ºC | E35: 45
C36: Resistividade térmica terreno | D36: K.m/W | E36: -
B38: IB | C38: Corrente de serviço | D38: A | E38: =E5/SQRT(3)/E8*1000 -> 387.94421
C39: Referência do modo de instalação | D39: - | E39: 61 | F39: Quadro 52H
C40: Método de referência do modo de instalação | D40: - | E40: D | F40: Quadro 52H
B42: Factores de correcção
...

Sheet bal_pot
A1: Balanço de potência industrial
C3: Us = | D3: =D4/SQRT(3) -> 230.94011 | E3: V
C4: Uc = | D4: 400 | E4: V
B6: Saída 3 - Escritório
C7: BALANÇO DE POTÊNCIA MONOFÁSICO
C8: Designação | D8: Obs | E8: Pinst (kW) | F8: cos j | G8: Ku | H8: Ks | I8: P (kW) | J8: Q (kVAr)
C9: Tomadas | D9: 3x(10x16) | E9: =$D$3*3*10*16/1000 -> 110.85125 | F9: 1 | G9: 1 | H9: 0.2 | I9: =E9*G9*H9 -> 22.17025 | J9: =I9*TAN(ACOS(F9)) -> 0
C10: Aquecimento | D10: 12x1kW | E10: =12*1 -> 12 | F10: 1 | G10: 1 | H10: 1 | I10: =E10*G10*H10 -> 12 | J10: =I10*TAN(ACOS(F10)) -> 0
C11: Iluminação | D11: 6x16lum (2x36W)+25% | E11: =6*16*2*36*1.25/1000 -> 8.64 | F11: 0.6 | G11: 1 | H11: 1 | I11: =E11*G11*H11 -> 8.64 | J11: =I11*TAN(ACOS(F11)) -> 11.52
C12: TOTAL | I12: =SUM(I9:I11) -> 42.81025 | J12: =SUM(J9:J11) -> 11.52 | M12: Ib (A) | N12: cos j
M13: =N18*1000/(3*D3) -> 93.947477 | N13: =L18/N18 -> 0.96919675
C14: BALANÇO DE POTÊNCIA TRIFÁSICO
C15: Designação | D15: Obs | E15: Pinst (kW) | F15: cos j | G15: Ku | H15: Ks | I15: Pu (kW) | J15: Qu (kVAr)
C16: Aquecimento | D16: 6 kW | E16: 6 | F16: 1 | G16: 1 | H16: 1 | I16: =E16*G16*H16 -> 6 | J16: =I16*TAN(ACOS(F16)) -> 0 | L16: Ptotal (kW) | M16: Qtotal (kVAr) | N16: Stotal (kVA)
C17: UPS | D17: Iamont=18A | E17: =SQRT(3)*D4*18*0.95/1000 -> 11.847228 | F17: 0.95 | G17: 1 | H17: 1 | I17: =E17*G17*H17 -> 11.847228 | J17: =I17*TAN(ACOS(F17)) -> 3.8939954 | L17: =I12+I18 -> 60.657478 | M17: =J12+J18 -> 15.413995 | N17: =SQRT(L17^2+M17^2) -> 62.585309 | O17: Sem perdas
C18: TOTAL | I18: =SUM(I16:I17) -> 17.847228 | J18: =SUM(J16:J17) -> 3.8939954 | L18: =L17*1.04 -> 63.083777 | M18: =M17*1.04 -> 16.030555 | N18: =SQRT(L18^2+M18^2) -> 65.088721 | O18: Com perdas
C20: Considerando as cargas das saídas monofásicas repartidas sobre as 3 fases de forma equilibrada na saída do transformador.
B24: Saída 4 - Estação de bombagem
C25: Motor | D25: Pn (kW) | E25: h | F25: cos j | G25: Ku | H25: P (kW) | I25: Q (kVAr) | J25: S (kVAr) | K25: Ib(A)
C26: M1 | D26: 11 | E26: 0.87 | F26: 0.86 | G26: 1 | H26: =D26/E26*G26 -> 12.643678 | I26: =H26*TAN(ACOS(F26)) -> 7.502318 | J26: =SQRT(H26^2+I26^2) -> 14.701951 | K26: =J26*1000/(3*$D$3) -> 21.220439
C27: M2 | D27: 22 | E27: 0.89 | F27: 0.86 | G27: 1 | H27: =D27/E27*G27 -> 24.719101 | I27: =H27*TAN(ACOS(F27)) -> 14.667453 | J27: =SQRT(H27^2+I27^2) -> 28.743141 | K27: =J27*1000/(3*$D$3) -> 41.48715
C28: M3 | D28: 37 | E28: 0.9 | F28: 0.86 | G28: 1 | H28: =D28/E28*G28 -> 41.111111 | I28: =H28*TAN(ACOS(F28)) -> 24.393901 | J28: =SQRT(H28^2+I28^2) -> 47.803618 | K28: =J28*1000/(3*$D$3) -> 68.998579 | L28: Ib (A) | M28: cos j | N28: In
C29: TOTAL | H29: =SUM(H26:H28) -> 78.47389 | I29: =SUM(I26:I28) -> 46.563672 | J29: =SUM(J26:J28) -> 91.24871 | L29: =J29/(3*$D$3)*1000 -> 131.70617 | M29: =H29/J29 -> 0.86 | N29: 160
B32: Saída 5 - Ventilador - extrator
D33: Pn (kW) | E33: h | F33: cos j | G33: Ku | H33: P (kW) | I33: Q (kVAr) | J33: S (kVAr) | L33: Ib (A) | M33: cos j | N33: In
D34: 75 | E34: 0.92 | F34: 0.87 | G34: 0.8 | H34: =D34/E34*G34 -> 65.217391 | I34: =H34*TAN(ACOS(F34)) -> 36.960399 | J34: =SQRT(H34^2+I34^2) -> 74.962519 | L34: =J34/(3*$D$3)*1000 -> 108.19908 | M34: =H34/J34 -> 0.87 | N34: 125
B37: Saída 6 - Ponte rolante
D38: Pn (kW) | E38: h | F38: cos j | G38: Ku | H38: P (kW) | I38: Q (kVAr) | J38: S (kVAr) | L38: Ib (A) | M38: cos j | N38: In
D39: 110 | E39: 0.93 | F39: 0.87 | G39: 1 | H39: =D39/E39*G39 -> 118.27957 | I39: 0 | J39: =SQRT(H39^2+I39^2) -> 118.27957 | L39: =J39/(3*$D$3)*1000 -> 170.72185 | M39: =H39/J39 -> 1 | N39: 200
B41: Saída 7 - Oficina
E42: Stotal (kVA) | F42: Ks | G42: cos j | H42: P (kW) | I42: Q (kVAr) | J42: S (kVAr) | L42: Ib (A) | M42: cos j | N42: In
E43: 340 | F43: 0.8 | G43: 0.8 | H43: =J43*G43 -> 217.6 | I43: =SQRT(J43^2-H43^2) -> 163.2 | J43: =E43*F43 -> 272 | L43: =J43/SQRT(3)/$D$4*1000 -> 392.59818 | M43: =H43/J43 -> 0.8 | N43: 400
B45: QGBT
C47: Carga | D47: Saída | E47: P (kW) | F47: Q (kW) | G47: S (kVA) | H47: Ib (A) | I47: In (A)
C48: Escritório | D48: 3 | E48: =L18 -> 63.083777 | F48: =M18 -> 16.030555 | G48: =N18 -> 65.088721 | H48: =G48*1000/SQRT(3)/$D$4 -> 93.947477 | I48: 100
C49: Estação de bombagem | D49: 4 | E49: =H29 -> 78.47389 | F49: =I29 -> 46.563672 | G49: =J29 -> 91.24871 | H49: =G49*1000/SQRT(3)/$D$4 -> 131.70617 | I49: 160
C50: Extrator | D50: 5 | E50: =H34 -> 65.217391 | F50: =I34 -> 36.960399 | G50: =J34 -> 74.962519 | H50: =G50*1000/SQRT(3)/$D$4 -> 108.19908 | I50: 125
C51: Ponte rolante | D51: 6 | E51: =H39 -> 118.27957 | F51: =I39 -> 0 | G51: =J39 -> 118.27957 | H51: =G51*1000/SQRT(3)/$D$4 -> 170.72185 | I51: 200
C52: Oficina | D52: 7 | E52: =H43 -> 217.6 | F52: =I43 -> 163.2 | G52: =J43 -> 272 | H52: =G52*1000/SQRT(3)/$D$4 -> 392.59818 | I52: 400 | K52: Reserva | L52: Sc (kVA) | M52: Sn (kVA) | N52: IB (A) | O52: cos j
C53: TOTAL (QGBT) | D53: - | E53: =SUM(E48:E52) -> 542.65463 | F53: =SUM(F48:F52) -> 262.75463 | G53: =SUM(G48:G52) -> 621.57952 | H53: =G53*1000/SQRT(3)/$D$4 -> 897.17276 | I53: 1000 | K53: 0.7 | L53: =G53/K53 -> 887.97074 | M53: 1000 | N53: =L53*1000/(3*D3) -> 1281.6754 | O53: =E53/G53 -> 0.87302527

Sheet perg1a4
B3: 1. Queda de tensão da saída 5
C8: Queda de tensão | D8: u | E8: V | F8: =F11*(F12*F13/F14*F15+F16/1000*F13*SIN(ACOS(F15)))*F17 -> 6.6740772
C9: Queda de tensão | D9: Du | E9: % | F9: =F8/F10 -> 0.029017727 | M9: b
C10: Tensão simples | D10: U | E10: V | F10: 230 | L10: Trifásico equilibrado | M10: 1
C11: Sistema | D11: b | E11: mono, tri? | F11: 1 | L11: Monofásico ou trifásico desequilibrado | M11: 2
C12: Resistividade | D12: r1 | E12: W.mm2/m | F12: 0.0225
C13: Comprimento | D13: L | E13: m | F13: 75 | M13: r1
C14: Secção | D14: S | E14: mm2 | F14: 25 | L14: Cobre | M14: 0.0225
C15: Fator de potência | D15: cos j | E15: - | F15: =bal_pot!M34 -> 0.87 | L15: Alumínio | M15: 0.036
C16: Reatância linear | D16: l | E16: mW/m | F16: 0.08
C17: Corrente de serviço | D17: IB | E17: A | F17: =bal_pot!L34 -> 108.19908 | J17: Quadro 52O | L17: Iluminação | M17: Outros
K18: Alimentação BT | L18: 0.03 | M18: 0.05
K19: Alimentação MT/BT | L19: 0.06 | M19: 0.08
B26: 2. Intensidade estipulada de fusível gG
C28: Fusível gG
C29: LSVAV 4x95 mm2
M30: MR | O30: In
C31: Isolamento | D31: - | F31: PVC | G31: Anexo IIB | K31: PVC | M31: A | O31: 2
C32: Condutor | F32: Alumínio | G32: Anexo IIB | K32: XLPE, EPR | M32: A2 | O32: 4
C33: Método de referência | D33: - | F33: D | G33: Quadro 52H | M33: B | O33: 6
C34: Condutores carregados | D34: cond | F34: 3 | K34: Cobre | M34: B2 | O34: 8
C35: Corrente admissível | D35: Iz | E35: A | F35: 197 | G35: Quadro 52-C30 | K35: Alumínio | M35: C | O35: 10
C36: Fator de correção 52-D1 | D36: FC1 | F36: 1 | G36: Quadro 52-D1 | M36: D | O36: 12
C37: Fator de correção 52-D2 | D37: FC2 | F37: 0.95 | G37: Quadro 52-D2 | M37: E | O37: 16
C38: Fator de correção 52-E1 | D38: FC3 | F38: 1 | G38: Quadro 52-E1 | M38: F | O38: 20
C39: Fator de correção 52-E2 | D39: FC4 | F39: 1 | G39: Quadro 52-E2 | M39: G | O39: 25
C40: Fator de correção 52-E3 | D40: FC5 | F40: 1 | G40: Quadro 52-E3 | K40: k2 | O40: 32
C41: Fator de correção 52-E4 | D41: FC6 | F41: 1 | G41: Quadro 52-E4 | J41: Disjuntor modular | K41: 1.45 | O41: 40
C42: Fator de correção 52-E5 | D42: FC7 | F42: 1 | G42: Quadro 52-E5 | J42: Disjuntor outros | K42: 1.3 | O42: 50
C43: Fator de correção total | D43: FC.total | F43: =F36*F37*F38*F39*F40*F41*F42 -> 0.95 | J43: Fusível (In >= 16 A) | K43: 1.6 | O43: 63
C44: Corrente admissível corrigida | D44: I'z | E44: A | F44: =F35*F43 -> 187.15 | J44: Fusível (4 < In< 16 A) | K44: 1.9 | O44: 80
C45: Corrente estipulada do fusível | D45: In | E45: A | F45: 160 | J45: Fusível (In <= 4 A) | K45: 2.1 | O45: 100
C46: Condição In <= I'z? | D46: In <= I'z | E46: ? | F46: =IF($F$45<=$F$44,"OK!","!!!!!!!!!") -> OK! | O46: 125
C47: Relação entre I2 e In | D47: k2 | E47: - | F47: 1.6 | O47: 160
C48: Corrente convencional de funcionamento | D48: I2 | E48: A | F48: =F47*F45 -> 256 | O48: 200
C49: Valor limite térmico da canalização | D49: 1,45xI'z | E49: A | F49: =1.45*F44 -> 271.3675 | O49: 250
C50: Condição I2 <= 1.45.I'z | D50: I2 <= 1.45.I'z | E50: ? | F50: =IF($F$48<=$F$49,"OK!","!!!!!!!!!") -> OK! | O50: 315
C51: RESPOSTA: | D51: In | E51: A | F51: =F45 -> 160 | O51: 400
O52: 500
O53: 630
...

Sheet perg5
H2: Valores em mW
H4: Resistência | I4: Reatância | J4: Impedância | K4: R.acum | L4: X.acum | M4: Z.acum | N4: Ik3.max
H5: mW | I5: mW | J5: mW | K5: mW | L5: mW | M5: mW | N5: kA
H7: Ra = 0,1.Xa | I7: Xa = 0,995.Za | J7: Za = (m.Un)^2/Scc
F8: Za | G8: Rede a montante | H8: =I8*0.1 -> 0.0351036 | I8: =J8*0.995 -> 0.351036 | J8: =(D29*D30)^2/(D28*10^6)*1000 -> 0.3528 | K8: =H8 -> 0.0351036 | L8: =I8 -> 0.351036 | M8: =J8 -> 0.3528 | N8: =$D$27*$D$29*$D$30/(SQRT(3)*M8) -> 721.68784
F10: Zt | G10: Transformador | H10: Rt = 0,31.Zt | I10: Xt = 0,95.Zt | J10: Zt = (mUn)^2.Ucc/(Sn.100)
H11: =0.31*J11 -> 4.1013 | I11: =0.95*J11 -> 12.5685 | J11: =(D29*D30)^2*D32/D31/1000/100*1000 -> 13.23 | K11: =H11+H8 -> 4.1364036 | L11: =I11+I8 -> 12.919536 | M11: =SQRT(K11^2+L11^2) -> 13.565554 | N11: =$D$27*$D$29*$D$30/(SQRT(3)*M11) -> 18.76897
F13: Zcabo1 | G13: Cabo QGBT-D1 | H13: Rc1 = r.L/S | I13: Xc1 = 0,08.L | J13: Zc1 = raizq(Rc1^2+Xc1^2)
H14: =D33*D35/D36*1000 -> 0.15625 | I14: =0.08*D35/3 -> 0.13333333 | J14: =SQRT(H14^2+I14^2) -> 0.20540652 | K14: =K11+H14 -> 4.2926536 | L14: =L11+I14 -> 13.052869 | M14: =SQRT(K14^2+L14^2) -> 13.740607 | N14: =$D$27*$D$29*$D$30/(SQRT(3)*M14) -> 18.529856
F16: Zd1 | G16: Disjuntor1 | H16: Rd = 0 | I16: Xd = 0,15 mW/pólo | J16: Zd = Xd
H17: 0 | I17: =0.15 -> 0.15 | J17: =I17 -> 0.15 | K17: =K14+H17 -> 4.2926536 | L17: =L14+I17 -> 13.202869 | M17: =SQRT(K17^2+L17^2) -> 13.883178 | N17: =$D$27*$D$29*$D$30/(SQRT(3)*M17) -> 18.339567
F19: Zb | G19: Barramento | H19: Rb = r.L/S | I19: Xb = 0,15 mW/m | J19: Zb = raizq(Rb^2+Xb^2)
H20: =D33*D37/D38*1000 -> 0.225 | I20: =0.15*D37 -> 0.75 | J20: =SQRT(H20^2+I20^2) -> 0.78302299 | K20: =K17+H20 -> 4.5176536 | L20: =L17+I20 -> 13.952869 | M20: =SQRT(K20^2+L20^2) -> 14.666007 | N20: =$D$27*$D$29*$D$30/(SQRT(3)*M20) -> 17.360654
F22: Zd2 | G22: Disjuntor2 | H22: Rd = 0 | I22: Xd = 0,15 mW/pólo | J22: Zd = Xd
H23: 0 | I23: =0.15 -> 0.15 | J23: =I23 -> 0.15 | K23: =K20+H23 -> 4.5176536 | L23: =L20+I23 -> 14.102869 | M23: =SQRT(K23^2+L23^2) -> 14.808785 | N23: =$D$27*$D$29*$D$30/(SQRT(3)*M23) -> 17.193272
F25: Zcabo2 | G25: Cabo QGBT-D1 | H25: Rc2 = r.L/S | I25: Xc2 = 0,08.L | J25: Zc1 = raizq(Rc2^2+Xc2^2)
H26: =D33*D39/D40*1000 -> 23.684211 | I26: =0.08*D39 -> 8 | J26: =SQRT(H26^2+I26^2) -> 24.998837 | K26: =K23+H26 -> 28.201864 | L26: =L23+I26 -> 22.102869 | M26: =SQRT(K26^2+L26^2) -> 35.831299 | N26: =$D$27*$D$29*$D$30/(SQRT(3)*M26) -> 7.1058398
B27: Cmax | C27: - | D27: 1.05
B28: Scc | C28: MVA | D28: 500
B29: m | C29: - | D29: 1.05 | H29: =H4 -> Resistência | I29: =I4 -> Reatância | J29: =J4 -> Impedância | K29: =K4 -> R.acum | L29: =L4 -> X.acum | M29: =M4 -> Z.acum | N29: =N4 -> Ik3.max
B30: Un | C30: V | D30: 400 | H30: mW | I30: mW | J30: mW | K30: mW | L30: mW | M30: mW | N30: =N5 -> kA
B31: Sn | C31: kVA | D31: 800 | F31: =F8 -> Za | G31: =G8 -> Rede a montante | H31: =H8 -> 0.0351036 | I31: =I8 -> 0.351036 | J31: =J8 -> 0.3528 | K31: =K8 -> 0.0351036 | L31: =L8 -> 0.351036 | M31: =M8 -> 0.3528 | N31: =N8 -> 721.68784
B32: Ucc | C32: % | D32: 6 | F32: =F10 -> Zt | G32: =G10 -> Transformador | H32: =H11 -> 4.1013 | I32: =I11 -> 12.5685 | J32: =J11 -> 13.23 | K32: =K11 -> 4.1364036 | L32: =L11 -> 12.919536 | M32: =M11 -> 13.565554 | N32: =N11 -> 18.76897
B33: rcu | C33: W.mm2/m | D33: 0.0225 | F33: =F13 -> Zcabo1 | G33: =G13 -> Cabo QGBT-D1 | H33: =H14 -> 0.15625 | I33: =I14 -> 0.13333333 | J33: =J14 -> 0.20540652 | K33: =K14 -> 4.2926536 | L33: =L14 -> 13.052869 | M33: =M14 -> 13.740607 | N33: =N14 -> 18.529856
B34: ral | C34: W.mm2/m | D34: 0.036 | F34: =F16 -> Zd1 | G34: =G16 -> Disjuntor1 | H34: =H17 -> 0 | I34: =I17 -> 0.15 | J34: =J17 -> 0.15 | K34: =K17 -> 4.2926536 | L34: =L17 -> 13.202869 | M34: =M17 -> 13.883178 | N34: =N17 -> 18.339567
B35: L.C1 | C35: m | D35: 5 | F35: =F19 -> Zb | G35: =G19 -> Barramento | H35: =H20 -> 0.225 | I35: =I20 -> 0.75 | J35: =J20 -> 0.78302299 | K35: =K20 -> 4.5176536 | L35: =L20 -> 13.952869 | M35: =M20 -> 14.666007 | N35: =N20 -> 17.360654
B36: S.C1 | C36: mm2 | D36: =240*3 -> 720 | F36: =F22 -> Zd2 | G36: =G22 -> Disjuntor2 | H36: =H23 -> 0 | I36: =I23 -> 0.15 | J36: =J23 -> 0.15 | K36: =K23 -> 4.5176536 | L36: =L23 -> 14.102869 | M36: =M23 -> 14.808785 | N36: =N23 -> 17.193272
B37: L.b | C37: m | D37: 5 | F37: =F25 -> Zcabo2 | G37: =G25 -> Cabo QGBT-D1 | H37: =H26 -> 23.684211 | I37: =I26 -> 8 | J37: =J26 -> 24.998837 | K37: =K26 -> 28.201864 | L37: =L26 -> 22.102869 | M37: =M26 -> 35.831299 | N37: =N26 -> 7.1058398
B38: S.b | C38: mm2 | D38: =100*5 -> 500
B39: L.C2 | C39: m | D39: 100
B40: S.C2 | C40: mm2 | D40: 95

Sheet perg6
H2: Valores em mW
H4: Resistência | I4: Reatância | J4: Impedância | K4: R.acum | L4: X.acum | M4: Z.acum | N4: Ik3.max
H5: mW | I5: mW | J5: mW | K5: mW | L5: mW | M5: mW | N5: kA
H7: Ra = 0,1.Xa | I7: Xa = 0,995.Za | J7: Za = (m.Un)^2/Scc
F8: Za | G8: Rede a montante | H8: =I8*0.1 -> 0.0351036 | I8: =J8*0.995 -> 0.351036 | J8: =(D29*D30)^2/(D28*10^6)*1000 -> 0.3528 | K8: =H8 -> 0.0351036 | L8: =I8 -> 0.351036 | M8: =J8 -> 0.3528 | N8: =$D$27*$D$29*$D$30/(SQRT(3)*M8) -> 721.68784
B10: Saída Q41 | F10: Zt | G10: Transformador | H10: Rt = 0,31.Zt | I10: Xt = 0,95.Zt | J10: Zt = (mUn)^2.Ucc/(Sn.100)
H11: =0.31*J11 -> 1.3671 | I11: =0.95*J11 -> 4.1895 | J11: =(D29*D30)^2*D32/D31/1000/100*1000 -> 4.41 | K11: =H11+H8 -> 1.4022036 | L11: =I11+I8 -> 4.540536 | M11: =SQRT(K11^2+L11^2) -> 4.7521197 | N11: =$D$27*$D$29*$D$30/(SQRT(3)*M11) -> 53.578504
F13: Zcabo1 | G13: Cabo QGBT-D1 | H13: Rc1 = r.L/S/2 | I13: Xc1 = 0,085.L | J13: Zc1 = raizq(Rc1^2+Xc1^2)
F14: 1//2 | H14: =D33*D35/D36*1000/2 -> 0.1875 | I14: =0.085*D35/4/2 -> 0.10625 | J14: =SQRT(H14^2+I14^2) -> 0.21551175 | K14: =K11+H14 -> 1.5897036 | L14: =L11+I14 -> 4.646786 | M14: =SQRT(K14^2+L14^2) -> 4.911189 | N14: =$D$27*$D$29*$D$30/(SQRT(3)*M14) -> 51.843142
F16: Zd1 | G16: Disjuntor1 | H16: Rd = 0 | I16: Xd = 0,15 mW/pólo | J16: Zd = Xd
F17: d1//d2 | H17: 0 | I17: =0.15/2 -> 0.075 | J17: =I17 -> 0.075 | K17: =K14+H17 -> 1.5897036 | L17: =L14+I17 -> 4.721786 | M17: =SQRT(K17^2+L17^2) -> 4.9822104 | N17: =$D$27*$D$29*$D$30/(SQRT(3)*M17) -> 51.104118
F19: Zb1 | G19: Barramento1 | H19: Rb = r.L/S | I19: Xb = 0,15 mW/m | J19: Zb = raizq(Rb^2+Xb^2)
G20: 2x100x10, 5m | H20: =D33*D37/D38*1000 -> 0.05625 | I20: =0.15*D37 -> 0.75 | J20: =SQRT(H20^2+I20^2) -> 0.75210642 | K20: =K17+H20 -> 1.6459536 | L20: =L17+I20 -> 5.471786 | M20: =SQRT(K20^2+L20^2) -> 5.7139833 | N20: =$D$27*$D$29*$D$30/(SQRT(3)*M20) -> 44.559365
F22: Zd4 | G22: Disjuntor4 | H22: Rd = 0 | I22: Xd = 0,15 mW/pólo | J22: Zd = Xd
H23: 0 | I23: =0.15 -> 0.15 | J23: =I23 -> 0.15 | K23: =K20+H23 -> 1.6459536 | L23: =L20+I23 -> 5.621786 | M23: =SQRT(K23^2+L23^2) -> 5.8577847 | N23: =$D$27*$D$29*$D$30/(SQRT(3)*M23) -> 43.465488
F25: Zcabo4 | G25: Cabo Q4-Q40 | H25: Rc4 = r.L/S | I25: Xc4 = 0,08.L | J25: Zc1 = raizq(Rc4^2+Xc4^2)
H26: =D33*D39/D40*1000 -> 102.85714 | I26: =0.08*D39 -> 25.6 | J26: =SQRT(H26^2+I26^2) -> 105.99506 | K26: =K23+H26 -> 104.5031 | L26: =L23+I26 -> 31.221786 | M26: =SQRT(K26^2+L26^2) -> 109.0674 | N26: =$D$27*$D$29*$D$30/(SQRT(3)*M26) -> 2.3344416
B27: Cmax | C27: - | D27: 1.05
B28: Scc | C28: MVA | D28: 500 | F28: Zb2 | G28: Barramento2 | H28: Rb = r.L/S | I28: Xb = 0,15 mW/m | J28: Zb = raizq(Rb^2+Xb^2)
B29: m | C29: - | D29: 1.05 | G29: 1x15x3, 3m | H29: =D33*D43/D44*1000 -> 1.5 | I29: =0.15*D43 -> 0.45 | J29: =SQRT(H29^2+I29^2) -> 1.566046 | K29: =K26+H29 -> 106.0031 | L29: =L26+I29 -> 31.671786 | M29: =SQRT(K29^2+L29^2) -> 110.63344 | N29: =$D$27*$D$29*$D$30/(SQRT(3)*M29) -> 2.301397
B30: Un | C30: V | D30: 400
B31: Sn | C31: kVA | D31: =bal_pot!M53*2 -> 2000 | F31: Zd41 | G31: Disjuntor41 | H31: Rd = 0 | I31: Xd = 0,15 mW/pólo | J31: Zd = Xd
B32: Ucc | C32: % | D32: 5 | H32: 0 | I32: =0.15 -> 0.15 | J32: =I32 -> 0.15 | K32: =K29+H32 -> 106.0031 | L32: =L29+I32 -> 31.821786 | M32: =SQRT(K32^2+L32^2) -> 110.67648 | N32: =$D$27*$D$29*$D$30/(SQRT(3)*M32) -> 2.3005021
B33: rcu | C33: W.mm2/m | D33: 0.0225
B34: ral | C34: W.mm2/m | D34: 0.036 | F34: Zcabo41 | G34: Cabo Q40-Q41 | H34: Rc2 = r.L/S | I34: Xc2 = 0,08.L | J34: Zc1 = raizq(Rc2^2+Xc2^2)
B35: L.C1 | C35: m | D35: =perg1a4!F88 -> 10 | H35: =$D$33*D41/D42*1000 -> 56.25 | I35: =0.08*D41 -> 1.2 | J35: =SQRT(H35^2+I35^2) -> 56.262799 | K35: =K32+H35 -> 162.2531 | L35: =L32+I35 -> 33.021786 | M35: =SQRT(K35^2+L35^2) -> 165.5793 | N35: =$D$27*$D$29*$D$30/(SQRT(3)*M35) -> 1.5377011
B36: S.C1 | C36: mm2 | D36: =perg1a4!F89 -> 600
B37: L.b1 | C37: m | D37: 5
B38: S.b1 | C38: mm2 | D38: =2*100*10 -> 2000 | H38: =H4 -> Resistência | I38: =I4 -> Reatância | J38: =J4 -> Impedância | K38: =K4 -> R.acum | L38: =L4 -> X.acum | M38: =M4 -> Z.acum | N38: =N4 -> Ik3.max
B39: L.C2 | C39: m | D39: 320 | H39: mW | I39: mW | J39: mW | K39: mW | L39: mW | M39: mW | N39: =N5 -> kA
B40: S.C2 | C40: mm2 | D40: 70 | F40: =F8 -> Za | G40: =G8 -> Rede a montante | H40: =H8 -> 0.0351036 | I40: =I8 -> 0.351036 | J40: =J8 -> 0.3528 | K40: =K8 -> 0.0351036 | L40: =L8 -> 0.351036 | M40: =M8 -> 0.3528 | N40: =N8 -> 721.68784
B41: L.C3 | C41: m | D41: =perg1a4!M88 -> 15 | F41: =F10 -> Zt | G41: =G10 -> Transformador | H41: =0.31*J41 -> 1.3671 | I41: =J41*0.95 -> 4.1895 | J41: =(D29*D30)^2*D32/D31/1000/100*1000 -> 4.41 | K41: =K11 -> 1.4022036 | L41: =L11 -> 4.540536 | M41: =M11 -> 4.7521197 | N41: =N11 -> 53.578504
B42: S.C3 | C42: mm2 | D42: =perg1a4!M96 -> 6 | F42: =F13 -> Zcabo1 | G42: =G13 -> Cabo QGBT-D1 | H42: =H14 -> 0.1875 | I42: =I14 -> 0.10625 | J42: =J14 -> 0.21551175 | K42: =K14 -> 1.5897036 | L42: =L14 -> 4.646786 | M42: =M14 -> 4.911189 | N42: =N14 -> 51.843142
B43: L.b2 | C43: m | D43: 3 | F43: =F16 -> Zd1 | G43: =G16 -> Disjuntor1 | H43: =H17 -> 0 | I43: =I17 -> 0.075 | J43: =J17 -> 0.075 | K43: =K17 -> 1.5897036 | L43: =L17 -> 4.721786 | M43: =M17 -> 4.9822104 | N43: =N17 -> 51.104118
B44: S.b2 | C44: mm2 | D44: =15*3 -> 45 | F44: =F19 -> Zb1 | G44: =G19 -> Barramento1 | H44: =H20 -> 0.05625 | I44: =I20 -> 0.75 | J44: =J20 -> 0.75210642 | K44: =K20 -> 1.6459536 | L44: =L20 -> 5.471786 | M44: =M20 -> 5.7139833 | N44: =N20 -> 44.559365
F45: =F22 -> Zd4 | G45: =G22 -> Disjuntor4 | H45: =H23 -> 0 | I45: =I23 -> 0.15 | J45: =J23 -> 0.15 | K45: =K23 -> 1.6459536 | L45: =L23 -> 5.621786 | M45: =M23 -> 5.8577847 | N45: =N23 -> 43.465488
F46: =F25 -> Zcabo4 | G46: =G25 -> Cabo Q4-Q40 | H46: =H26 -> 102.85714 | I46: =I26 -> 25.6 | J46: =J26 -> 105.99506 | K46: =K26 -> 104.5031 | L46: =L26 -> 31.221786 | M46: =M26 -> 109.0674 | N46: =N26 -> 2.3344416
F47: =F28 -> Zb2 | G47: =G28 -> Barramento2 | H47: =H29 -> 1.5 | I47: =I29 -> 0.45 | J47: =J29 -> 1.566046 | K47: =K29 -> 106.0031 | L47: =L29 -> 31.671786 | M47: =M29 -> 110.63344 | N47: =N29 -> 2.301397
F48: =F31 -> Zd41 | G48: =G31 -> Disjuntor41 | H48: =H32 -> 0 | I48: =I32 -> 0.15 | J48: =J32 -> 0.15 | K48: =K32 -> 106.0031 | L48: =L32 -> 31.821786 | M48: =M32 -> 110.67648 | N48: =N32 -> 2.3005021
F49: =F34 -> Zcabo41 | G49: =G34 -> Cabo Q40-Q41 | H49: =H35 -> 56.25 | I49: =I35 -> 1.2 | J49: =J35 -> 56.262799 | K49: =K35 -> 162.2531 | L49: =L35 -> 33.021786 | M49: =M35 -> 165.5793 | N49: =N35 -> 1.5377011
...

Sheet perg7
A1: Disjuntor
B4: Dados Máquina
C5: Potência de serviço | D5: kW | E5: 15
C6: Factor de utilização | D6: % | E6: 87
C7: Factor de potência | D7: - | E7: 0.89
B8: Dados Rede
C9: Tensão composta | D9: V | E9: 400
C10: Comprimento | D10: m | E10: 200
C11: Ucc, transformador a montante | D11: % | E11: 4.245
C12: Potência, transformador a montante | D12: kVA | E12: 2000
C13: Ik3.máx | D13: kA | E13: =E12/SQRT(3)/E9/E11*100 -> 68.003565
C14: b, tipo de rede (1-trifásico equilibrado; 2 - outros) | D14: - | E14: 1
C15: Cmax, fator de tensão máximo | D15: - | E15: 1.05
C16: Cmin, fator de tensão mínimo | E16: 0.95
C17: m, fator de carga em vazio | D17: - | E17: 1.05
C18: Regime de neutro | D18: - | E18: TN-C
B19: Dados cabo
C20: Tipo de cabo | D20: - | E20: VAV
C21: Tipo de material condutor | D21: - | E21: Cobre
C22: Resistividade do material condutor a 20 ºC | D22: W.mm2/m | E22: 0.017241 | F22: Anexo VI
C23: Coeficiente de variação de resistividade a 20 ºC | D23: K-1 | E23: 0.00393 | F23: Anexo VI
C24: Temperatura máxima de funcionamento | D24: ºC | E24: 90 | F24: Quadro 52A [523]
C25: Isolamento | D25: - | E25: XLPE | F25: Anexo IIB
C26: k - constante do isolamento cabo | D26: - | E26: 143 | F26: Secção 434
C27: l - Reatância linear do cabo | D27: mW/m | E27: 0.08
C28: Polaridade cabo | D28: - | E28: Multicondutor
C29: Modo instalação | D29: - | E29: Fixados ao tecto
C30: Tipo de colocação | D30: - | E30: -
C31: Secção condutor PEN | D31: mm2 | E31: Igual ao da fase
C32: Agrupamento de cabos | D32: - | E32: 5
B33: Dados bioclimáticos
C34: Temperatura ambiente | D34: ºC | E34: 45
C35: Temperatura do solo | D35: ºC | E35: -
C36: Resistividade térmica terreno | D36: K.m/W | E36: -
B38: IB | C38: Corrente de serviço | D38: A | E38: =E5*E6/100/E7/SQRT(3)/E9*1000 -> 21.164104
C39: Referência do modo de instalação | D39: - | E39: 11A | F39: Quadro 52H
C40: Método de referência do modo de instalação | D40: - | E40: C | F40: Quadro 52H
B42: Factores de correcção
C43: Função da temperatura ambiente | D43: - | E43: 0.87 | F43: Quadro 52-D1
C44: Agrupamento de cabos | D44: - | E44: 0.66 | F44: Quadro 52-E1
...

Sheet perg8
A1: Fusível
B4: Dados Máquina
C5: Potência instalada | D5: kVA | E5: 100
C6: Potência de serviço | D6: kW | E6: =E5*E8 -> 80
C7: Factor de utilização | D7: % | E7: 100
C8: Factor de potência | D8: - | E8: 0.8
B9: Dados Rede
C10: Tensão composta | D10: V | E10: 400
C11: Comprimento | D11: m | E11: 210
C12: Ucc, transformador a montante | D12: % | E12: 4.5
C13: Potência, transformador a montante | D13: kVA | E13: 1000
C14: Ik3.máx | D14: kA | E14: =E13/SQRT(3)/E10/E12*100 -> 32.075015
C15: b, tipo de rede (1-trifásico equilibrado; 2 - outros) | D15: - | E15: 1
C16: Cmax, fator de tensão máximo | D16: - | E16: 1.05
C17: Cmin, fator de tensão mínimo | E17: 0.95
C18: m, fator de carga em vazio | D18: - | E18: 1.05
C19: Regime de neutro | D19: - | E19: TN-C
B20: Dados cabo
C21: Tipo de cabo | D21: - | E21: XV
C22: Tipo de material condutor | D22: - | E22: Cobre
C23: Resistividade do material condutor a 20 ºC | D23: W.mm2/m | E23: 0.017241 | F23: Anexo VI
C24: Coeficiente de variação de resistividade a 20 ºC | D24: K-1 | E24: 0.00393 | F24: Anexo VI
C25: Temperatura máxima de funcionamento | D25: ºC | E25: 90 | F25: Quadro 52A
C26: Isolamento | D26: - | E26: XLPE | F26: Anexo IIB
C27: k - constante do isolamento cabo | D27: - | E27: 143 | F27: Secção 434
C28: l - Reatância linear do cabo | D28: mW/m | E28: 0.08
C29: Polaridade cabo | D29: - | E29: Monocondutor
C30: Modo instalação | D30: - | E30: Caminho cabos perf.
C31: Tipo de colocação | D31: - | E31: triângulo
C32: Secção condutor PEN | D32: mm2 | E32: Igual ao da fase
C33: Agrupamento de cabos | D33: - | E33: 3
B34: Dados bioclimáticos
C35: Temperatura ambiente | D35: ºC | E35: 40
C36: Temperatura do solo | D36: ºC | E36: -
C37: Resistividade térmica terreno | D37: K.m/W | E37: -
B39: IB | C39: Corrente de serviço | D39: A | E39: =E6*E7/100/E8/SQRT(3)/E10*1000 -> 144.33757
C40: Referência do modo de instalação | D40: - | E40: 13 | F40: Quadro 52H
C41: Método de referência do modo de instalação | D41: - | E41: F | F41: Quadro 52H
B43: Factores de correcção
C44: Função da temperatura ambiente | D44: - | E44: 0.91 | F44: Quadro 52-D1
...

Sheet perg12
A1: Dimensionamento de barramentos
C4: IB | D4: A | E4: 850
C5: IK3 | D5: kA | E5: 30
C6: d | D6: cm | E6: 12
C7: ltotal | D7: cm | E7: 200
C9: FC1 | E9: 0.85 | F9: Horizontal não pintada
C10: FC2 | E10: 0.87 | F10: Temperatura
C11: FCT | E11: =E9*E10 -> 0.7395
C12: Iz.min | D12: A | E12: =E4/E11 -> 1149.4253
C13: Iz.tabela | D13: A | E13: 1200
C14: Secção | D14: mm2 | E14: 60x10
C16: l | D16: cm | E16: 100
C17: Suportes | D17: - | E17: 2
C18: Sequência suportes | D18: cm | E18: 50+100+50
C19: fe | D19: kg/cm | E19: 10
C20: F (topo) | D20: kg | E20: =E19*E16/2 -> 500
C21: F (intermédios) | D21: kg | E21: NA
C23: Ressonância | E23: Fora da zona crítica de ressonância mecânica
